Workbook

Sheet Jan
B2: Cell # | C2: Membran # ¦ Batch # | D2: Temp Kat / [°C] | E2: Membrane V @ 13 bar/[V] | F2: Cell V @ 13 bar/[V] | G2: Cell V @ 0 bar [V] | H2: Voltage Diff. / [V] | I2: Typ | J2: FA # | K2: Bemerkungen | M2: Visum | N2: Jahr: | O2: 2017
B3: 17A-0001Z | C3: 16K-0006M | D3: 3.3 | F3: 1.936 | G3: 1.921 | H3: =F3-G3 -> 0.015 | I3: MI V3 | J3: FA700938 | L3: ab16K-0006M zus. Säure
B4: 17A-0002Z | C4: 16K-0007M | D4: 4.4 | F4: 1.977 | G4: 1.958 | H4: =F4-G4 -> 0.019 | I4: MI V3 | J4: FA700938
B5: 17A-0003Z | C5: 16K-0008M | D5: 4.3 | F5: 1.951 | G5: 1.93 | H5: =F5-G5 -> 0.021 | I5: MI V3 | J5: FA700938
B6: 17A-0004Z | C6: 16K-0009M | D6: 4.3 | F6: 1.936 | G6: 1.917 | H6: =F6-G6 -> 0.019 | I6: MI V3 | J6: FA700938
B7: 17A-0005Z | C7: 16K-0010M | D7: 4.8 | F7: 1.937 | G7: 1.918 | H7: =F7-G7 -> 0.019 | I7: MI V3 | J7: FA700938
B8: 17A-0006Z | C8: 16K-0011M | D8: 4.7 | F8: 1.932 | G8: 1.911 | H8: =F8-G8 -> 0.021 | I8: MI V3 | J8: FA700938
B9: 17A-0007Z | C9: 16K-0012M | D9: 4.8 | F9: 1.933 | G9: 1.916 | H9: =F9-G9 -> 0.017 | I9: MI V3 | J9: FA700938
B10: 17A-0008Z | C10: 16K-0013M | D10: 4.7 | F10: 1.928 | G10: 1.912 | H10: =F10-G10 -> 0.016 | I10: MI V3 | J10: FA700938
B11: 17A-0009Z | C11: 16K-0014M | D11: 5 | F11: 1.925 | G11: 1.909 | H11: =F11-G11 -> 0.016 | I11: MI V3 | J11: FA700938
B12: 17A-0010Z | C12: 16K-0015M | D12: 5.2 | F12: 1.94 | G12: 1.922 | H12: =F12-G12 -> 0.018 | I12: MI V3 | J12: FA700938
B13: 17A-0011Z | C13: 16K-0113M | D13: 27.9 | E13: 1.862 | F13: 3.726 | G13: 3.702 | H13: =F13-G13 -> 0.024 | I13: MU2 V1 | J13: FA701147 | K13: Carmen i.O.
C14: 16K-0114M | E14: 1.864
B15: 17A-0012Z | C15: 16K-0115M | D15: 18.4 | E15: 1.858 | F15: 3.71 | G15: 3.686 | H15: =F15-G15 -> 0.024 | I15: " | J15: "
C16: 16K-0116M | E16: 1.851
B17: 17A-0013Z | C17: 16K-0117M | D17: 20.7 | E17: 1.866 | F17: 3.747 | G17: 3.716 | H17: =F17-G17 -> 0.031 | I17: MU2 V1 | J17: FA700798
C18: 16K-0118M | E18: 1.88
B19: 17A-0014Z | C19: 16K-0119M | D19: 40.8 | E19: 1.852 | F19: 3.697 | G19: 3.685 | H19: =F19-G19 -> 0.012 | I19: " | J19: "
C20: 16K-0120M | E20: 1.845
B21: " | C21: 16K-0119M | D21: 9.9 | E21: 1.854 | F21: 3.702 | G21: 3.687 | H21: =F21-G21 -> 0.015 | K21: nach Membranenwechsel (knapp geschnitten) Temp19.9/ 15.9
C22: 16L-0026M | E22: 1.847 | H22: =F22-G22 -> 0 | K22: auf Testsystem ca. 30 Std laufenlassen
B23: 17A-0015Z | C23: 16K-0121M | D23: 19.6 | E23: 1.867 | F23: 3.733 | G23: 3.695 | H23: =F23-G23 -> 0.038 | I23: " | J23: "
C24: 16K-0122M | E24: 1.865
B25: 17A-0016Z | C25: 16K-0123M | D25: 3.8 | E25: 1.845 | F25: 3.7 | G25: 3.676 | H25: =F25-G25 -> 0.024 | I25: " | J25: "
C26: 16K-0124M | E26: 1.855
B27: 17A-0017Z | C27: 16K-0125M | D27: 2.6 | E27: 1.843 | F27: 3.694 | G27: 3.667 | H27: =F27-G27 -> 0.027 | I27: " | J27: "
C28: 16K-0126M | E28: 1.851
B29: 17A-0018Z | C29: 16K-0127M | D29: 3.4 | E29: 1.844 | F29: 3.694 | G29: 3.669 | H29: =F29-G29 -> 0.025 | I29: " | J29: "
C30: 16K-0128M | E30: 1.85
B31: 17A-0019Z | C31: 16K-0129M | D31: 3.2 | E31: 1.843 | F31: 3.682 | G31: 3.655 | H31: =F31-G31 -> 0.027 | I31: " | J31: "
C32: 16K-0130M | E32: 1.838
B33: 17A-0020Z | C33: 16L-0001M | D33: 6.7 | E33: 1.828 | F33: 3.666 | G33: 3.638 | H33: =F33-G33 -> 0.028 | I33: " | J33: "
C34: 16L-0002M | E34: 1.837
B35: 17A-0021Z | C35: 16L-0003M | D35: 21.1 | E35: 1.871 | F35: 3.742 | G35: 3.722 | H35: =F35-G35 -> 0.02 | I35: MU2 V1 | J35: FA701149
C36: 16L-0004M | E36: 1.87
B37: 17A-0022Z | C37: 16L-0005M | D37: 22.4 | E37: 1.858 | F37: 3.725 | G37: 3.701 | H37: =F37-G37 -> 0.024 | I37: " | J37: "
C38: 16L-0006M | E38: 1.866
B39: 17A-0023Z | C39: 16L-0007M | D39: 16.4 | E39: 1.874 | F39: 3.738 | G39: 3.708 | H39: =F39-G39 -> 0.03 | I39: " | J39: "
C40: 16L-0008M | E40: 1.863
B41: 17A-0024Z | C41: 16L-0009M | D41: 20.1 | E41: 1.881 | F41: 3.766 | G41: 3.746 | H41: =F41-G41 -> 0.02 | I41: " | J41: "
...

Sheet Feb
B2: Cell # | C2: Membran # ¦ Batch # | D2: Temp Kat / [°C] | E2: Membrane V @ 13 bar/[V] | F2: Cell V @ 13 bar/[V] | G2: Cell V @ 0 bar [V] | H2: Voltage Diff. / [V] | I2: Typ | J2: FA # | K2: Bemerkungen | M2: Visum | N2: Jahr: | O2: 2017
B3: 17B-0001Z | C3: FA700973 | D3: 4.9 | F3: 1.914 | G3: 1.899 | H3: =F3-G3 -> 0.015 | I3: MI V3 | J3: FA701172
B4: 17B-0002Z | C4: " | D4: 5.1 | F4: 1.913 | G4: 1.9 | H4: =F4-G4 -> 0.013 | I4: " | J4: "
B5: 17B-0003Z | C5: " | D5: 5.5 | F5: 1.923 | G5: 1.909 | H5: =F5-G5 -> 0.014 | I5: " | J5: "
B6: 17B-0004Z | C6: FA701047 | D6: 7.1 | F6: 1.917 | G6: 1.905 | H6: =F6-G6 -> 0.012 | I6: " | J6: "
B7: 17B-0005Z | C7: " | D7: 6.3 | F7: 1.91 | G7: 1.895 | H7: =F7-G7 -> 0.015 | I7: " | J7: "
B8: 17B-0006Z | C8: " | D8: 7 | F8: 1.913 | G8: 1.899 | H8: =F8-G8 -> 0.014 | I8: " | J8: "
B9: 17B-0007Z | C9: " | D9: 7 | F9: 1.904 | G9: 1.89 | H9: =F9-G9 -> 0.014 | I9: " | J9: "
B10: 17B-0008Z | C10: " | D10: 8.2 | F10: 1.91 | G10: 1.894 | H10: =F10-G10 -> 0.016 | I10: " | J10: "
B11: 17B-0009Z | C11: " | D11: 5.2 | F11: 1.901 | G11: 1.887 | H11: =F11-G11 -> 0.014 | I11: " | J11: "
B12: 17B-0010Z | C12: " | D12: 5.2 | F12: 1.882 | G12: 1.871 | H12: =F12-G12 -> 0.011 | I12: " | J12: "
B13: 17B-0011Z | C13: FA700977 | I13: MU-12 | J13: FA700918
C14: FA700977
C15: "
C16: "
C17: "
C18: "
C19: "
C20: "
C21: "
C22: "
C23: "
C24: "
B25: 17B-0012Z | C25: FA701047 | D25: 6.5 | F25: 1.882 | G25: 1.866 | H25: =F25-G25 -> 0.016 | I25: MI V3 | J25: FA701172
B26: 17B-0013Z | C26: " | D26: 4 | F26: 1.904 | G26: 1.891 | H26: =F26-G26 -> 0.013 | I26: " | J26: "
B27: 17B-0014Z | C27: " | D27: 2.8 | F27: 1.9 | G27: 1.887 | H27: =F27-G27 -> 0.013 | I27: " | J27: "
B28: 17B-0015Z | C28: " | D28: 10.7 | F28: 1.896 | G28: 1.89 | H28: =F28-G28 -> 0.006 | I28: " | J28: "
B29: 17B-0016Z | C29: " | D29: 6.7 | F29: 1.899 | G29: 1.885 | H29: =F29-G29 -> 0.014 | I29: " | J29: "
B30: 17B-0017Z | C30: " | D30: 6.1 | F30: 1.872 | G30: 1.858 | H30: =F30-G30 -> 0.014 | I30: " | J30: "
B31: 17B-0018Z | C31: " | D31: 10.6 | F31: 1.906 | G31: 1.897 | H31: =F31-G31 -> 0.009 | I31: " | J31: "
B32: 17B-0019Z | C32: " | D32: 6.7 | F32: 1.886 | G32: 1.871 | H32: =F32-G32 -> 0.015 | I32: " | J32: "
B33: 17B-0020Z | C33: " | D33: 7.8 | F33: 1.892 | G33: 1.88 | H33: =F33-G33 -> 0.012 | I33: " | J33: "
B34: 17B-0021Z | C34: " | D34: 7.3 | F34: 1.901 | G34: 1.889 | H34: =F34-G34 -> 0.012 | I34: " | J34: "
B35: 17B-0022Z-R | C35: " | D35: 4.7 | F35: 1.901 | G35: 1.889 | H35: =F35-G35 -> 0.012 | I35: MI V1-R | J35: FA701353 | K35: 19.04.2017: 0.8/ 1.913/ 1.906 | L35: vormals 11081888 (unter Kleber 1106850)
B36: 17B-0023Z-R | C36: " | D36: 5.8 | F36: 1.914 | G36: 1.902 | H36: =F36-G36 -> 0.012 | I36: MI V1-R | J36: " | K36: 19.04.2017: 0.7/ 1.928/ 1.920 | L36: vormals 11111992 (unter Kleber 1107936)
B37: 16H-0012Z | C37: " | D37: 6.7 | F37: 1.903 | G37: 1.892 | H37: =F37-G37 -> 0.011 | I37: MI V3-R | J37: FA701356 | L37: vormals 16H-0012Z
B38: 17B-0024Z | C38: FA701049 | D38: 7.1 | F38: 1.898 | G38: 1.885 | H38: =F38-G38 -> 0.013 | I38: MI V3 | J38: FA701172
B39: 17B-0025Z | C39: " | D39: 6.6 | F39: 1.892 | G39: 1.876 | H39: =F39-G39 -> 0.016 | I39: " | J39: "
B40: 17B-0026Z | C40: " | D40: 6.9 | F40: 1.884 | G40: 1.87 | H40: =F40-G40 -> 0.014 | I40: " | J40: "
B41: 17B-0027Z | C41: " | D41: 10.8 | F41: 1.91 | G41: 1.899 | H41: =F41-G41 -> 0.011 | I41: " | J41: "
...

Sheet Mar
B2: Cell # | C2: Membran # ¦ Batch # | D2: Temp Kat / [°C] | E2: Membrane V @ 13 bar/[V] | F2: Cell V @ 13 bar/[V] | G2: Cell V @ 0 bar [V] | H2: Voltage Diff. / [V] | I2: Typ | J2: FA # | K2: Bemerkungen | M2: Visum | N2: Jahr: | O2: 2017
B3: 17C-0001Z | C3: 16K-0100M | D3: 0.2 | E3: 1.878 | F3: 3.76 | G3: 3.737 | H3: =F3-G3 -> 0.023 | I3: MU2 | J3: FA701252
C4: FA701095 | E4: 1.882
B5: 17C-0002Z | C5: " | D5: 0.3 | E5: 1.875 | F5: 3.755 | G5: 3.728 | H5: =F5-G5 -> 0.027 | I5: " | J5: "
C6: " | E6: 1.879
B7: 17C-0003Z | C7: " | D7: 0.7 | E7: 1.884 | F7: 3.781 | G7: 3.757 | H7: =F7-G7 -> 0.024 | I7: " | J7: "
C8: " | E8: 1.897
B9: 17C-0004Z | C9: " | D9: 0.5 | E9: 1.86 | F9: 3.722 | G9: 3.694 | H9: =F9-G9 -> 0.028 | I9: " | J9: "
C10: " | E10: 1.861
B11: 17C-0005Z | C11: " | D11: 0 | F11: 1.886 | G11: 1.872 | H11: =F11-G11 -> 0.014 | I11: MU1 | J11: FA700594
B12: 17C-0006Z | C12: " | D12: 0.4 | F12: 1.884 | G12: 1.87 | H12: =F12-G12 -> 0.014 | I12: " | J12: " | K12: Vlies filzig
B13: 17C-0007Z | C13: " | D13: 0.3 | F13: 1.885 | G13: 1.872 | H13: =F13-G13 -> 0.013 | I13: " | J13: " | K13: Vlies filzig
B14: 17C-0008Z | C14: " | D14: 0.2 | F14: 1.893 | G14: 1.883 | H14: =F14-G14 -> 0.01 | I14: " | J14: " | K14: Memb. kl. Faden
B15: 17C-0009Z | C15: " | D15: 0 | F15: 1.881 | G15: 1.868 | H15: =F15-G15 -> 0.013 | I15: " | J15: "
B16: 17C-0010Z | C16: " | D16: 0 | F16: 1.878 | G16: 1.864 | H16: =F16-G16 -> 0.014 | I16: " | J16: "
B17: 17C-0011Z-R | C17: " | D17: 0.5 | F17: 1.916 | G17: 1.906 | H17: =F17-G17 -> 0.01 | I17: MA V2- R | J17: FA701511 | K17: vormals 1308-4384
B18: 17C-0012Z-R | C18: " | D18: 0.3 | F18: 1.891 | G18: 1.879 | H18: =F18-G18 -> 0.012 | I18: MA V2- R | J18: " | K18: vormals 1308-4401
B19: 17C-0013Z-R | C19: " | D19: 0.3 | F19: 1.907 | G19: 1.894 | H19: =F19-G19 -> 0.013 | I19: MA V2- R | J19: FA701512 | K19: vormals 1412-5419
B20: 17C-0014Z | C20: " | D20: 0.2 | E20: 1.842 | F20: 5.499 | G20: 5.459 | H20: =F20-G20 -> 0.04 | I20: MU3 | J20: FA701428
C21: " | E21: 1.829
C22: " | E22: 1.828
B23: 17C-0015Z-R | C23: FA701093 | D23: 0.2 | F23: 1.919 | G23: 1.904 | H23: =F23-G23 -> 0.015 | I23: MI V2 | J23: FA701509 | K23: vormals 1509-2576
B24: 17C-0016Z-R | C24: " | D24: 0.5 | F24: 1.916 | G24: 1.904 | H24: =F24-G24 -> 0.012 | I24: MI V2 | J24: " | K24: vormals 1510-2633
B25: 17C-0017Z-R | C25: " | D25: 0.7 | F25: 1.918 | G25: 1.912 | H25: =F25-G25 -> 0.006 | I25: MI V2 | J25: FA701510 | K25: vormals 1504-2381A
B26: 17C-0018Z | C26: " | D26: 0.1 | F26: 1.881 | G26: 1.867 | H26: =F26-G26 -> 0.014 | I26: MI V3 | J26: FA701357
B27: 17C-0019Z | C27: " | D27: 0.4 | F27: 1.864 | G27: 1.85 | H27: =F27-G27 -> 0.014 | I27: " | J27: "
B28: 17C-0020Z | C28: " | D28: 0.2 | F28: 1.861 | G28: 1.847 | H28: =F28-G28 -> 0.014 | I28: " | J28: "
B29: 17C-0021Z | C29: " | D29: 0.5 | F29: 1.882 | G29: 1.866 | H29: =F29-G29 -> 0.016 | I29: " | J29: "
B30: 17C-0022Z | C30: " | D30: 0.3 | F30: 1.881 | G30: 1.866 | H30: =F30-G30 -> 0.015 | I30: " | J30: "
B31: 17C-0023Z | C31: " | D31: 0.3 | F31: 1.878 | G31: 1.864 | H31: =F31-G31 -> 0.014 | I31: " | J31: "
B32: 17C-0024Z | C32: " | D32: 0.2 | F32: 1.89 | G32: 1.876 | H32: =F32-G32 -> 0.014 | I32: " | J32: "
B33: 17C-0025Z | C33: FA701095 | D33: 0.3 | E33: 1.848 | F33: 3.702 | G33: 3.677 | H33: =F33-G33 -> 0.025 | I33: MU2 | J33: ?
C34: FA701096 | E34: 1.853
B35: 17C-0026Z | C35: " | D35: 0.3 | E35: 1.855 | F35: 3.71 | G35: 3.682 | H35: =F35-G35 -> 0.028 | I35: " | L35: ab 17C-0026Z neues Pl. Ch.-Nr 3502
C36: " | E36: 1.854
B37: 17C-0027Z | C37: " | D37: 0.5 | E37: 1.848 | F37: 3.703 | G37: 3.676 | H37: =F37-G37 -> 0.027 | I37: "
C38: " | E38: 1.855
B39: 17C-0028Z | C39: " | D39: 0.7 | E39: 1.855 | F39: 3.711 | G39: 3.69 | H39: =F39-G39 -> 0.021 | I39: "
C40: " | E40: 1.856
B41: M2-1604-077 | C41: " | D41: 0.3 | E41: 1.865 | F41: 3.736 | G41: 3.714 | H41: =F41-G41 -> 0.022 | I41: MU2 | J41: ? | K41: SS-Vliese= rostig
...

Sheet Apr
B2: Cell # | C2: Membran # ¦ Batch # | D2: Temp Kat / [°C] | E2: Membrane V @ 13 bar/[V] | F2: Cell V @ 13 bar/[V] | G2: Cell V @ 0 bar [V] | H2: Voltage Diff. / [V] | I2: Typ | J2: FA # | K2: Bemerkungen | M2: Visum | N2: Jahr: | O2: 2017
B3: 17D-0001Z | C3: FA701154 | D3: 0.5 | F3: 1.888 | G3: 1.878 | H3: =F3-G3 -> 0.01 | I3: MI V3 | J3: FA701357
B4: 17D-0002Z | C4: " | D4: 0.7 | F4: 1.883 | G4: 1.87 | H4: =F4-G4 -> 0.013 | I4: " | J4: "
B5: 17D-0003Z | C5: " | D5: 0.4 | F5: 1.881 | G5: 1.865 | H5: =F5-G5 -> 0.016 | I5: " | J5: "
B6: 17D-0004Z | C6: FA700908 | D6: 0.4 | F6: 1.873 | G6: 1.859 | H6: =F6-G6 -> 0.014 | I6: " | J6: "
B7: 17D-0005Z | C7: " | D7: 0.6 | F7: 1.865 | G7: 1.851 | H7: =F7-G7 -> 0.014 | I7: " | J7: "
B8: 17D-0006Z | C8: " | D8: 0.3 | F8: 1.865 | G8: 1.85 | H8: =F8-G8 -> 0.015 | I8: " | J8: "
B9: 17D-0007Z | C9: " | D9: 0.2 | F9: 1.853 | G9: 1.838 | H9: =F9-G9 -> 0.015 | I9: " | J9: "
B10: 17D-0008Z | C10: " | D10: 0 | F10: 1.831 | G10: 1.818 | H10: =F10-G10 -> 0.013 | I10: " | J10: "
B11: 17D-0009Z | C11: FA701100 | H11: =F11-G11 -> 0 | I11: MU1 | J11: FA701694
B12: 17D-0010Z | C12: " | D12: 1 | F12: 1.868 | G12: 1.856 | H12: =F12-G12 -> 0.012 | I12: " | J12: "
B13: 17D-0011Z | C13: " | D13: 0.8 | F13: 1.868 | G13: 1.859 | H13: =F13-G13 -> 0.009 | I13: " | J13: "
B14: 17D-0012Z | C14: " | D14: 0.9 | F14: 1.857 | G14: 1.843 | H14: =F14-G14 -> 0.014 | I14: " | J14: " | L14: Membrane Kratzer
B15: 17D-0013Z | C15: " | D15: 0.7 | E15: 1.85 | F15: 5.559 | G15: 5.522 | H15: =F15-G15 -> 0.037 | I15: MU3 | J15: FA701857 | K15: Ersatz für M3-1512-0032
C16: " | E16: 1.853
C17: " | E17: 1.856
B18: 17D-0014Z | C18: FA700908 | D18: 0.6 | F18: 1.874 | G18: 1.865 | H18: =F18-G18 -> 0.009 | I18: MI V3 | J18: FA701150
B19: 17D-0015Z | C19: " | D19: 0.7 | F19: 1.878 | G19: 1.866 | H19: =F19-G19 -> 0.012 | I19: " | J19: "
B20: 17D-0016Z | C20: " | D20: 0.6 | F20: 1.883 | G20: 1.873 | H20: =F20-G20 -> 0.01 | I20: " | J20: "
B21: 17D-0017Z | C21: " | D21: 0.6 | F21: 1.887 | G21: 1.877 | H21: =F21-G21 -> 0.01 | I21: " | J21: "
B22: 17D-0018Z | C22: " | D22: 0.7 | F22: 1.89 | G22: 1.88 | H22: =F22-G22 -> 0.01 | I22: " | J22: "
B23: 17D-0019Z | C23: " | D23: 0.4 | F23: 1.88 | G23: 1.87 | H23: =F23-G23 -> 0.01 | I23: " | J23: "
B24: 17D-0020Z | C24: " | D24: 0.7 | F24: 1.872 | G24: 1.865 | H24: =F24-G24 -> 0.007 | I24: " | J24: "
B25: 17D-0021Z | C25: " | D25: 0.6 | F25: 1.886 | G25: 1.877 | H25: =F25-G25 -> 0.009 | I25: " | J25: " | K25: 2 kleine Flecken und kl. Kratzer | L25: / auf Spülstation Zellspannung ist >2V/ Membrane gewechselt
B26: 17D-0022Z | C26: " | D26: 0.8 | F26: 1.88 | G26: 1.87 | H26: =F26-G26 -> 0.01 | I26: " | J26: "
B27: 17D-0023Z | C27: " | D27: 0.6 | F27: 1.883 | G27: 1.877 | H27: =F27-G27 -> 0.006 | I27: " | J27: "
B28: 17D-0024Z-R | C28: FA701100 | D28: 4.4 | F28: 1.918 | G28: 1.908 | H28: =F28-G28 -> 0.01 | I28: MA-V1-R | J28: FA701902 | K28: vormals: 0811-1241A
B29: 17D-0025Z-R | C29: " | D29: 8.4 | F29: 1.912 | G29: 1.905 | H29: =F29-G29 -> 0.007 | I29: " | J29: " | K29: vormals: 0711-0099
B30: 17D-0026Z-R | C30: " | D30: 7.4 | F30: 1.913 | G30: 1.906 | H30: =F30-G30 -> 0.007 | I30: " | J30: " | K30: vormals: 0711-0101
B31: 17D-0027Z-R | C31: " | D31: 4.3 | F31: 1.893 | G31: 1.884 | H31: =F31-G31 -> 0.009 | I31: " | J31: " | K31: vormals: 1301-3808A
B32: 17D-0028Z-R | C32: FA701099 | D32: 7.6 | F32: 1.887 | G32: 1.88 | H32: =F32-G32 -> 0.007 | I32: " | J32: " | K32: vormals: 1403-4892A
B33: 17D-0029Z-R | C33: FA700908 | D33: 0.8 | F33: 1.948 | G33: 1.94 | H33: =F33-G33 -> 0.008 | I33: MI-V2-R | J33: FA701901 | K33: vormals: 1511-2639
B34: 17D-0030Z-R | C34: " | D34: 1.3 | F34: 1.941 | G34: 1.934 | H34: =F34-G34 -> 0.007 | I34: " | J34: FA701903 | K34: vormals: 1505-2269
B35: 17D-0031Z-R | C35: " | D35: 0.8 | F35: 1.937 | G35: 1.929 | H35: =F35-G35 -> 0.008 | I35: " | J35: " | K35: vormals: 1505-2396
B36: 17D-0032Z-R | C36: " | D36: 0.9 | F36: 1.934 | G36: 1.925 | H36: =F36-G36 -> 0.009 | I36: " | J36: " | K36: vormals: 1507-2484
B37: 17D-0033Z | C37: FA701408 | D37: 1.2 | F37: 1.919 | G37: 1.911 | H37: =F37-G37 -> 0.008 | I37: MI V3 | J37: FA701905 | L37: Ersatz für MI-V1 17B-0022Z-R
B38: 17D-0034Z | C38: " | D38: 1.2 | F38: 1.91 | G38: 1.904 | H38: =F38-G38 -> 0.006 | I38: " | J38: " | L38: Ersatz für MI-V1 17B-0023Z-R
B39: 17D-0035Z | C39: " | D39: 1.4 | F39: 1.914 | G39: 1.907 | H39: =F39-G39 -> 0.007 | I39: " | J39: FA701150
B40: 17D-0036Z | C40: " | D40: 1.2 | F40: 1.913 | G40: 1.905 | H40: =F40-G40 -> 0.008 | I40: " | J40: "
B41: 17D-0037Z | C41: FA701100 | D41: 15.9 | E41: 1.845 | F41: 3.697 | G41: 3.675 | H41: =F41-G41 -> 0.022 | I41: MU2 | J41: FA701904 | K41: 38.4° | L41: Ersatz für MA's-V2-R 1502-5558/ 1502-5559
...

Sheet May
B2: Cell # | C2: Membran # ¦ Batch # | D2: Temp Kat / [°C] | E2: Membrane V @ 13 bar/[V] | F2: Cell V @ 13 bar/[V] | G2: Cell V @ 0 bar [V] | H2: Voltage Diff. / [V] | I2: Typ | J2: FA # | K2: Bemerkungen | M2: Visum | N2: Jahr: | O2: 2017
B3: 17E-0001Z | C3: FA701236 | D3: 2.2 | F3: 1.904 | G3: 1.891 | H3: =F3-G3 -> 0.013 | I3: MU1 | J3: FA701151 | L3: mit auto. Spülstops/ ohne Kurzschl.
B4: 17E-0002Z | C4: " | D4: 0.9 | F4: 1.87 | G4: 1.859 | H4: =F4-G4 -> 0.011 | I4: " | J4: " | L4: mit man. Spülstops/ ohne Kurzschl.
B5: 17E-0003Z | C5: " | D5: 1.5 | F5: 1.911 | G5: 1.899 | H5: =F5-G5 -> 0.012 | I5: " | J5: " | L5: mit auto. Spülstops/ ohne Kurzschl.
B6: 17E-0004Z | C6: " | D6: 1.6 | F6: 1.889 | G6: 1.882 | H6: =F6-G6 -> 0.007 | I6: " | J6: " | L6: mit man. Spülstops/ ohne Kurzschl.
B7: 17E-0005Z | C7: " | D7: 0.9 | F7: 1.902 | G7: 1.889 | H7: =F7-G7 -> 0.013 | I7: " | J7: " | L7: mit auto. Spülstops/ ohne Kurzschl.
B8: 17E-0006Z | C8: " | D8: 0.8 | F8: 1.892 | G8: 1.881 | H8: =F8-G8 -> 0.011 | I8: " | J8: " | K8: Memb.: kleiner Faden | L8: mit man. Spülstops/ ohne Kurzschl.
B9: 17E-0007Z | C9: " | D9: 1 | F9: 1.904 | G9: 1.892 | H9: =F9-G9 -> 0.012 | I9: " | J9: " | L9: mit auto. Spülstops/ ohne Kurzschl.
B10: 17E-0008Z | C10: " | D10: 1 | F10: 1.895 | G10: 1.887 | H10: =F10-G10 -> 0.008 | I10: " | J10: " | L10: mit man. Spülstops/ ohne Kurzschl.
B11: 17E-0009Z | C11: " | D11: 3/ 20° +.. | E11: 1.882 | F11: 5.659 | G11: 5.623 | H11: =F11-G11 -> 0.036 | I11: MU3 | J11: FA701153 | K11: Temp? | L11: mit auto. Spülstops/ ohne Kurzschl.
C12: " | E12: 1.888
C13: " | E13: 1.889
B14: " | D14: 0.5 | E14: 1.855 | F14: 5.57 | G14: 5.55 | H14: =F14-G14 -> 0.02 | K14: innerhalb 30min max. 0.9° | L14: anschliessend mit man. Spülstops/ ohne Kurzschl.
E15: 1.858
E16: 1.857
B17: 17E-0010Z | C17: " | D17: 0.8 | E17: 1.881 | F17: 5.627 | G17: 5.59 | H17: =F17-G17 -> 0.037 | I17: " | J17: " | L17: mit man. Spülstops/ ohne Kurzschl.
C18: " | E18: 1.873
C19: " | E19: 1.874
B20: 17E-0011Z | C20: " | D20: 3.3 | E20: 1.89 | F20: 5.685 | G20: 5.655 | H20: =F20-G20 -> 0.03 | I20: " | J20: " | K20: Temp? | L20: mit auto. Spülstops/ ohne Kurzschl.
C21: " | E21: 1.9
C22: " | E22: 1.895
B23: " | D23: 0.6 | E23: 1.879 | F23: 5.641 | G23: 5.62 | H23: =F23-G23 -> 0.021 | K23: innerhalb 15min max. 0.7° | L23: anschliessend mit man. Spülstops/ ohne Kurzschl.
E24: 1.884
E25: 1.878
B26: 17E-0012Z | C26: " | D26: 0.4 | E26: 1.888 | F26: 5.673 | G26: 5.638 | H26: =F26-G26 -> 0.035 | I26: " | J26: " | K26: konstant 20min: 0.4-1.2° | L26: mit man. Spülstops/ ohne Kurzschl.
C27: FA701237 | E27: 1.894 | K27: ab Membrane Nr19 neues Pl. Lot-MKBJ3600 (keine Membrane mit Nr19 beschriftet)
C28: " | E28: 1.89
B29: 17E-0013Z | C29: " | D29: 0.7 | E29: 1.845 | F29: 5.547 | G29: 5.51 | H29: =F29-G29 -> 0.037 | I29: " | J29: "
C30: " | E30: 1.852
C31: " | E31: 1.85
B32: 17E-0014Z-R | C32: " | D32: 0.9 | F32: 1.908 | G32: 1.899 | H32: =F32-G32 -> 0.009 | I32: MA-V1-R | J32: FA701919 | K32: vormals: 1210-3625 | L32: Ø knapp geschnitten
B33: 17E-0015Z-R | C33: FA701236 | D33: 0.8 | F33: 1.901 | G33: 1.889 | H33: =F33-G33 -> 0.012 | I33: MA-V1-R | J33: " | K33: vormals: 1404-4671A | L33: Membrane: Rand 2mm verschoben, + kleines Punktloch
B34: 17E-0016Z-R | C34: FA701237 | D34: 1 | F34: 1.891 | G34: 1.88 | H34: =F34-G34 -> 0.011 | I34: MA-V1-R | J34: " | K34: vormals: 1409-5236A
B35: 17E-0017Z-R | C35: " | D35: 0.3 | F35: 1.918 | G35: 1.907 | H35: =F35-G35 -> 0.011 | I35: MA-V1-R | J35: FA701920 | K35: vormals: 1601-6113A
B36: 17E-0018Z-R | C36: " | D36: 0.2 | F36: 1.906 | G36: 1.894 | H36: =F36-G36 -> 0.012 | I36: MA-V1-R | J36: " | K36: vormals: 1601-6114A
B37: 17E-0019Z-R | C37: " | D37: 0.9 | F37: 1.914 | G37: 1.904 | H37: =F37-G37 -> 0.01 | I37: MA-V2-R | J37: FA701921 | K37: vormals: 1311-4621
B38: 17E-0020Z-R | C38: " | D38: 0.7 | F38: 1.908 | G38: 1.894 | H38: =F38-G38 -> 0.014 | I38: MA-V1-R | J38: FA701924 | K38: vormals: 1307-4292A
B39: 17E-0021Z-R | C39: " | D39: 0.5 | F39: 1.916 | G39: 1.905 | H39: =F39-G39 -> 0.011 | I39: MA-V1-R | J39: " | K39: vormals: 1501-5502A
B40: 17E-0022Z-R | C40: " | D40: 0.9 | F40: 1.918 | G40: 1.91 | H40: =F40-G40 -> 0.008 | I40: MA-V1-R | J40: " | K40: vormals: 1501-5503A
B41: 16J-0001Z-R | C41: B24-0396 | D41: 0.5 | E41: 1.796 | F41: 5.401 | G41: 5.38 | H41: =F41-G41 -> 0.021 | I41: MU3 | J41: ohne | K41: vormals: 16J-0001Z | L41: Spannung zu hoch
...

Sheet Jun
B2: Cell # | C2: Membran # ¦ Batch # | D2: Temp Umgebung T2 / [°C] | E2: Temp Kat T1-T2 / [°C] | F2: Gasfluss / [sccm / min] | G2: Membrane V @ 13 bar/[V] | H2: Cell V @ 13 bar/[V] | I2: Cell V @ 0 bar [V] | J2: Voltage Diff. / [V] | K2: H2 Prod / [nmL/A] | L2: Typ | M2: Anzahl Layer | N2: Strom / [A] | O2: FA # | P2: Bemerkungen | R2: Visum | S2: Jahr: | T2: 2017
B3: 17F-0001Z | C3: FA701237 | G3: 1.812 | J3: =H3-I3 -> 0 | K3: =(F3*(273.15+D3)/273.15)/(M3*N3) -> 0 | L3: MU12 | M3: =VLOOKUP(L3,allgemein!$B$3:$C$11,2,FALSE) -> 12 | N3: 40 | O3: FA701186 | P3: PEEK- Stützring/ laserd Disc's
C4: " | G4: 1.806 | J4: =H4-I4 -> 0 | K4: =(F4*(273.15+D4)/273.15)/(M4*N4) -> #N/A | M4: =VLOOKUP(L4,allgemein!$B$3:$C$11,2,FALSE) -> #N/A | P4: Messung auf Spülanlage nach ca. 30 Std
C5: " | G5: 1.808 | J5: =H5-I5 -> 0 | K5: =(F5*(273.15+D5)/273.15)/(M5*N5) -> #N/A | M5: =VLOOKUP(L5,allgemein!$B$3:$C$11,2,FALSE) -> #N/A | P5: bei 30 A/ 5 bar
C6: " | G6: 1.811 | J6: =H6-I6 -> 0 | K6: =(F6*(273.15+D6)/273.15)/(M6*N6) -> #N/A | M6: =VLOOKUP(L6,allgemein!$B$3:$C$11,2,FALSE) -> #N/A
C7: " | G7: 1.814 | J7: =H7-I7 -> 0 | K7: =(F7*(273.15+D7)/273.15)/(M7*N7) -> #N/A | M7: =VLOOKUP(L7,allgemein!$B$3:$C$11,2,FALSE) -> #N/A
C8: " | G8: 1.814 | J8: =H8-I8 -> 0 | K8: =(F8*(273.15+D8)/273.15)/(M8*N8) -> #N/A | M8: =VLOOKUP(L8,allgemein!$B$3:$C$11,2,FALSE) -> #N/A
C9: " | G9: 1.825 | J9: =H9-I9 -> 0 | K9: =(F9*(273.15+D9)/273.15)/(M9*N9) -> #N/A | M9: =VLOOKUP(L9,allgemein!$B$3:$C$11,2,FALSE) -> #N/A
C10: FA701860 | G10: 1.809 | J10: =H10-I10 -> 0 | K10: =(F10*(273.15+D10)/273.15)/(M10*N10) -> #N/A | M10: =VLOOKUP(L10,allgemein!$B$3:$C$11,2,FALSE) -> #N/A
C11: " | G11: 1.818 | J11: =H11-I11 -> 0 | K11: =(F11*(273.15+D11)/273.15)/(M11*N11) -> #N/A | M11: =VLOOKUP(L11,allgemein!$B$3:$C$11,2,FALSE) -> #N/A
C12: " | G12: 1.817 | J12: =H12-I12 -> 0 | K12: =(F12*(273.15+D12)/273.15)/(M12*N12) -> #N/A | M12: =VLOOKUP(L12,allgemein!$B$3:$C$11,2,FALSE) -> #N/A
C13: " | G13: 1.817 | J13: =H13-I13 -> 0 | K13: =(F13*(273.15+D13)/273.15)/(M13*N13) -> #N/A | M13: =VLOOKUP(L13,allgemein!$B$3:$C$11,2,FALSE) -> #N/A
C14: " | G14: 1.817 | J14: =H14-I14 -> 0 | K14: =(F14*(273.15+D14)/273.15)/(M14*N14) -> #N/A | M14: =VLOOKUP(L14,allgemein!$B$3:$C$11,2,FALSE) -> #N/A
B15: 17F-0002Z | C15: " | D15: 26.4 | E15: 0.6 | F15: 540 | G15: 1.875 | H15: 3.751 | I15: 3.725 | J15: =H15-I15 -> 0.026 | K15: =(F15*(273.15+D15)/273.15)/(M15*N15) -> 7.4023888 | L15: MU2 | M15: =VLOOKUP(L15,allgemein!$B$3:$C$11,2,FALSE) -> 2 | N15: 40 | O15: FA701872 | P15: Spülanlage "autostops" V1.1; während Nacht ohne Stops
C16: " | G16: 1.876 | J16: =H16-I16 -> 0 | K16: =(F16*(273.15+D16)/273.15)/(M16*N16) -> #N/A | M16: =VLOOKUP(L16,allgemein!$B$3:$C$11,2,FALSE) -> #N/A
B17: 17F-0003Z | C17: " | D17: 26.6 | E17: 0.7 | F17: 537 | G17: 1.873 | H17: 3.743 | I17: 3.715 | J17: =H17-I17 -> 0.028 | K17: =(F17*(273.15+D17)/273.15)/(M17*N17) -> 7.3661793 | L17: MU2 | M17: =VLOOKUP(L17,allgemein!$B$3:$C$11,2,FALSE) -> 2 | N17: 40 | O17: " | P17: "
C18: " | G18: 1.87 | J18: =H18-I18 -> 0 | K18: =(F18*(273.15+D18)/273.15)/(M18*N18) -> #N/A | M18: =VLOOKUP(L18,allgemein!$B$3:$C$11,2,FALSE) -> #N/A
B19: 17F-0004Z | C19: " | D19: 26.5 | E19: 0.5 | F19: 543 | G19: 1.87 | H19: 3.746 | I19: 3.715 | J19: =H19-I19 -> 0.031 | K19: =(F19*(273.15+D19)/273.15)/(M19*N19) -> 7.4459981 | L19: MU2 | M19: =VLOOKUP(L19,allgemein!$B$3:$C$11,2,FALSE) -> 2 | N19: 40 | O19: " | P19: "
C20: " | G20: 1.875 | J20: =H20-I20 -> 0 | K20: =(F20*(273.15+D20)/273.15)/(M20*N20) -> #N/A | M20: =VLOOKUP(L20,allgemein!$B$3:$C$11,2,FALSE) -> #N/A
B21: 17F-0005Z | C21: " | D21: 26.5 | E21: 0.9 | F21: 540 | G21: 1.868 | H21: 3.736 | I21: 3.707 | J21: =H21-I21 -> 0.029 | K21: =(F21*(273.15+D21)/273.15)/(M21*N21) -> 7.40486 | L21: MU2 | M21: =VLOOKUP(L21,allgemein!$B$3:$C$11,2,FALSE) -> 2 | N21: 40 | O21: " | P21: "
C22: " | G22: 1.867 | J22: =H22-I22 -> 0 | K22: =(F22*(273.15+D22)/273.15)/(M22*N22) -> #N/A | M22: =VLOOKUP(L22,allgemein!$B$3:$C$11,2,FALSE) -> #N/A
B23: 17F-0006Z | C23: " | D23: 25.3 | E23: 1.3 | F23: 265 | H23: 1.871 | I23: 1.852 | J23: =H23-I23 -> 0.019 | K23: =(F23*(273.15+D23)/273.15)/(M23*N23) -> 7.238628 | L23: MU1 | M23: =VLOOKUP(L23,allgemein!$B$3:$C$11,2,FALSE) -> 1 | N23: 40 | O23: FA701873 | P23: "
B24: 17F-0007Z | C24: " | D24: 25.2 | E24: 1.3 | F24: 264 | H24: 1.859 | I24: 1.843 | J24: =H24-I24 -> 0.016 | K24: =(F24*(273.15+D24)/273.15)/(M24*N24) -> 7.2088962 | L24: MU1 | M24: =VLOOKUP(L24,allgemein!$B$3:$C$11,2,FALSE) -> 1 | N24: 40 | O24: " | P24: "
B25: 17F-0008Z | C25: " | D25: 25.4 | E25: 1.5 | F25: 265 | H25: 1.847 | I25: 1.832 | J25: =H25-I25 -> 0.015 | K25: =(F25*(273.15+D25)/273.15)/(M25*N25) -> 7.2410535 | L25: MU1 | M25: =VLOOKUP(L25,allgemein!$B$3:$C$11,2,FALSE) -> 1 | N25: 40 | O25: " | P25: "
B26: 17F-0009Z | C26: " | D26: 25.2 | E26: 1.1 | F26: 270 | H26: 1.848 | I26: 1.829 | J26: =H26-I26 -> 0.019 | K26: =(F26*(273.15+D26)/273.15)/(M26*N26) -> 7.3727348 | L26: MU1 | M26: =VLOOKUP(L26,allgemein!$B$3:$C$11,2,FALSE) -> 1 | N26: 40 | O26: " | P26: " | Q26: Membrane: kleiner Tropfen
B27: M1-1604-062 | C27: n/a | D27: 26.5 | E27: 0.1 | F27: 272 | G27: 1.861 | H27: 1.861 | I27: 1.853 | J27: =H27-I27 -> 0.008 | K27: =(F27*(273.15+D27)/273.15)/(M27*N27) -> 7.4597108 | L27: MU1 | M27: =VLOOKUP(L27,allgemein!$B$3:$C$11,2,FALSE) -> 1 | N27: 40 | P27: war 2.5V/ verschmutzt -Membrane in Säure-
B28: 17F-0010Z-R | C28: FA701410 | D28: 26 | E28: 0.5 | F28: 164 | H28: 1.949 | I28: 1.936 | J28: =H28-I28 -> 0.013 | K28: =(F28*(273.15+D28)/273.15)/(M28*N28) -> 7.1844188 | L28: MI_V2 | M28: =VLOOKUP(L28,allgemein!$B$3:$C$11,2,FALSE) -> 1 | N28: 25 | O28: FA702110 | P28: > 3.5V vormals: 1501-2259 | Q28: man. Spülstops
B29: 17F-0011Z | C29: " | D29: 26.1 | E29: 0.6 | F29: 166 | H29: 1.914 | I29: 1.899 | J29: =H29-I29 -> 0.015 | K29: =(F29*(273.15+D29)/273.15)/(M29*N29) -> 7.2744646 | L29: MI_V3 | M29: =VLOOKUP(L29,allgemein!$B$3:$C$11,2,FALSE) -> 1 | N29: 25 | O29: FA701900 | Q29: "
B30: 17F-0012Z | C30: " | D30: 26 | E30: 0.5 | F30: 162 | H30: 1.891 | I30: 1.875 | J30: =H30-I30 -> 0.016 | K30: =(F30*(273.15+D30)/273.15)/(M30*N30) -> 7.096804 | L30: MI_V3 | M30: =VLOOKUP(L30,allgemein!$B$3:$C$11,2,FALSE) -> 1 | N30: 25 | O30: " | Q30: "
B31: 17F-0013Z | C31: " | D31: 25.9 | E31: 0.7 | F31: 165 | H31: 1.914 | I31: 1.901 | J31: =H31-I31 -> 0.013 | K31: =(F31*(273.15+D31)/273.15)/(M31*N31) -> 7.22581 | L31: MI_V3 | M31: =VLOOKUP(L31,allgemein!$B$3:$C$11,2,FALSE) -> 1 | N31: 25 | O31: " | Q31: "
B32: 17F-0014Z | C32: " | D32: 26.2 | E32: 0.4 | F32: 163 | H32: 1.918 | I32: 1.904 | J32: =H32-I32 -> 0.014 | K32: =(F32*(273.15+D32)/273.15)/(M32*N32) -> 7.1453853 | L32: MI_V3 | M32: =VLOOKUP(L32,allgemein!$B$3:$C$11,2,FALSE) -> 1 | N32: 25 | O32: " | Q32: "
B33: 17F-0015Z | C33: " | D33: 26.8 | E33: 0.3 | F33: 162 | H33: 1.892 | I33: 1.878 | J33: =H33-I33 -> 0.014 | K33: =(F33*(273.15+D33)/273.15)/(M33*N33) -> 7.1157825 | L33: MI_V3 | M33: =VLOOKUP(L33,allgemein!$B$3:$C$11,2,FALSE) -> 1 | N33: 25 | O33: FA702080 | Q33: "
B34: 17F-0016Z | C34: " | D34: 26.7 | E34: 0.3 | F34: 171 | H34: 1.893 | I34: 1.879 | J34: =H34-I34 -> 0.014 | K34: =(F34*(273.15+D34)/273.15)/(M34*N34) -> 7.5085997 | L34: MI_V3 | M34: =VLOOKUP(L34,allgemein!$B$3:$C$11,2,FALSE) -> 1 | N34: 25 | O34: " | Q34: "
B35: 17F-0017Z | C35: " | D35: 26.8 | E35: 0.3 | F35: 162 | H35: 1.884 | I35: 1.872 | J35: =H35-I35 -> 0.012 | K35: =(F35*(273.15+D35)/273.15)/(M35*N35) -> 7.1157825 | L35: MI_V3 | M35: =VLOOKUP(L35,allgemein!$B$3:$C$11,2,FALSE) -> 1 | N35: 25 | O35: " | Q35: " (Memb: kleiner Faden)
B36: 17F-0018Z | C36: " | D36: 26.5 | E36: 0.3 | F36: 167 | H36: 1.891 | I36: 1.876 | J36: =H36-I36 -> 0.015 | K36: =(F36*(273.15+D36)/273.15)/(M36*N36) -> 7.3280688 | L36: MI_V3 | M36: =VLOOKUP(L36,allgemein!$B$3:$C$11,2,FALSE) -> 1 | N36: 25 | O36: " | Q36: "
B37: 17F-0019Z | C37: " | D37: 26.1 | E37: 0.4 | F37: 164 | H37: 1.889 | I37: 1.876 | J37: =H37-I37 -> 0.013 | K37: =(F37*(273.15+D37)/273.15)/(M37*N37) -> 7.1868204 | L37: MI_V3 | M37: =VLOOKUP(L37,allgemein!$B$3:$C$11,2,FALSE) -> 1 | N37: 25 | O37: " | Q37: "
B38: 17F-0020Z | C38: " | D38: 25.3 | E38: 1 | F38: 170 | H38: 1.887 | I38: 1.874 | J38: =H38-I38 -> 0.013 | K38: =(F38*(273.15+D38)/273.15)/(M38*N38) -> 7.4298371 | L38: MI_V3 | M38: =VLOOKUP(L38,allgemein!$B$3:$C$11,2,FALSE) -> 1 | N38: 25 | O38: " | Q38: "
B39: 17F-0021Z | C39: " | D39: 25 | E39: 0.5 | F39: 166 | H39: 1.902 | I39: 1.888 | J39: =H39-I39 -> 0.014 | K39: =(F39*(273.15+D39)/273.15)/(M39*N39) -> 7.2477247 | L39: MI_V3 | M39: =VLOOKUP(L39,allgemein!$B$3:$C$11,2,FALSE) -> 1 | N39: 25 | O39: " | Q39: "
B40: 17F-0022Z | C40: " | D40: 25 | E40: 0.3 | F40: 163 | H40: 1.907 | I40: 1.897 | J40: =H40-I40 -> 0.01 | K40: =(F40*(273.15+D40)/273.15)/(M40*N40) -> 7.1167417 | L40: MI_V3 | M40: =VLOOKUP(L40,allgemein!$B$3:$C$11,2,FALSE) -> 1 | N40: 25 | O40: " | Q40: "
B41: 17F-0023Z | C41: " | D41: 24.9 | E41: 0.3 | F41: 169 | H41: 1.901 | I41: 1.889 | J41: =H41-I41 -> 0.012 | K41: =(F41*(273.15+D41)/273.15)/(M41*N41) -> 7.3762328 | L41: MI_V3 | M41: =VLOOKUP(L41,allgemein!$B$3:$C$11,2,FALSE) -> 1 | N41: 25 | O41: " | P41: von Me. Nr. 14 Neue Filterplatte (F) | Q41: "
...

Sheet Jul
B2: Cell # | C2: Membran # ¦ Batch # | D2: Temp Umgebung T2 / [°C] | E2: Temp Kat T1-T2 / [°C] | F2: Gasfluss / [sccm / min] | G2: Membrane V @ 13 bar/[V] | H2: Cell V @ 13 bar/[V] | I2: Cell V @ 0 bar [V] | J2: Voltage Diff. / [V] | K2: H2 Prod / [nmL/A] | L2: Typ | M2: Anzahl Layer | N2: Strom / [A] | O2: FA # | P2: Bemerkungen | R2: Visum | S2: Jahr: | T2: 2017
B3: 17B-0035Z-R | C3: FA700977 | D3: 28.3 | E3: 0.5 | G3: 1.831 | H3: 3.677 | I3: 3.655 | J3: =H3-I3 -> 0.022 | K3: =(F3*(273.15+D3)/273.15)/(M3*N3) -> 0 | L3: MU2 | M3: =VLOOKUP(L3,allgemein!$B$3:$C$11,2,FALSE) -> 2 | N3: 40 | O3: FA702313 | P3: vormals: 17B-0035Z
C4: FA701862 | G4: 1.845
B5: 17G-0001Z-R | C5: " | D5: 28.6 | E5: 0.5 | H5: 1.909 | I5: 1.894 | J5: =H5-I5 -> 0.015 | K5: =(F5*(273.15+D5)/273.15)/(M5*N5) -> 0 | L5: MA_V2 | M5: =VLOOKUP(L5,allgemein!$B$3:$C$11,2,FALSE) -> 1 | N5: 40 | O5: FA702312 | P5: vormals: 1510-6043
B6: 17G-0002Z | C6: " | D6: 28.6 | E6: 0.7 | G6: 1.843 | H6: 5.525 | I6: 5.482 | J6: =H6-I6 -> 0.043 | K6: =(F6*(273.15+D6)/273.15)/(M6*N6) -> 0 | L6: MU3 | M6: =VLOOKUP(L6,allgemein!$B$3:$C$11,2,FALSE) -> 3 | N6: 40 | O6: FA701983
C7: " | G7: 1.844
C8: " | G8: 1.837
B9: 17G-0003Z | C9: " | D9: 28.7 | E9: 0.3 | G9: 1.862 | H9: 5.584 | I9: 5.544 | J9: =H9-I9 -> 0.04 | K9: =(F9*(273.15+D9)/273.15)/(M9*N9) -> 0 | L9: MU3 | M9: =VLOOKUP(L9,allgemein!$B$3:$C$11,2,FALSE) -> 3 | N9: 40 | O9: "
C10: " | G10: 1.859
C11: " | G11: 1.862
B12: 17G-0004Z | C12: FA701863 | D12: 28.6 | E12: 0.2 | G12: 1.868 | H12: 5.613 | I12: 5.577 | J12: =H12-I12 -> 0.036 | K12: =(F12*(273.15+D12)/273.15)/(M12*N12) -> 0 | L12: MU3 | M12: =VLOOKUP(L12,allgemein!$B$3:$C$11,2,FALSE) -> 3 | N12: 40 | O12: "
C13: " | G13: 1.869
C14: " | G14: 1.876
B15: 17G-0005Z | C15: " | D15: 28 | E15: 0.1 | G15: 1.875 | H15: 5.624 | I15: 5.583 | J15: =H15-I15 -> 0.041 | K15: =(F15*(273.15+D15)/273.15)/(M15*N15) -> 0 | L15: MU3 | M15: =VLOOKUP(L15,allgemein!$B$3:$C$11,2,FALSE) -> 3 | N15: 40 | O15: "
C16: " | G16: 1.872
C17: " | G17: 1.876
B18: 17G-0006Z | C18: " | D18: 29.2 | E18: 0.9 | H18: 1.87 | I18: 1.86 | J18: =H18-I18 -> 0.01 | K18: =(F18*(273.15+D18)/273.15)/(M18*N18) -> 0 | L18: MU1 | M18: =VLOOKUP(L18,allgemein!$B$3:$C$11,2,FALSE) -> 1 | N18: 40 | O18: FA701910
B19: 17G-0007Z | C19: " | D19: 28.9 | E19: 0.5 | H19: 1.883 | I19: 1.869 | J19: =H19-I19 -> 0.014 | K19: =(F19*(273.15+D19)/273.15)/(M19*N19) -> 0 | L19: MU1 | M19: =VLOOKUP(L19,allgemein!$B$3:$C$11,2,FALSE) -> 1 | N19: 40 | O19: "
B20: 17G-0008Z | C20: " | D20: 28.9 | E20: 0.4 | H20: 1.888 | I20: 1.876 | J20: =H20-I20 -> 0.012 | K20: =(F20*(273.15+D20)/273.15)/(M20*N20) -> 0 | L20: MU1 | M20: =VLOOKUP(L20,allgemein!$B$3:$C$11,2,FALSE) -> 1 | N20: 40 | O20: "
B21: 17G-0009Z | C21: " | D21: 28.9 | E21: 0.7 | H21: 1.887 | I21: 1.873 | J21: =H21-I21 -> 0.014 | K21: =(F21*(273.15+D21)/273.15)/(M21*N21) -> 0 | L21: MU1 | M21: =VLOOKUP(L21,allgemein!$B$3:$C$11,2,FALSE) -> 1 | N21: 40 | O21: "
B22: 17G-0010Z | C22: " | D22: 28.8 | E22: 0.7 | H22: 1.883 | I22: 1.868 | J22: =H22-I22 -> 0.015 | K22: =(F22*(273.15+D22)/273.15)/(M22*N22) -> 0 | L22: MU1 | M22: =VLOOKUP(L22,allgemein!$B$3:$C$11,2,FALSE) -> 1 | N22: 40 | O22: "
B23: 17G-0011Z | C23: " | D23: 28.8 | E23: 0.5 | H23: 1.878 | I23: 1.866 | J23: =H23-I23 -> 0.012 | K23: =(F23*(273.15+D23)/273.15)/(M23*N23) -> 0 | L23: MU1 | M23: =VLOOKUP(L23,allgemein!$B$3:$C$11,2,FALSE) -> 1 | N23: 40 | O23: "
B24: 17G-0012Z | C24: " | D24: 29 | E24: 0.5 | H24: 1.875 | I24: 1.863 | J24: =H24-I24 -> 0.012 | K24: =(F24*(273.15+D24)/273.15)/(M24*N24) -> 0 | L24: MU1 | M24: =VLOOKUP(L24,allgemein!$B$3:$C$11,2,FALSE) -> 1 | N24: 40 | O24: "
B25: 17G-0013Z | C25: " | D25: 29 | E25: 0.8 | H25: 1.863 | I25: 1.85 | J25: =H25-I25 -> 0.013 | K25: =(F25*(273.15+D25)/273.15)/(M25*N25) -> 0 | L25: MU1 | M25: =VLOOKUP(L25,allgemein!$B$3:$C$11,2,FALSE) -> 1 | N25: 40 | O25: " | P25: H-seitig lasered Disc
B26: 17G-0014Z | C26: " | D26: 29.1 | E26: 0.8 | H26: 1.854 | I26: 1.843 | J26: =H26-I26 -> 0.011 | K26: =(F26*(273.15+D26)/273.15)/(M26*N26) -> 0 | L26: MU1 | M26: =VLOOKUP(L26,allgemein!$B$3:$C$11,2,FALSE) -> 1 | N26: 40 | O26: " | P26: "
B27: 17G-0015Z | C27: " | D27: 27.8 | E27: 0.8 | H27: 1.885 | I27: 1.872 | J27: =H27-I27 -> 0.013 | K27: =(F27*(273.15+D27)/273.15)/(M27*N27) -> 0 | L27: MU1 | M27: =VLOOKUP(L27,allgemein!$B$3:$C$11,2,FALSE) -> 1 | N27: 40 | O27: " | P27: Lasered Disc's PEEK Stützring
B28: 17G-0016Z | C28: " | D28: 27.8 | E28: 0.7 | H28: 1.886 | I28: 1.871 | J28: =H28-I28 -> 0.015 | K28: =(F28*(273.15+D28)/273.15)/(M28*N28) -> 0 | L28: MU1 | M28: =VLOOKUP(L28,allgemein!$B$3:$C$11,2,FALSE) -> 1 | N28: 40 | O28: "
B29: 17G-0017Z | C29: " | D29: 27.8 | E29: 0.6 | H29: 1.883 | I29: 1.869 | J29: =H29-I29 -> 0.014 | K29: =(F29*(273.15+D29)/273.15)/(M29*N29) -> 0 | L29: MU1 | M29: =VLOOKUP(L29,allgemein!$B$3:$C$11,2,FALSE) -> 1 | N29: 40 | O29: "
B30: 17G-0018Z | C30: " | D30: 27.8 | E30: 0.8 | H30: 1.897 | I30: 1.886 | J30: =H30-I30 -> 0.011 | K30: =(F30*(273.15+D30)/273.15)/(M30*N30) -> 0 | L30: MU1 | M30: =VLOOKUP(L30,allgemein!$B$3:$C$11,2,FALSE) -> 1 | N30: 40 | O30: "
B31: 17G-0019Z | C31: " | D31: 27.7 | E31: 0.7 | H31: 1.886 | I31: 1.874 | J31: =H31-I31 -> 0.012 | K31: =(F31*(273.15+D31)/273.15)/(M31*N31) -> 0 | L31: MU1 | M31: =VLOOKUP(L31,allgemein!$B$3:$C$11,2,FALSE) -> 1 | N31: 40 | O31: "
B32: 17G-0020Z | C32: FA701864 | D32: 27.3 | E32: 0.3 | H32: 1.891 | I32: 1.878 | J32: =H32-I32 -> 0.013 | K32: =(F32*(273.15+D32)/273.15)/(M32*N32) -> 0 | L32: MU1 | M32: =VLOOKUP(L32,allgemein!$B$3:$C$11,2,FALSE) -> 1 | N32: 40 | O32: " | P32: Alle Mem. leicht transparente Stellen
B33: 17G-0021Z | C33: " | D33: 27.9 | E33: 1 | H33: 1.867 | I33: 1.857 | J33: =H33-I33 -> 0.01 | K33: =(F33*(273.15+D33)/273.15)/(M33*N33) -> 0 | L33: MU1 | M33: =VLOOKUP(L33,allgemein!$B$3:$C$11,2,FALSE) -> 1 | N33: 40 | O33: " | P33: "
B34: 17G-0022Z | C34: " | D34: 27.1 | E34: 0.3 | H34: 1.872 | I34: 1.86 | J34: =H34-I34 -> 0.012 | K34: =(F34*(273.15+D34)/273.15)/(M34*N34) -> 0 | L34: MU1 | M34: =VLOOKUP(L34,allgemein!$B$3:$C$11,2,FALSE) -> 1 | N34: 40 | O34: " | P34: "
B35: 17G-0023Z | C35: " | D35: 26.9 | E35: 0.4 | H35: 1.88 | I35: 1.869 | J35: =H35-I35 -> 0.011 | K35: =(F35*(273.15+D35)/273.15)/(M35*N35) -> 0 | L35: MU1 | M35: =VLOOKUP(L35,allgemein!$B$3:$C$11,2,FALSE) -> 1 | N35: 40 | O35: " | P35: "
B36: 17C-0030Z | C36: FA701096 | D36: 28.6 | E36: 0 | G36: 1.741 | H36: 5.237 | I36: 5.212 | J36: =H36-I36 -> 0.025 | K36: =(F36*(273.15+D36)/273.15)/(M36*N36) -> 0 | L36: MU3 | M36: =VLOOKUP(L36,allgemein!$B$3:$C$11,2,FALSE) -> 3 | N36: 40 | O36: ohne | P36: nur Nachmessung
C37: " | G37: 1.748
C38: " | G38: 1.748
B39: 17G-0024Z | C39: FA701410 | D39: 28.7 | E39: 0.7 | H39: 1.855 | I39: 1.838 | J39: =H39-I39 -> 0.017 | K39: =(F39*(273.15+D39)/273.15)/(M39*N39) -> 0 | L39: MI_V3 | M39: =VLOOKUP(L39,allgemein!$B$3:$C$11,2,FALSE) -> 1 | N39: 25 | O39: FA701954
B40: 17G-0025Z | C40: " | D40: 28.6 | E40: 0.6 | H40: 1.87 | I40: 1.852 | J40: =H40-I40 -> 0.018 | K40: =(F40*(273.15+D40)/273.15)/(M40*N40) -> 0 | L40: MI_V3 | M40: =VLOOKUP(L40,allgemein!$B$3:$C$11,2,FALSE) -> 1 | N40: 25 | O40: "
B41: 17G-0026Z | C41: " | D41: 28.8 | E41: 0.8 | H41: 1.882 | I41: 1.87 | J41: =H41-I41 -> 0.012 | K41: =(F41*(273.15+D41)/273.15)/(M41*N41) -> 0 | L41: MI_V3 | M41: =VLOOKUP(L41,allgemein!$B$3:$C$11,2,FALSE) -> 1 | N41: 25 | O41: "
...

Sheet Aug
B2: Cell # | C2: Membran # ¦ Batch # | D2: Temp Gas / [°C] | E2: Temp Kat T1-T2 / [°C] | F2: Gasfluss / [sccm / min] | G2: Membrane V @ 13 bar/[V] | H2: Cell V @ 13 bar/[V] | I2: Cell V @ 0 bar [V] | J2: Voltage Diff. / [V] | K2: H2 Prod / [nmL/A] | L2: Typ | M2: Anzahl Layer | N2: Strom / [A] | O2: FA # | P2: Bemerkungen | R2: Visum | S2: Jahr: | T2: 2017
B3: 17H-0001Z | C3: FA701864 | D3: 29.1 | E3: 0.7 | F3: 547 | G3: 1.857 | H3: 3.717 | I3: 3.696 | J3: =H3-I3 -> 0.021 | K3: =(F3*(273.15+D3)/273.15)/(M3*N3) -> 7.5659322 | L3: MU2 | M3: =VLOOKUP(L3,allgemein!$B$3:$C$11,2,FALSE) -> 2 | N3: 40 | O3: FA701152
C4: " | G4: 1.859
B5: 17H-0002Z | C5: " | D5: 29.5 | E5: 0.6 | F5: 546 | G5: 1.845 | H5: 3.693 | I5: 3.671 | J5: =H5-I5 -> 0.022 | K5: =(F5*(273.15+D5)/273.15)/(M5*N5) -> 7.562095 | L5: MU2 | M5: =VLOOKUP(L5,allgemein!$B$3:$C$11,2,FALSE) -> 2 | N5: 40 | O5: "
C6: " | G6: 1.847
B7: 17H-0003Z | C7: " | D7: 29.4 | E7: 0.8 | F7: 543 | G7: 1.86 | H7: 3.725 | I7: 3.707 | J7: =H7-I7 -> 0.018 | K7: =(F7*(273.15+D7)/273.15)/(M7*N7) -> 7.5180601 | L7: MU2 | M7: =VLOOKUP(L7,allgemein!$B$3:$C$11,2,FALSE) -> 2 | N7: 40 | O7: "
C8: " | G8: 1.865 | P8: Mem. Mehrere kleine Punktlöcher
B9: 17H-0004Z | C9: " | D9: 29.2 | E9: 0.9 | F9: 544 | G9: 1.855 | H9: 3.719 | I9: 3.699 | J9: =H9-I9 -> 0.02 | K9: =(F9*(273.15+D9)/273.15)/(M9*N9) -> 7.5269266 | L9: MU2 | M9: =VLOOKUP(L9,allgemein!$B$3:$C$11,2,FALSE) -> 2 | N9: 40 | O9: "
C10: " | G10: 1.863
B11: 17H-0005Z | C11: " | D11: 29.5 | E11: 0.9 | F11: 545 | G11: 1.858 | H11: 3.715 | I11: 3.689 | J11: =H11-I11 -> 0.026 | K11: =(F11*(273.15+D11)/273.15)/(M11*N11) -> 7.548245 | L11: MU2 | M11: =VLOOKUP(L11,allgemein!$B$3:$C$11,2,FALSE) -> 2 | N11: 40 | O11: "
C12: " | G12: 1.857 | P12: Mem. Mehrere kleine Punktlöcher
B13: 17H-0006Z | C13: " | D13: 29.6 | E13: 0.9 | F13: 545 | G13: 1.861 | H13: 3.719 | I13: 3.695 | J13: =H13-I13 -> 0.024 | K13: =(F13*(273.15+D13)/273.15)/(M13*N13) -> 7.5507391 | L13: MU2 | M13: =VLOOKUP(L13,allgemein!$B$3:$C$11,2,FALSE) -> 2 | N13: 40 | O13: "
C14: " | G14: 1.858
B15: 17H-0007Z | C15: " | D15: 29.8 | E15: 0.5 | F15: 544 | G15: 1.86 | H15: 3.718 | I15: 3.693 | J15: =H15-I15 -> 0.025 | K15: =(F15*(273.15+D15)/273.15)/(M15*N15) -> 7.5418634 | L15: MU2 | M15: =VLOOKUP(L15,allgemein!$B$3:$C$11,2,FALSE) -> 2 | N15: 40 | O15: "
C16: " | G16: 1.858
B17: 17H-0008Z | C17: " | D17: 29.7 | E17: 0.7 | F17: 544 | G17: 1.862 | H17: 3.733 | I17: 3.713 | J17: =H17-I17 -> 0.02 | K17: =(F17*(273.15+D17)/273.15)/(M17*N17) -> 7.539374 | L17: MU2 | M17: =VLOOKUP(L17,allgemein!$B$3:$C$11,2,FALSE) -> 2 | N17: 40 | O17: "
C18: FA702175 | G18: 1.87
B19: 17H-0009Z | C19: " | D19: 29.8 | E19: 0.7 | F19: 544 | G19: 1.87 | H19: 3.74 | I19: 3.72 | J19: =H19-I19 -> 0.02 | K19: =(F19*(273.15+D19)/273.15)/(M19*N19) -> 7.5418634 | L19: MU2 | M19: =VLOOKUP(L19,allgemein!$B$3:$C$11,2,FALSE) -> 2 | N19: 40 | O19: "
C20: " | G20: 1.87
B21: 17H-0010Z | C21: " | D21: 29.9 | E21: 0.7 | F21: 545 | G21: 1.871 | H21: 3.741 | I21: 3.718 | J21: =H21-I21 -> 0.023 | K21: =(F21*(273.15+D21)/273.15)/(M21*N21) -> 7.5582212 | L21: MU2 | M21: =VLOOKUP(L21,allgemein!$B$3:$C$11,2,FALSE) -> 2 | N21: 40 | O21: "
C22: " | G22: 1.87
B23: 17H-0011Z | C23: " | D23: 29 | E23: 0.3 | F23: 551 | G23: 1.87 | H23: 3.743 | I23: 3.72 | J23: =H23-I23 -> 0.023 | K23: =(F23*(273.15+D23)/273.15)/(M23*N23) -> 7.6187374 | L23: MU2 | M23: =VLOOKUP(L23,allgemein!$B$3:$C$11,2,FALSE) -> 2 | N23: 40 | O23: "
C24: " | G24: 1.873
B25: 17H-0012Z | C25: " | D25: 29.3 | E25: 0.2 | F25: 547 | G25: 1.863 | H25: 3.727 | I25: 3.704 | J25: =H25-I25 -> 0.023 | K25: =(F25*(273.15+D25)/273.15)/(M25*N25) -> 7.5709386 | L25: MU2 | M25: =VLOOKUP(L25,allgemein!$B$3:$C$11,2,FALSE) -> 2 | N25: 40 | O25: "
C26: " | G26: 1.864
B27: 17H-0013Z | C27: " | D27: 29.5 | E27: 0.2 | F27: 547 | G27: 1.862 | H27: 3.723 | I27: 3.701 | J27: =H27-I27 -> 0.022 | K27: =(F27*(273.15+D27)/273.15)/(M27*N27) -> 7.575945 | L27: MU2 | M27: =VLOOKUP(L27,allgemein!$B$3:$C$11,2,FALSE) -> 2 | N27: 40 | O27: "
C28: " | G28: 1.86
B29: 17H-0014Z | C29: " | D29: 29.6 | E29: 0.2 | F29: 548 | G29: 1.852 | H29: 3.706 | I29: 3.681 | J29: =H29-I29 -> 0.025 | K29: =(F29*(273.15+D29)/273.15)/(M29*N29) -> 7.5923028 | L29: MU2 | M29: =VLOOKUP(L29,allgemein!$B$3:$C$11,2,FALSE) -> 2 | N29: 40 | O29: "
C30: " | G30: 1.854
B31: 17H-0015Z | C31: " | D31: 29.6 | E31: 0.4 | F31: 546 | G31: 1.858 | H31: 3.714 | I31: 3.692 | J31: =H31-I31 -> 0.022 | K31: =(F31*(273.15+D31)/273.15)/(M31*N31) -> 7.5645936 | L31: MU2 | M31: =VLOOKUP(L31,allgemein!$B$3:$C$11,2,FALSE) -> 2 | N31: 40 | O31: "
C32: " | G32: 1.856
B33: 17H-0016Z | C33: " | D33: 29.5 | E33: 0.7 | F33: 545 | G33: 1.861 | H33: 3.728 | I33: 3.704 | J33: =H33-I33 -> 0.024 | K33: =(F33*(273.15+D33)/273.15)/(M33*N33) -> 7.548245 | L33: MU2 | M33: =VLOOKUP(L33,allgemein!$B$3:$C$11,2,FALSE) -> 2 | N33: 40 | O33: "
C34: " | G34: 1.867
B35: 17H-0017Z | C35: " | D35: 29.5 | E35: 0.8 | F35: 275 | H35: 1.867 | I35: 1.858 | J35: =H35-I35 -> 0.009 | K35: =(F35*(273.15+D35)/273.15)/(M35*N35) -> 7.617495 | L35: MU1 | M35: =VLOOKUP(L35,allgemein!$B$3:$C$11,2,FALSE) -> 1 | N35: 40 | O35: FA702335
B36: 17H-0018Z | C36: " | D36: 29.3 | E36: 0.6 | F36: 274 | H36: 1.867 | I36: 1.854 | J36: =H36-I36 -> 0.013 | K36: =(F36*(273.15+D36)/273.15)/(M36*N36) -> 7.5847794 | L36: MU1 | M36: =VLOOKUP(L36,allgemein!$B$3:$C$11,2,FALSE) -> 1 | N36: 40 | O36: "
B37: 17H-0019Z | C37: " | D37: 29.6 | E37: 0.4 | F37: 275 | H37: 1.867 | I37: 1.855 | J37: =H37-I37 -> 0.012 | K37: =(F37*(273.15+D37)/273.15)/(M37*N37) -> 7.6200119 | L37: MU1 | M37: =VLOOKUP(L37,allgemein!$B$3:$C$11,2,FALSE) -> 1 | N37: 40 | O37: "
B38: 17H-0020Z | C38: FA702176 | D38: 29.3 | E38: 0.8 | F38: 275 | H38: 1.872 | I38: 1.86 | J38: =H38-I38 -> 0.012 | K38: =(F38*(273.15+D38)/273.15)/(M38*N38) -> 7.6124611 | L38: MU1 | M38: =VLOOKUP(L38,allgemein!$B$3:$C$11,2,FALSE) -> 1 | N38: 40 | O38: "
B39: 17H-0021Z | C39: " | D39: 27.3 | E39: 0.4 | F39: 276 | H39: 1.864 | I39: 1.85 | J39: =H39-I39 -> 0.014 | K39: =(F39*(273.15+D39)/273.15)/(M39*N39) -> 7.5896211 | L39: MU1 | M39: =VLOOKUP(L39,allgemein!$B$3:$C$11,2,FALSE) -> 1 | N39: 40 | O39: "
B40: 17H-0022Z | C40: " | D40: 27.2 | E40: 0.9 | F40: 274 | H40: 1.875 | I40: 1.867 | J40: =H40-I40 -> 0.008 | K40: =(F40*(273.15+D40)/273.15)/(M40*N40) -> 7.5321161 | L40: MU1 | M40: =VLOOKUP(L40,allgemein!$B$3:$C$11,2,FALSE) -> 1 | N40: 40 | O40: "
B41: 17H-0023Z | C41: " | D41: 27.2 | E41: 0.6 | F41: 276 | H41: 1.871 | I41: 1.858 | J41: =H41-I41 -> 0.013 | K41: =(F41*(273.15+D41)/273.15)/(M41*N41) -> 7.587095 | L41: MU1 | M41: =VLOOKUP(L41,allgemein!$B$3:$C$11,2,FALSE) -> 1 | N41: 40 | O41: "
...

Sheet Sep
B2: Cell # | C2: Membran # ¦ Batch # | D2: Temp Gas / [°C] | E2: Temp Kat T1-T2 / [°C] | F2: Gasfluss / [sccm / min] | G2: Membrane V @ 13 bar/[V] | H2: Cell V @ 13 bar/[V] | I2: Cell V @ 0 bar [V] | J2: Voltage Diff. / [V] | K2: H2 Prod / [nmL/A] | L2: Typ | M2: Anzahl Layer | N2: Strom / [A] | O2: FA # | P2: Bemerkungen | R2: Visum | S2: Jahr: | T2: 2017
B3: 17I-0001Z | C3: FA702229 | D3: 25.3 | E3: 0.3 | F3: 179 | H3: 1.892 | I3: 1.882 | J3: =H3-I3 -> 0.01 | K3: =(F3*(273.15+D3)/273.15)/(M3*N3) -> 7.8231814 | L3: MI_V3 | M3: =VLOOKUP(L3,allgemein!$B$3:$C$11,2,FALSE) -> 1 | N3: 25 | O3: FA702428
B4: 17I-0002Z | C4: " | D4: 25.4 | E4: 0.3 | F4: 179 | H4: 1.9 | I4: 1.887 | J4: =H4-I4 -> 0.013 | K4: =(F4*(273.15+D4)/273.15)/(M4*N4) -> 7.8258027 | L4: MI_V3 | M4: =VLOOKUP(L4,allgemein!$B$3:$C$11,2,FALSE) -> 1 | N4: 25 | O4: "
B5: 17I-0003Z | C5: " | D5: 25.8 | E5: 0.3 | F5: 179 | H5: 1.879 | I5: 1.868 | J5: =H5-I5 -> 0.011 | K5: =(F8*(273.15+D8)/273.15)/(M5*N5) -> 7.7977229 | L5: MI_V3 | M5: =VLOOKUP(L5,allgemein!$B$3:$C$11,2,FALSE) -> 1 | N5: 25 | O5: "
B6: 17I-0004Z | C6: FA702230 | D6: 26.2 | E6: 0.7 | F6: 179 | H6: 1.868 | I6: 1.855 | J6: =H6-I6 -> 0.013 | K6: =(F6*(273.15+D6)/273.15)/(M6*N6) -> 7.8467728 | L6: MI_V3 | M6: =VLOOKUP(L6,allgemein!$B$3:$C$11,2,FALSE) -> 1 | N6: 25 | O6: "
B7: 17I-0005Z | C7: " | D7: 26.5 | E7: 0.3 | F7: 178 | H7: 1.875 | I7: 1.865 | J7: =H7-I7 -> 0.01 | K7: =(F7*(273.15+D7)/273.15)/(M7*N7) -> 7.810756 | L7: MI_V3 | M7: =VLOOKUP(L7,allgemein!$B$3:$C$11,2,FALSE) -> 1 | N7: 25 | O7: "
B8: 17I-0006Z | C8: " | D8: 26 | E8: 0.8 | F8: 178 | H8: 1.888 | I8: 1.881 | J8: =H8-I8 -> 0.007 | K8: =(F8*(273.15+D8)/273.15)/(M8*N8) -> 7.7977229 | L8: MI_V3 | M8: =VLOOKUP(L8,allgemein!$B$3:$C$11,2,FALSE) -> 1 | N8: 25 | O8: "
B9: 17I-0007Z | C9: " | D9: 25.5 | E9: 0.3 | F9: 179 | H9: 1.884 | I9: 1.872 | J9: =H9-I9 -> 0.012 | K9: =(F9*(273.15+D9)/273.15)/(M9*N9) -> 7.8284239 | L9: MI_V3 | M9: =VLOOKUP(L9,allgemein!$B$3:$C$11,2,FALSE) -> 1 | N9: 25 | O9: "
B10: 17I-0008Z | C10: " | D10: 25.3 | E10: 0.2 | F10: 179 | H10: 1.883 | I10: 1.868 | J10: =H10-I10 -> 0.015 | K10: =(F10*(273.15+D10)/273.15)/(M10*N10) -> 7.8231814 | L10: MI_V3 | M10: =VLOOKUP(L10,allgemein!$B$3:$C$11,2,FALSE) -> 1 | N10: 25 | O10: "
B11: 17I-0009Z | C11: " | D11: 25.3 | E11: 0 | F11: 180 | H11: 1.896 | I11: 1.884 | J11: =H11-I11 -> 0.012 | K11: =(F11*(273.15+D11)/273.15)/(M11*N11) -> 7.8668863 | L11: MI_V3 | M11: =VLOOKUP(L11,allgemein!$B$3:$C$11,2,FALSE) -> 1 | N11: 25 | O11: "
B12: 17I-0010Z | C12: " | D12: 24.9 | E12: 0.1 | F12: 179 | H12: 1.888 | I12: 1.876 | J12: =H12-I12 -> 0.012 | K12: =(F12*(273.15+D12)/273.15)/(M12*N12) -> 7.8126963 | L12: MI_V3 | M12: =VLOOKUP(L12,allgemein!$B$3:$C$11,2,FALSE) -> 1 | N12: 25 | O12: "
B13: 17I-0011Z | C13: " | D13: 24.6 | E13: 0.2 | F13: 181 | H13: 1.892 | I13: 1.876 | J13: =H13-I13 -> 0.016 | K13: =(F13*(273.15+D13)/273.15)/(M13*N13) -> 7.8920373 | L13: MI_V3 | M13: =VLOOKUP(L13,allgemein!$B$3:$C$11,2,FALSE) -> 1 | N13: 25 | O13: "
B14: 17I-0012Z | C14: " | D14: 24.3 | E14: 0.3 | F14: 180 | H14: 1.914 | I14: 1.899 | J14: =H14-I14 -> 0.015 | K14: =(F14*(273.15+D14)/273.15)/(M14*N14) -> 7.8405272 | L14: MI_V3 | M14: =VLOOKUP(L14,allgemein!$B$3:$C$11,2,FALSE) -> 1 | N14: 25 | O14: "
B15: 17I-0013Z | C15: " | D15: 24 | E15: 0.1 | F15: 180 | H15: 1.918 | I15: 1.905 | J15: =H15-I15 -> 0.013 | K15: =(F15*(273.15+D15)/273.15)/(M15*N15) -> 7.8326194 | L15: MI_V3 | M15: =VLOOKUP(L15,allgemein!$B$3:$C$11,2,FALSE) -> 1 | N15: 25 | O15: "
B16: 17I-0014Z | C16: " | D16: 24 | E16: 0.2 | F16: 179 | H16: 1.901 | I16: 1.89 | J16: =H16-I16 -> 0.011 | K16: =(F16*(273.15+D16)/273.15)/(M16*N16) -> 7.7891049 | L16: MI_V3 | M16: =VLOOKUP(L16,allgemein!$B$3:$C$11,2,FALSE) -> 1 | N16: 25 | O16: "
B17: 17I-0015Z | C17: " | D17: 24 | E17: 0.1 | F17: 179 | H17: 1.918 | I17: 1.902 | J17: =H17-I17 -> 0.016 | K17: =(F17*(273.15+D17)/273.15)/(M17*N17) -> 7.7891049 | L17: MI_V3 | M17: =VLOOKUP(L17,allgemein!$B$3:$C$11,2,FALSE) -> 1 | N17: 25 | O17: "
B18: 17I-0016Z | C18: " | D18: 24 | E18: 0.2 | F18: 180 | H18: 1.899 | I18: 1.887 | J18: =H18-I18 -> 0.012 | K18: =(F18*(273.15+D18)/273.15)/(M18*N18) -> 7.8326194 | L18: MI_V3 | M18: =VLOOKUP(L18,allgemein!$B$3:$C$11,2,FALSE) -> 1 | N18: 25 | O18: " | P18: (179) ROTA: 180; -Druck nur 9bar-
B19: 17B-0070Z | C19: 16K-0086M | D19: 24.1 | E19: 0.2 | F19: 850 | G19: 1.829 | H19: 5.528 | I19: 5.504 | J19: =H19-I19 -> 0.024 | K19: =(F19*(273.15+D19)/273.15)/(M19*N19) -> 7.7082952 | L19: MU3 | M19: =VLOOKUP(L19,allgemein!$B$3:$C$11,2,FALSE) -> 3 | N19: 40 | O19: FA702435 | P19: Revidiert; neuwertig
C20: 16K-0087M | G20: 1.821
C21: FA702176 | G21: 1.878
B22: 17I-0017Z | C22: " | D22: 28.7 | E22: 0 | F22: 570 | G22: 1.829 | H22: 3.657 | I22: 3.634 | J22: =H22-I22 -> 0.023 | K22: =(F22*(273.15+D22)/273.15)/(M22*N22) -> 7.8736271 | L22: MU2 | M22: =VLOOKUP(L22,allgemein!$B$3:$C$11,2,FALSE) -> 2 | N22: 40 | O22: FA702334
C23: " | G23: 1.828
B24: 17I-0018Z | C24: " | D24: 28.6 | E24: 0.4 | F24: 571 | G24: 1.845 | H24: 3.684 | I24: 3.665 | J24: =H24-I24 -> 0.019 | K24: =(F24*(273.15+D24)/273.15)/(M24*N24) -> 7.8848275 | L24: MU2 | M24: =VLOOKUP(L24,allgemein!$B$3:$C$11,2,FALSE) -> 2 | N24: 40 | O24: "
C25: " | G25: 1.838
B26: 17I-0019Z | C26: FA702177 | D26: 28.5 | E26: 0 | F26: 571 | G26: 1.851 | H26: 3.702 | I26: 3.679 | J26: =H26-I26 -> 0.023 | K26: =(F26*(273.15+D26)/273.15)/(M26*N26) -> 7.8822144 | L26: MU2 | M26: =VLOOKUP(L26,allgemein!$B$3:$C$11,2,FALSE) -> 2 | N26: 40 | O26: "
C27: " | G27: 1.85
B28: 17I-0020Z | C28: " | D28: 28.4 | E28: 0 | F28: 572 | G28: 1.853 | H28: 3.703 | I28: 3.678 | J28: =H28-I28 -> 0.025 | K28: =(F28*(273.15+D28)/273.15)/(M28*N28) -> 7.8934011 | L28: MU2 | M28: =VLOOKUP(L28,allgemein!$B$3:$C$11,2,FALSE) -> 2 | N28: 40 | O28: " | Q28: §
C29: " | G29: 1.849
J30: =H30-I30 -> 0 | K30: =(F30*(273.15+D30)/273.15)/(M30*N30) -> #DIV/0!
J31: =H31-I31 -> 0 | K31: =(F31*(273.15+D31)/273.15)/(M31*N31) -> #DIV/0!
J32: =H32-I32 -> 0 | K32: =(F32*(273.15+D32)/273.15)/(M32*N32) -> #DIV/0!
J33: =H33-I33 -> 0 | K33: =(F33*(273.15+D33)/273.15)/(M33*N33) -> #DIV/0!
J34: =H34-I34 -> 0 | K34: =(F34*(273.15+D34)/273.15)/(M34*N34) -> #DIV/0!
B35: 17I-0004Z | D35: 29.7 | E35: 0.2 | F35: 180 | H35: 1.849 | I35: 1.834 | J35: =H35-I35 -> 0.015 | K35: =(F35*(273.15+D35)/273.15)/(M35*N35) -> 7.9828666 | L35: MI_V1 | M35: =VLOOKUP(L35,allgemein!$B$3:$C$11,2,FALSE) -> 1 | N35: 25
D36: 27.2 | F36: 180 | J36: =H36-I36 -> 0 | K36: =(F36*(273.15+D36)/273.15)/(M36*N36) -> 7.9169687 | L36: MI_V1 | M36: =VLOOKUP(L36,allgemein!$B$3:$C$11,2,FALSE) -> 1 | N36: 25
J37: =H37-I37 -> 0 | K37: =(F37*(273.15+D37)/273.15)/(M37*N37) -> #DIV/0!
B38: 17C0010Z-R | D38: 25.5 | F38: 180 | J38: =H38-I38 -> 0 | K38: =(F38*(273.15+D38)/273.15)/(M38*N38) -> 7.8721582 | L38: MU1 | M38: 1 | N38: 25 | P38: Test 25A
B39: " | D39: 25.4 | F39: 285 | J39: =H39-I39 -> 0 | K39: =(F39*(273.15+D39)/273.15)/(M39*N39) -> 7.7875481 | L39: MU1 | M39: 1 | N39: 40
J40: =H40-I40 -> 0 | K40: =(F40*(273.15+D40)/273.15)/(M40*N40) -> #DIV/0!
J41: =H41-I41 -> 0 | K41: =(F41*(273.15+D41)/273.15)/(M41*N41) -> #DIV/0!
...

Sheet Oct
B2: Cell # | C2: Membran # ¦ Batch # | D2: Temp Gas / [°C] | E2: Temp Kat T1-T2 / [°C] | F2: Gasfluss / [sccm / min] | G2: Membrane V @ 13 bar/[V] | H2: Cell V @ 13 bar/[V] | I2: Cell V @ 0 bar [V] | J2: Voltage Diff. / [V] | K2: H2 Prod / [nmL/A] | L2: Typ | M2: Anzahl Layer | N2: Strom / [A] | O2: FA # | P2: Bemerkungen | R2: Visum | S2: Jahr: | T2: 2017
B3: 17J-0001Z | C3: FA702177 | D3: 25.1 | E3: 0 | F3: 284 | H3: 1.863 | I3: 1.853 | J3: =H3-I3 -> 0.01 | K3: =(F3*(273.15+D3)/273.15)/(M3*N3) -> 7.7524254 | L3: MU1 | M3: =VLOOKUP(L3,allgemein!$B$3:$C$11,2,FALSE) -> 1 | N3: 40 | O3: FA702394 | P3: neues Edelstahlflies
B4: 17J-0002Z | C4: " | D4: 25.3 | E4: 0 | F4: 286 | H4: 1.869 | I4: 1.853 | J4: =H4-I4 -> 0.016 | K4: =(F4*(273.15+D4)/273.15)/(M4*N4) -> 7.8122552 | L4: MU1 | M4: =VLOOKUP(L4,allgemein!$B$3:$C$11,2,FALSE) -> 1 | N4: 40 | O4: "
B5: 17J-0003Z | C5: " | D5: 25.3 | E5: 0 | F5: 285 | H5: 1.856 | I5: 1.842 | J5: =H5-I5 -> 0.014 | K5: =(F5*(273.15+D5)/273.15)/(M5*N5) -> 7.7849396 | L5: MU1 | M5: =VLOOKUP(L5,allgemein!$B$3:$C$11,2,FALSE) -> 1 | N5: 40 | O5: " | P5: Mem. kleines Punktloch
B6: 17J-0004Z | C6: " | D6: 25.5 | E6: 0.1 | F6: 285 | H6: 1.867 | I6: 1.856 | J6: =H6-I6 -> 0.011 | K6: =(F6*(273.15+D6)/273.15)/(M6*N6) -> 7.7901565 | L6: MU1 | M6: =VLOOKUP(L6,allgemein!$B$3:$C$11,2,FALSE) -> 1 | N6: 40 | O6: "
B7: 17J-0005Z | C7: " | D7: 25.6 | E7: 0 | F7: 285 | H7: 1.859 | I7: 1.845 | J7: =H7-I7 -> 0.014 | K7: =(F7*(273.15+D7)/273.15)/(M7*N7) -> 7.792765 | L7: MU1 | M7: =VLOOKUP(L7,allgemein!$B$3:$C$11,2,FALSE) -> 1 | N7: 40 | O7: "
B8: 17J-0006Z | C8: " | D8: 25.6 | E8: 0 | F8: 285 | H8: 1.876 | I8: 1.864 | J8: =H8-I8 -> 0.012 | K8: =(F8*(273.15+D8)/273.15)/(M8*N8) -> 7.792765 | L8: MU1 | M8: =VLOOKUP(L8,allgemein!$B$3:$C$11,2,FALSE) -> 1 | N8: 40 | O8: "
B9: 17J-0007Z | C9: " | D9: 25.6 | E9: 0 | F9: 284 | H9: 1.862 | I9: 1.849 | J9: =H9-I9 -> 0.013 | K9: =(F9*(273.15+D9)/273.15)/(M9*N9) -> 7.7654219 | L9: MU1 | M9: =VLOOKUP(L9,allgemein!$B$3:$C$11,2,FALSE) -> 1 | N9: 40 | O9: "
B10: 17J-0008Z | C10: " | D10: 25.6 | E10: 0.1 | F10: 285 | H10: 1.868 | I10: 1.855 | J10: =H10-I10 -> 0.013 | K10: =(F10*(273.15+D10)/273.15)/(M10*N10) -> 7.792765 | L10: MU1 | M10: =VLOOKUP(L10,allgemein!$B$3:$C$11,2,FALSE) -> 1 | N10: 40 | O10: "
B11: 17J-0009Z | C11: " | D11: 25.7 | E11: 0.3 | F11: 283 | H11: 1.868 | I11: 1.859 | J11: =H11-I11 -> 0.009 | K11: =(F11*(273.15+D11)/273.15)/(M11*N11) -> 7.740669 | L11: MU1 | M11: =VLOOKUP(L11,allgemein!$B$3:$C$11,2,FALSE) -> 1 | N11: 40 | O11: "
B12: 17J-0010Z | C12: " | D12: 25.7 | E12: 0.1 | F12: 285 | H12: 1.863 | I12: 1.849 | J12: =H12-I12 -> 0.014 | K12: =(F12*(273.15+D12)/273.15)/(M12*N12) -> 7.7953734 | L12: MU1 | M12: =VLOOKUP(L12,allgemein!$B$3:$C$11,2,FALSE) -> 1 | N12: 40 | O12: "
B13: 17J-0010Z | C13: " | D13: 25.6 | E13: 0.2 | F13: 286 | H13: 1.88 | I13: 1.866 | J13: =H13-I13 -> 0.014 | K13: =(F13*(273.15+D13)/273.15)/(M13*N13) -> 7.820108 | L13: MU1 | M13: =VLOOKUP(L13,allgemein!$B$3:$C$11,2,FALSE) -> 1 | N13: 40 | O13: "
B14: 17J-0012Z | C14: " | D14: 25.8 | E14: 0 | F14: 287 | H14: 1.881 | I14: 1.866 | J14: =H14-I14 -> 0.015 | K14: =(F14*(273.15+D14)/273.15)/(M14*N14) -> 7.8527046 | L14: MU1 | M14: =VLOOKUP(L14,allgemein!$B$3:$C$11,2,FALSE) -> 1 | N14: 40 | O14: "
B15: 17J-0013Z | C15: " | D15: 26.1 | E15: 0.1 | F15: 287 | H15: 1.883 | I15: 1.867 | J15: =H15-I15 -> 0.016 | K15: =(F15*(273.15+D15)/273.15)/(M15*N15) -> 7.8605848 | L15: MU1 | M15: =VLOOKUP(L15,allgemein!$B$3:$C$11,2,FALSE) -> 1 | N15: 40 | O15: "
B16: 17J-0014Z | C16: " | D16: 26.4 | E16: 0 | F16: 287 | H16: 1.885 | I16: 1.872 | J16: =H16-I16 -> 0.013 | K16: =(F16*(273.15+D16)/273.15)/(M16*N16) -> 7.8684651 | L16: MU1 | M16: =VLOOKUP(L16,allgemein!$B$3:$C$11,2,FALSE) -> 1 | N16: 40 | O16: "
B17: 17J-0015Z | C17: " | D17: 26.7 | E17: 0 | F17: 287 | H17: 1.88 | I17: 1.866 | J17: =H17-I17 -> 0.014 | K17: =(F17*(273.15+D17)/273.15)/(M17*N17) -> 7.8763454 | L17: MU1 | M17: =VLOOKUP(L17,allgemein!$B$3:$C$11,2,FALSE) -> 1 | N17: 40 | O17: "
B18: 17J-0016Z | C18: " | D18: 27.2 | E18: 0 | F18: 288 | H18: 1.876 | I18: 1.861 | J18: =H18-I18 -> 0.015 | K18: =(F18*(273.15+D18)/273.15)/(M18*N18) -> 7.9169687 | L18: MU1 | M18: =VLOOKUP(L18,allgemein!$B$3:$C$11,2,FALSE) -> 1 | N18: 40 | O18: "
B19: 17J-0017Z | C19: FA702178 | D19: 27.9 | E19: 0 | F19: 287 | H19: 1.84 | I19: 1.826 | J19: =H19-I19 -> 0.014 | K19: =(F19*(273.15+D19)/273.15)/(M19*N19) -> 7.9078666 | L19: MU1 | M19: =VLOOKUP(L19,allgemein!$B$3:$C$11,2,FALSE) -> 1 | N19: 40 | O19: " | P19: Mem. kleines Punktloch
B20: 17J-0018Z | C20: " | D20: 28.7 | E20: 0 | F20: 287 | H20: 1.839 | I20: 1.826 | J20: =H20-I20 -> 0.013 | K20: =(F20*(273.15+D20)/273.15)/(M20*N20) -> 7.9288807 | L20: MU1 | M20: =VLOOKUP(L20,allgemein!$B$3:$C$11,2,FALSE) -> 1 | N20: 40 | O20: " | P20: neuer Ultraschall- Konverter
B21: 17J-0019Z | C21: " | D21: 27 | E21: 0.1 | F21: 568 | G21: 1.834 | H21: 3.671 | I21: 3.646 | J21: =H21-I21 -> 0.025 | K21: =(F21*(273.15+D21)/273.15)/(M21*N21) -> 7.8018122 | L21: MU2 | M21: =VLOOKUP(L21,allgemein!$B$3:$C$11,2,FALSE) -> 2 | N21: 40 | O21: FA702334 | P21: "
C22: " | G22: 1.836
B23: 17J-0020Z | C23: " | D23: 27.6 | E23: 0 | F23: 568 | G23: 1.841 | H23: 3.683 | I23: 3.659 | J23: =H23-I23 -> 0.024 | K23: =(F23*(273.15+D23)/273.15)/(M23*N23) -> 7.817408 | L23: MU2 | M23: =VLOOKUP(L23,allgemein!$B$3:$C$11,2,FALSE) -> 2 | N23: 40 | O23: "
C24: " | G24: 1.842 | P24: "
B25: 17J-0021Z | C25: " | D25: 27.7 | E25: 0 | F25: 568 | G25: 1.842 | H25: 3.682 | I25: 3.654 | J25: =H25-I25 -> 0.028 | K25: =(F25*(273.15+D25)/273.15)/(M25*N25) -> 7.8200073 | L25: MU2 | M25: =VLOOKUP(L25,allgemein!$B$3:$C$11,2,FALSE) -> 2 | N25: 40 | O25: " | P25: "
C26: " | G26: 1.84 | P26: "
B27: 17J-0022Z | C27: " | D27: 27.7 | E27: 0 | F27: 569 | G27: 1.838 | H27: 3.674 | I27: 3.647 | J27: =H27-I27 -> 0.027 | K27: =(F27*(273.15+D27)/273.15)/(M27*N27) -> 7.8337749 | L27: MU2 | M27: =VLOOKUP(L27,allgemein!$B$3:$C$11,2,FALSE) -> 2 | N27: 40 | O27: " | P27: "
C28: " | G28: 1.836
B29: 17J-0023Z | C29: " | D29: 27.7 | E29: 0 | F29: 566 | G29: 1.872 | H29: 3.721 | I29: 3.702 | J29: =H29-I29 -> 0.019 | K29: =(F29*(273.15+D29)/273.15)/(M29*N29) -> 7.7924721 | L29: MU2 | M29: =VLOOKUP(L29,allgemein!$B$3:$C$11,2,FALSE) -> 2 | N29: 40 | O29: "
C30: " | G30: 1.849
B31: 17J-0024Z | C31: " | D31: 27 | E31: 0.2 | F31: 569 | G31: 1.857 | H31: 3.715 | I31: 3.689 | J31: =H31-I31 -> 0.026 | K31: =(F31*(273.15+D31)/273.15)/(M31*N31) -> 7.8155478 | L31: MU2 | M31: =VLOOKUP(L31,allgemein!$B$3:$C$11,2,FALSE) -> 2 | N31: 40 | O31: "
C32: " | G32: 1.858
B33: 17J-0025Z | C33: " | D33: 26.9 | E33: 0.3 | F33: 569 | G33: 1.857 | H33: 3.712 | I33: 3.685 | J33: =H33-I33 -> 0.027 | K33: =(F33*(273.15+D33)/273.15)/(M33*N33) -> 7.8129439 | L33: MU2 | M33: =VLOOKUP(L33,allgemein!$B$3:$C$11,2,FALSE) -> 2 | N33: 40 | O33: "
C34: " | G34: 1.855
B35: 17J-0026Z | C35: " | D35: 26.7 | E35: 0.5 | F35: 569 | G35: 1.847 | H35: 3.698 | I35: 3.675 | J35: =H35-I35 -> 0.023 | K35: =(F35*(273.15+D35)/273.15)/(M35*N35) -> 7.8077361 | L35: MU2 | M35: =VLOOKUP(L35,allgemein!$B$3:$C$11,2,FALSE) -> 2 | N35: 40 | O35: "
C36: " | G36: 1.851
B37: 17C-0080Z | C37: FA701100 | D37: 25.3 | E37: 0.3 | F37: 282 | H37: 1.99 | I37: 1.937 | J37: =H37-I37 -> 0.053 | K37: =(F37*(273.15+D37)/273.15)/(M37*N37) -> 7.7029929 | L37: MU1 | M37: 1 | N37: 40 | O37: i.O.; C.S. | P37: angeliefert
C38: " | D38: 25.6 | E38: 0.2 | F38: 281 | H38: 1.988 | I38: 1.924 | J38: =H38-I38 -> 0.064 | K38: =(F38*(273.15+D38)/273.15)/(M38*N38) -> 7.6833928 | L38: MU1 | M38: 1 | N38: 40 | O38: i.O.; C.S. | P38: " ca 90 Min Betrieb
D39: 23.6 | E39: 0.2 | F39: 284 | H39: 1.86 | I39: 1.847 | J39: =H39-I39 -> 0.013 | K39: =(F39*(273.15+D39)/273.15)/(M39*N39) -> 7.7134358 | L39: MU1 | M39: 1 | N39: 40 | O39: FA701694 | P39: nach Revision; Auslief Nov
B40: 17J-0027Z | C40: FA702178 | G40: 1.811 | L40: MU12 | M40: 12 | O40: FA702533
C41: FA702179 | G41: 1.788
...

Sheet Nov
B2: Cell # | C2: Membran # ¦ Batch # | D2: Temp Gas / [°C] | E2: Temp Kat T1-T2 / [°C] | F2: Gasfluss / [sccm / min] | G2: Membrane V @ 13 bar/[V] | H2: Cell V @ 13 bar/[V] | I2: Cell V @ 0 bar [V] | J2: Voltage Diff. / [V] | K2: H2 Prod / [nmL/A] | L2: Typ | M2: Anzahl Layer | N2: Strom / [A] | O2: FA # | P2: Bemerkungen | R2: Visum | S2: Jahr: | T2: 2017
B3: 17K-0001Z | C3: FA702429 | D3: 23.2 | E3: 1 | F3: 177 | H3: 1.913 | I3: 1.9 | J3: =H3-I3 -> 0.013 | K3: =(F3*(273.15+D3)/273.15)/(M3*N3) -> 7.6813399 | L3: MI_V3 | M3: =VLOOKUP(L3,allgemein!$B$3:$C$11,2,FALSE) -> 1 | N3: 25 | O3: FA702625
B4: 17K-0002Z | C4: " | D4: 23.2 | E4: 1.7 | F4: 177 | H4: 1.92 | I4: 1.909 | J4: =H4-I4 -> 0.011 | K4: =(F4*(273.15+D4)/273.15)/(M4*N4) -> 7.6813399 | L4: MI_V3 | M4: =VLOOKUP(L4,allgemein!$B$3:$C$11,2,FALSE) -> 1 | N4: 25 | O4: "
B5: 17K-0003Z | C5: " | D5: 23.2 | E5: 1 | F5: 177 | H5: 1.901 | I5: 1.887 | J5: =H5-I5 -> 0.014 | K5: =(F8*(273.15+D8)/273.15)/(M5*N5) -> 7.6813399 | L5: MI_V3 | M5: =VLOOKUP(L5,allgemein!$B$3:$C$11,2,FALSE) -> 1 | N5: 25 | O5: "
