Workbook

Sheet Jan
B2: Cell # | C2: Membran # ¦ Batch # | D2: Temp Gas / [°C] | E2: Temp Kat T1-T2 / [°C] | F2: Gasfluss / [sccm / min] | G2: Membrane V @ 13 bar/[V] | H2: Cell V @ 13 bar/[V] | I2: Cell V @ 0 bar [V] | J2: Voltage Diff. / [V] | K2: H2 Prod / [nmL/A] | L2: Typ | M2: Anzahl Layer | N2: Strom / [A] | O2: FA # | P2: Bemerkungen | R2: Visum | S2: Jahr: | T2: 2018
B3: 18A-0001Z | C3: FA702717 | D3: 25.5 | E3: 0.3 | F3: 570 | G3: 1.831 | H3: 3.676 | I3: 3.652 | J3: =H3-I3 -> 0.024 | K3: =(F3*(273.15+D3)/273.15)/(M3*N3) -> 7.7901565 | L3: MU2 | M3: =VLOOKUP(L3,allgemein!$B$3:$C$13,2,FALSE) -> 2 | N3: 40 | O3: FA703190
C4: " | G4: 1.844 | P4: Kratzer und am Rand! Grenzfall
B5: 18A-0002Z | C5: " | D5: 25.6 | E5: 0.7 | F5: 569 | G5: 1.827 | H5: 3.664 | I5: 3.643 | J5: =H5-I5 -> 0.021 | K5: =(F5*(273.15+D5)/273.15)/(M5*N5) -> 7.7790934 | L5: MU2 | M5: =VLOOKUP(L5,allgemein!$B$3:$C$13,2,FALSE) -> 2 | N5: 40 | O5: " | P5: kleines Punktloch
C6: FA702783 | G6: 1.837
B7: 18A-0003Z | C7: " | D7: 25.8 | E7: 0.6 | F7: 569 | G7: 1.84 | H7: 3.669 | I7: 3.649 | J7: =H7-I7 -> 0.02 | K7: =(F7*(273.15+D7)/273.15)/(M7*N7) -> 7.7843012 | L7: MU2 | M7: =VLOOKUP(L7,allgemein!$B$3:$C$13,2,FALSE) -> 2 | N7: 40 | O7: " | P7: Faden
C8: " | G8: 1.829
B9: 18A-0004Z | C9: " | D9: 26.1 | E9: 0.5 | F9: 570 | G9: 1.825 | H9: 3.657 | I9: 3.633 | J9: =H9-I9 -> 0.024 | K9: =(F9*(273.15+D9)/273.15)/(M9*N9) -> 7.8058072 | L9: MU2 | M9: =VLOOKUP(L9,allgemein!$B$3:$C$13,2,FALSE) -> 2 | N9: 40 | O9: "
C10: " | G10: 1.831
B11: 18A-0005Z | C11: " | D11: 26.3 | E11: 0.3 | F11: 571 | G11: 1.832 | H11: 3.653 | I11: 3.63 | J11: =H11-I11 -> 0.023 | K11: =(F11*(273.15+D11)/273.15)/(M11*N11) -> 7.8247277 | L11: MU2 | M11: =VLOOKUP(L11,allgemein!$B$3:$C$13,2,FALSE) -> 2 | N11: 40 | O11: "
C12: " | G12: 1.82
B13: 18A-0006Z | C13: " | D13: 25.2 | E13: 0.5 | F13: 571 | G13: 1.86 | H13: 3.721 | I13: 3.691 | J13: =H13-I13 -> 0.03 | K13: =(F13*(273.15+D13)/273.15)/(M13*N13) -> 7.7959843 | L13: MU2 | M13: =VLOOKUP(L13,allgemein!$B$3:$C$13,2,FALSE) -> 2 | N13: 40 | O13: "
C14: " | G14: 1.861
B15: 18A-0007Z | C15: " | D15: 25.3 | E15: 0.8 | F15: 570 | G15: 1.857 | H15: 3.713 | I15: 3.687 | J15: =H15-I15 -> 0.026 | K15: =(F15*(273.15+D15)/273.15)/(M15*N15) -> 7.7849396 | L15: MU2 | M15: =VLOOKUP(L15,allgemein!$B$3:$C$13,2,FALSE) -> 2 | N15: 40 | O15: "
C16: " | G16: 1.856
B17: 18A-0008Z | C17: " | D17: 25.3 | E17: 0.5 | F17: 571 | G17: 1.849 | H17: 3.712 | I17: 3.682 | J17: =H17-I17 -> 0.03 | K17: =(F17*(273.15+D17)/273.15)/(M17*N17) -> 7.7985974 | L17: MU2 | M17: =VLOOKUP(L17,allgemein!$B$3:$C$13,2,FALSE) -> 2 | N17: 40 | O17: "
C18: " | G18: 1.863
B19: 18A-0009Z | C19: " | D19: 25.3 | E19: 0.6 | F19: 569 | G19: 1.836 | H19: 3.67 | I19: 3.645 | J19: =H19-I19 -> 0.025 | K19: =(F19*(273.15+D19)/273.15)/(M19*N19) -> 7.7712818 | L19: MU2 | M19: =VLOOKUP(L19,allgemein!$B$3:$C$13,2,FALSE) -> 2 | N19: 40 | O19: "
C20: " | G20: 1.834
B21: 18A-0010Z | C21: " | D21: 25.4 | E21: 0.5 | F21: 569 | G21: 1.836 | H21: 3.678 | I21: 3.65 | J21: =H21-I21 -> 0.028 | K21: =(F21*(273.15+D21)/273.15)/(M21*N21) -> 7.7738857 | L21: MU2 | M21: =VLOOKUP(L21,allgemein!$B$3:$C$13,2,FALSE) -> 2 | N21: 40 | O21: "
C22: " | G22: 1.842
B23: 18A-0011Z | C23: " | D23: 25.3 | E23: 0.4 | F23: 570 | G23: 1.831 | H23: 3.675 | I23: 3.647 | J23: =H23-I23 -> 0.028 | K23: =(F23*(273.15+D23)/273.15)/(M23*N23) -> 7.7849396 | L23: MU2 | M23: =VLOOKUP(L23,allgemein!$B$3:$C$13,2,FALSE) -> 2 | N23: 40 | O23: "
C24: " | G24: 1.844
B25: 18A-0012Z | C25: FA702430 | D25: 23.4 | E25: 0.3 | F25: 177 | H25: 1.903 | I25: 1.88 | J25: =H25-I25 -> 0.023 | K25: =(F25*(273.15+D25)/273.15)/(M25*N25) -> 7.6865239 | L25: MI_V3 | M25: =VLOOKUP(L25,allgemein!$B$3:$C$13,2,FALSE) -> 1 | N25: 25 | O25: FA703552
B26: " | C26: " | D26: 23.4 | E26: 0.3 | F26: 177 | H26: 1.896 | I26: 1.872 | J26: =H26-I26 -> 0.024 | K26: =(F26*(273.15+D26)/273.15)/(M26*N26) -> 7.6865239 | L26: MI_V3 | M26: =VLOOKUP(L26,allgemein!$B$3:$C$13,2,FALSE) -> 1 | N26: 25
B27: " | C27: " | D27: 23.8 | E27: 0.2 | F27: 177 | H27: 1.893 | I27: 1.879 | J27: =H27-I27 -> 0.014 | K27: =(F27*(273.15+D27)/273.15)/(M27*N27) -> 7.6968918 | L27: MI_V3 | M27: =VLOOKUP(L27,allgemein!$B$3:$C$13,2,FALSE) -> 1 | N27: 25 | P27: nach Mem. in Säure
B28: 18A-0013Z | C28: " | D28: 23.5 | E28: 0.3 | F28: 177 | H28: 1.907 | I28: 1.891 | J28: =H28-I28 -> 0.016 | K28: =(F28*(273.15+D28)/273.15)/(M28*N28) -> 7.6891159 | L28: MI_V3 | M28: =VLOOKUP(L28,allgemein!$B$3:$C$13,2,FALSE) -> 1 | N28: 25 | O28: FA702768
B29: 18A-0014Z | C29: " | D29: 23.6 | E29: 0.3 | F29: 177 | H29: 1.903 | I29: 1.886 | J29: =H29-I29 -> 0.017 | K29: =(F29*(273.15+D29)/273.15)/(M29*N29) -> 7.6917079 | L29: MI_V3 | M29: =VLOOKUP(L29,allgemein!$B$3:$C$13,2,FALSE) -> 1 | N29: 25 | O29: "
B30: 18A-0015Z | C30: " | D30: 23.7 | E30: 0.4 | F30: 177 | H30: 1.89 | I30: 1.877 | J30: =H30-I30 -> 0.013 | K30: =(F30*(273.15+D30)/273.15)/(M30*N30) -> 7.6942998 | L30: MI_V3 | M30: =VLOOKUP(L30,allgemein!$B$3:$C$13,2,FALSE) -> 1 | N30: 25 | O30: "
B31: 18A-0016Z | C31: " | D31: 23.9 | E31: 0.5 | F31: 178 | H31: 1.894 | I31: 1.877 | J31: =H31-I31 -> 0.017 | K31: =(F31*(273.15+D31)/273.15)/(M31*N31) -> 7.7429837 | L31: MI_V3 | M31: =VLOOKUP(L31,allgemein!$B$3:$C$13,2,FALSE) -> 1 | N31: 25 | O31: "
B32: 18A-0017Z | C32: " | D32: 24.2 | E32: 0.4 | F32: 178 | H32: 1.894 | I32: 1.88 | J32: =H32-I32 -> 0.014 | K32: =(F32*(273.15+D32)/273.15)/(M32*N32) -> 7.7508036 | L32: MI_V3 | M32: =VLOOKUP(L32,allgemein!$B$3:$C$13,2,FALSE) -> 1 | N32: 25 | O32: "
B33: 18A-0018Z | C33: " | D33: 24.6 | E33: 0.4 | F33: 178 | H33: 1.876 | I33: 1.86 | J33: =H33-I33 -> 0.016 | K33: =(F33*(273.15+D33)/273.15)/(M33*N33) -> 7.7612301 | L33: MI_V3 | M33: =VLOOKUP(L33,allgemein!$B$3:$C$13,2,FALSE) -> 1 | N33: 25 | O33: "
B34: 18A-0019Z | C34: " | D34: 25.2 | E34: 1 | F34: 175 | H34: 1.883 | I34: 1.87 | J34: =H34-I34 -> 0.013 | K34: =(F34*(273.15+D34)/273.15)/(M34*N34) -> 7.645799 | L34: MI_V3 | M34: =VLOOKUP(L34,allgemein!$B$3:$C$13,2,FALSE) -> 1 | N34: 25 | O34: "
B35: 18A-0020Z | C35: " | D35: 23 | E35: 0.3 | F35: 176 | H35: 1.894 | I35: 1.876 | J35: =H35-I35 -> 0.018 | K35: =(F35*(273.15+D35)/273.15)/(M35*N35) -> 7.6327878 | L35: MI_V3 | M35: =VLOOKUP(L35,allgemein!$B$3:$C$13,2,FALSE) -> 1 | N35: 25 | O35: "
B36: 18A-0021Z | C36: " | D36: 23 | E36: 0.3 | F36: 177 | H36: 1.889 | I36: 1.877 | J36: =H36-I36 -> 0.012 | K36: =(F36*(273.15+D36)/273.15)/(M36*N36) -> 7.676156 | L36: MI_V3 | M36: =VLOOKUP(L36,allgemein!$B$3:$C$13,2,FALSE) -> 1 | N36: 25 | O36: "
B37: 18A-0022Z | C37: " | D37: 23.9 | E37: 0.3 | F37: 178 | H37: 1.878 | I37: 1.862 | J37: =H37-I37 -> 0.016 | K37: =(F37*(273.15+D37)/273.15)/(M37*N37) -> 7.7429837 | L37: MI_V3 | M37: =VLOOKUP(L37,allgemein!$B$3:$C$13,2,FALSE) -> 1 | N37: 25 | O37: "
B38: 18A-0023Z | C38: " | D38: 24.2 | E38: 0.5 | F38: 178 | H38: 1.879 | I38: 1.864 | J38: =H38-I38 -> 0.015 | K38: =(F38*(273.15+D38)/273.15)/(M38*N38) -> 7.7508036 | L38: MI_V3 | M38: =VLOOKUP(L38,allgemein!$B$3:$C$13,2,FALSE) -> 1 | N38: 25 | O38: "
B39: 18A-0024Z | C39: " | D39: 24.6 | E39: 0.5 | F39: 178 | H39: 1.874 | I39: 1.86 | J39: =H39-I39 -> 0.014 | K39: =(F39*(273.15+D39)/273.15)/(M39*N39) -> 7.7612301 | L39: MI_V3 | M39: =VLOOKUP(L39,allgemein!$B$3:$C$13,2,FALSE) -> 1 | N39: 25 | O39: "
... B50: 18A-0035Z | C50: " | D50: 24.3 | E50: 0.3 | F50: 284 | H50: 1.87 | I50: 1.858 | J50: =H50-I50 -> 0.012 | K50: =(F50*(273.15+D50)/273.15)/(M50*N50) -> 7.731631 | L50: MU1 | M50: =VLOOKUP(L50,allgemein!$B$3:$C$13,2,FALSE) -> 1 | N50: 40 | O50: "
B51: 18A-0036Z | C51: " | D51: 24.3 | E51: 0.2 | F51: 285 | H51: 1.873 | I51: 1.862 | J51: =H51-I51 -> 0.011 | K51: =(F51*(273.15+D51)/273.15)/(M51*N51) -> 7.758855 | L51: MU1 | M51: =VLOOKUP(L51,allgemein!$B$3:$C$13,2,FALSE) -> 1 | N51: 40 | O51: " | P51: neues Pl. MkCC3809
...

Sheet Feb
B2: Cell # | C2: Membran # ¦ Batch # | D2: Temp Gas / [°C] | E2: Temp Kat T1-T2 / [°C] | F2: Gasfluss / [sccm / min] | G2: Membrane V @ 13 bar/[V] | H2: Cell V @ 13 bar/[V] | I2: Cell V @ 0 bar [V] | J2: Voltage Diff. / [V] | K2: H2 Prod / [nmL/A] | L2: Typ | M2: Anzahl Layer | N2: Strom / [A] | O2: FA # | P2: Bemerkungen | R2: Visum | S2: Jahr: | T2: 2018
B3: 18B-0001Z | C3: FA702785 | D3: 24.3 | E3: 0.4 | F3: 286 | H3: 1.875 | I3: 1.863 | J3: =H3-I3 -> 0.012 | K3: =(F3*(273.15+D3)/273.15)/(M3*N3) -> 7.7860791 | L3: MU1 | M3: =VLOOKUP(L3,allgemein!$B$3:$C$13,2,FALSE) -> 1 | N3: 40 | O3: FA703428
B4: 18B-0002Z | C4: FA703191 | D4: 23.9 | E4: 0.5 | F4: 286 | H4: 1.855 | I4: 1.844 | J4: =H4-I4 -> 0.011 | K4: =(F4*(273.15+D4)/273.15)/(M4*N4) -> 7.7756086 | L4: MU1 | M4: =VLOOKUP(L4,allgemein!$B$3:$C$13,2,FALSE) -> 1 | N4: 40 | O4: "
B5: 18B-0003Z | C5: " | D5: 24 | E5: 0.3 | F5: 285 | H5: 1.874 | I5: 1.863 | J5: =H5-I5 -> 0.011 | K5: =(F5*(273.15+D5)/273.15)/(M5*N5) -> 7.7510297 | L5: MU1 | M5: =VLOOKUP(L5,allgemein!$B$3:$C$13,2,FALSE) -> 1 | N5: 40 | O5: "
B6: 18B-0004Z | C6: " | D6: 23.8 | E6: 0.2 | F6: 285 | H6: 1.882 | I6: 1.87 | J6: =H6-I6 -> 0.012 | K6: =(F6*(273.15+D6)/273.15)/(M6*N6) -> 7.7458127 | L6: MU1 | M6: =VLOOKUP(L6,allgemein!$B$3:$C$13,2,FALSE) -> 1 | N6: 40 | O6: "
B7: 18B-0005Z | C7: " | D7: 23.6 | E7: 0.3 | F7: 284 | H7: 1.874 | I7: 1.864 | J7: =H7-I7 -> 0.01 | K7: =(F7*(273.15+D7)/273.15)/(M7*N7) -> 7.7134358 | L7: MU1 | M7: =VLOOKUP(L7,allgemein!$B$3:$C$13,2,FALSE) -> 1 | N7: 40 | O7: "
B8: 18B-0006Z | C8: " | D8: 23.2 | E8: 0.1 | F8: 285 | H8: 1.878 | I8: 1.866 | J8: =H8-I8 -> 0.012 | K8: =(F8*(273.15+D8)/273.15)/(M8*N8) -> 7.730162 | L8: MU1 | M8: =VLOOKUP(L8,allgemein!$B$3:$C$13,2,FALSE) -> 1 | N8: 40 | O8: "
B9: 18B-0007Z-R | C9: FA702785 | D9: 24.2 | E9: 0.4 | F9: 285 | H9: 1.9 | I9: 1.888 | J9: =H9-I9 -> 0.012 | K9: =(F9*(273.15+D9)/273.15)/(M9*N9) -> 7.7562466 | L9: MA_V1 | M9: =VLOOKUP(L9,allgemein!$B$3:$C$13,2,FALSE) -> 1 | N9: 40 | O9: FA703598 | P9: ersetzt: 1506-5855A
B10: 18B-0008Z-R | C10: FA703191 | D10: 24.2 | E10: 0.2 | F10: 285 | H10: 1.895 | I10: 1.881 | J10: =H10-I10 -> 0.014 | K10: =(F10*(273.15+D10)/273.15)/(M10*N10) -> 7.7562466 | L10: MA_V1 | M10: =VLOOKUP(L10,allgemein!$B$3:$C$13,2,FALSE) -> 1 | N10: 40 | O10: " | P10: ersetzt: 1506-5856A
B11: 18B-0009Z-R | C11: " | D11: 24 | E11: 0.2 | F11: 285 | H11: 1.896 | I11: 1.885 | J11: =H11-I11 -> 0.011 | K11: =(F11*(273.15+D11)/273.15)/(M11*N11) -> 7.7510297 | L11: MA_V1 | M11: =VLOOKUP(L11,allgemein!$B$3:$C$13,2,FALSE) -> 1 | N11: 40 | O11: ?
B12: 18B-0010Z-R | C12: " | D12: 23.7 | E12: 0.1 | F12: 285 | H12: 1.905 | I12: 1.895 | J12: =H12-I12 -> 0.01 | K12: =(F12*(273.15+D12)/273.15)/(M12*N12) -> 7.7432043 | L12: MA_V1 | M12: =VLOOKUP(L12,allgemein!$B$3:$C$13,2,FALSE) -> 1 | N12: 40 | O12: ?
B13: 18B-0011Z-R | C13: " | D13: 23.2 | E13: 0 | F13: 285 | H13: 1.904 | I13: 1.892 | J13: =H13-I13 -> 0.012 | K13: =(F13*(273.15+D13)/273.15)/(M13*N13) -> 7.730162 | L13: MA_V1 | M13: =VLOOKUP(L13,allgemein!$B$3:$C$13,2,FALSE) -> 1 | N13: 40 | O13: ?
B14: 18B-0012Z-R | C14: " | D14: 24.2 | E14: 0.4 | F14: 285 | H14: 1.911 | I14: 1.899 | J14: =H14-I14 -> 0.012 | K14: =(F14*(273.15+D14)/273.15)/(M14*N14) -> 7.7562466 | L14: MA_V1 | M14: =VLOOKUP(L14,allgemein!$B$3:$C$13,2,FALSE) -> 1 | N14: 40 | O14: FA703595
B15: 18B-0013Z-R | C15: " | D15: 24.2 | E15: 0.3 | F15: 285 | H15: 1.912 | I15: 1.899 | J15: =H15-I15 -> 0.013 | K15: =(F15*(273.15+D15)/273.15)/(M15*N15) -> 7.7562466 | L15: MA_V1 | M15: =VLOOKUP(L15,allgemein!$B$3:$C$13,2,FALSE) -> 1 | N15: 40 | O15: "
B16: 18B-0014Z-R | C16: " | D16: 24.3 | E16: 0.3 | F16: 285 | H16: 1.887 | I16: 1.876 | J16: =H17-I17 -> 0.009 | K16: =(F17*(273.15+D17)/273.15)/(M16*N16) -> 7.7290317 | L16: MA_V1 | M16: =VLOOKUP(L16,allgemein!$B$3:$C$13,2,FALSE) -> 1 | N16: 40 | O16: "
B17: 18B-0015Z-R | C17: " | D17: 24.2 | E17: 0.7 | F17: 284 | H17: 1.916 | I17: 1.907 | J17: =H16-I16 -> 0.011 | K17: =(F16*(273.15+D16)/273.15)/(M17*N17) -> 7.758855 | L17: MA_V1 | M17: =VLOOKUP(L17,allgemein!$B$3:$C$13,2,FALSE) -> 1 | N17: 40 | O17: "
B18: 18B-0016Z-R | C18: " | D18: 24.4 | E18: 0.3 | F18: 284 | H18: 1.907 | I18: 1.896 | J18: =H18-I18 -> 0.011 | K18: =(F18*(273.15+D18)/273.15)/(M18*N18) -> 7.7342303 | L18: MA_V1 | M18: =VLOOKUP(L18,allgemein!$B$3:$C$13,2,FALSE) -> 1 | N18: 40 | O18: "
B19: 18B-0017Z-R | C19: " | D19: 25.8 | E19: 0 | F19: 285 | H19: 1.884 | I19: 1.874 | J19: =H19-I19 -> 0.01 | K19: =(F19*(273.15+D19)/273.15)/(M19*N19) -> 7.7979819 | L19: MA_V1 | M19: =VLOOKUP(L19,allgemein!$B$3:$C$13,2,FALSE) -> 1 | N19: 40 | O19: "
B20: 18B-0018Z-R | C20: " | D20: 26 | E20: 0 | F20: 286 | H20: 1.909 | I20: 1.897 | J20: =H20-I20 -> 0.012 | K20: =(F20*(273.15+D20)/273.15)/(M20*N20) -> 7.8305784 | L20: MA_V1 | M20: =VLOOKUP(L20,allgemein!$B$3:$C$13,2,FALSE) -> 1 | N20: 40 | O20: "
B21: 18B-0019Z-R | C21: " | D21: 26.3 | E21: 0.1 | F21: 284 | H21: 1.898 | I21: 1.888 | J21: =H21-I21 -> 0.01 | K21: =(F21*(273.15+D21)/273.15)/(M21*N21) -> 7.7836171 | L21: MA_V1 | M21: =VLOOKUP(L21,allgemein!$B$3:$C$13,2,FALSE) -> 1 | N21: 40 | O21: "
B22: 18B-0020Z-R | C22: FA703192 | D22: 26.7 | E22: 0 | F22: 284 | H22: 1.89 | I22: 1.879 | J22: =H22-I22 -> 0.011 | K22: =(F22*(273.15+D22)/273.15)/(M22*N22) -> 7.7940143 | L22: MA_V1 | M22: =VLOOKUP(L22,allgemein!$B$3:$C$13,2,FALSE) -> 1 | N22: 40 | O22: "
B23: 18B-0021Z-R | C23: " | D23: 27.2 | E23: 0 | F23: 284 | H23: 1.873 | I23: 1.86 | J23: =H23-I23 -> 0.013 | K23: =(F23*(273.15+D23)/273.15)/(M23*N23) -> 7.8070108 | L23: MA_V1 | M23: =VLOOKUP(L23,allgemein!$B$3:$C$13,2,FALSE) -> 1 | N23: 40 | O23: "
B24: 18B-0022Z | C24: " | D24: 25.2 | E24: 0.5 | F24: 285 | H24: 1.856 | I24: 1.845 | J24: =H24-I24 -> 0.011 | K24: =(F24*(273.15+D24)/273.15)/(M24*N24) -> 7.7823311 | L24: MU1 | M24: =VLOOKUP(L24,allgemein!$B$3:$C$13,2,FALSE) -> 1 | N24: 40 | O24: FA703428
B25: 18B-0023Z | C25: " | D25: 25.2 | E25: 0.3 | F25: 285 | H25: 1.855 | I25: 1.843 | J25: =H25-I25 -> 0.012 | K25: =(F25*(273.15+D25)/273.15)/(M25*N25) -> 7.7823311 | L25: MU1 | M25: =VLOOKUP(L25,allgemein!$B$3:$C$13,2,FALSE) -> 1 | N25: 40 | O25: "
B26: 18B-0024Z | C26: " | D26: 25.2 | E26: 0.3 | F26: 286 | H26: 1.86 | I26: 1.846 | J26: =H26-I26 -> 0.014 | K26: =(F26*(273.15+D26)/273.15)/(M26*N26) -> 7.8096376 | L26: MU1 | M26: =VLOOKUP(L26,allgemein!$B$3:$C$13,2,FALSE) -> 1 | N26: 40 | O26: "
B27: 18B-0025Z | C27: " | D27: 25.2 | E27: 0 | F27: 285 | H27: 1.855 | I27: 1.842 | J27: =H27-I27 -> 0.013 | K27: =(F27*(273.15+D27)/273.15)/(M27*N27) -> 7.7823311 | L27: MU1 | M27: =VLOOKUP(L27,allgemein!$B$3:$C$13,2,FALSE) -> 1 | N27: 40 | O27: "
B28: 18B-0026Z | C28: " | D28: 24.9 | E28: 0.3 | F28: 284 | H28: 1.853 | I28: 1.841 | J28: =H28-I28 -> 0.012 | K28: =(F28*(273.15+D28)/273.15)/(M28*N28) -> 7.7472268 | L28: MU1 | M28: =VLOOKUP(L28,allgemein!$B$3:$C$13,2,FALSE) -> 1 | N28: 40 | O28: "
B29: 18B-0027Z | C29: " | D29: 24.8 | E29: 0.5 | F29: 285 | H29: 1.863 | I29: 1.85 | J29: =H29-I29 -> 0.013 | K29: =(F29*(273.15+D29)/273.15)/(M29*N29) -> 7.7718973 | L29: MU1 | M29: =VLOOKUP(L29,allgemein!$B$3:$C$13,2,FALSE) -> 1 | N29: 40 | O29: "
B30: 18B-0028Z | C30: " | D30: 24.8 | E30: 0.7 | F30: 286 | H30: 1.868 | I30: 1.853 | J30: =H30-I30 -> 0.015 | K30: =(F30*(273.15+D30)/273.15)/(M30*N30) -> 7.7991671 | L30: MU1 | M30: =VLOOKUP(L30,allgemein!$B$3:$C$13,2,FALSE) -> 1 | N30: 40 | O30: " | P30: Mem. kleiner Faden
B31: 18B-0029Z | C31: " | D31: 24.8 | E31: 0.5 | F31: 287 | H31: 1.874 | I31: 1.859 | J31: =H31-I31 -> 0.015 | K31: =(F31*(273.15+D31)/273.15)/(M31*N31) -> 7.8264369 | L31: MU1 | M31: =VLOOKUP(L31,allgemein!$B$3:$C$13,2,FALSE) -> 1 | N31: 40 | O31: "
B32: 18B-0030Z | C32: " | D32: 24.7 | E32: 0.6 | F32: 286 | H32: 1.867 | I32: 1.852 | J32: =H32-I32 -> 0.015 | K32: =(F32*(273.15+D32)/273.15)/(M32*N32) -> 7.7965495 | L32: MU1 | M32: =VLOOKUP(L32,allgemein!$B$3:$C$13,2,FALSE) -> 1 | N32: 40 | O32: "
B33: 18B-0031Z | C33: " | D33: 24.6 | E33: 0.6 | F33: 285 | H33: 1.869 | I33: 1.855 | J33: =H33-I33 -> 0.014 | K33: =(F33*(273.15+D33)/273.15)/(M33*N33) -> 7.7666804 | L33: MU1 | M33: =VLOOKUP(L33,allgemein!$B$3:$C$13,2,FALSE) -> 1 | N33: 40 | O33: "
B34: 18B-0032Z | C34: " | D34: 24.3 | E34: 0.6 | F34: 285 | H34: 1.874 | I34: 1.86 | J34: =H34-I34 -> 0.014 | K34: =(F34*(273.15+D34)/273.15)/(M34*N34) -> 7.758855 | L34: MU1 | M34: =VLOOKUP(L34,allgemein!$B$3:$C$13,2,FALSE) -> 1 | N34: 40 | O34: "
B35: 18B-0033Z | C35: " | D35: 24 | E35: 0.4 | F35: 285 | H35: 1.856 | I35: 1.845 | J35: =H35-I35 -> 0.011 | K35: =(F35*(273.15+D35)/273.15)/(M35*N35) -> 7.7510297 | L35: MU1 | M35: =VLOOKUP(L35,allgemein!$B$3:$C$13,2,FALSE) -> 1 | N35: 40 | O35: "
B36: 18B-0034Z | C36: FA702672 | D36: 23.6 | E36: 0.2 | F36: 177 | H36: 1.895 | I36: 1.884 | J36: =H36-I36 -> 0.011 | K36: =(F36*(273.15+D36)/273.15)/(M36*N36) -> 7.6917079 | L36: MI_V3 | M36: =VLOOKUP(L36,allgemein!$B$3:$C$13,2,FALSE) -> 1 | N36: 25 | O36: FA703325
B37: 18B-0035Z | C37: " | D37: 23.4 | E37: 0.4 | F37: 177 | H37: 1.903 | I37: 1.894 | J37: =H37-I37 -> 0.009 | K37: =(F37*(273.15+D37)/273.15)/(M37*N37) -> 7.6865239 | L37: MI_V3 | M37: =VLOOKUP(L37,allgemein!$B$3:$C$13,2,FALSE) -> 1 | N37: 25 | O37: "
B38: 18B-0036Z | C38: " | D38: 23.3 | E38: 0.4 | F38: 177 | H38: 1.892 | I38: 1.883 | J38: =H38-I38 -> 0.009 | K38: =(F38*(273.15+D38)/273.15)/(M38*N38) -> 7.6839319 | L38: MI_V3 | M38: =VLOOKUP(L38,allgemein!$B$3:$C$13,2,FALSE) -> 1 | N38: 25 | O38: "
B39: 18B-0037Z | C39: " | D39: 23.4 | E39: 0.4 | F39: 178 | H39: 1.89 | I39: 1.88 | J39: =H39-I39 -> 0.01 | K39: =(F39*(273.15+D39)/273.15)/(M39*N39) -> 7.7299506 | L39: MI_V3 | M39: =VLOOKUP(L39,allgemein!$B$3:$C$13,2,FALSE) -> 1 | N39: 25 | O39: "
B40: 18B-0038Z | C40: " | D40: 23.4 | E40: 0.4 | F40: 177 | H40: 1.883 | I40: 1.873 | J40: =H40-I40 -> 0.01 | K40: =(F40*(273.15+D40)/273.15)/(M40*N40) -> 7.6865239 | L40: MI_V3 | M40: =VLOOKUP(L40,allgemein!$B$3:$C$13,2,FALSE) -> 1 | N40: 25 | O40: "
B41: 18B-0039Z | C41: " | D41: 23.4 | E41: 0.6 | F41: 177 | H41: 1.896 | I41: 1.887 | J41: =H41-I41 -> 0.009 | K41: =(F41*(273.15+D41)/273.15)/(M41*N41) -> 7.6865239 | L41: MI_V3 | M41: =VLOOKUP(L41,allgemein!$B$3:$C$13,2,FALSE) -> 1 | N41: 25 | O41: "
...

Sheet Mar
B2: Cell # | C2: Membran # ¦ Batch # | D2: Temp Gas / [°C] | E2: Temp Kat T1-T2 / [°C] | F2: Gasfluss / [sccm / min] | G2: Membrane V @ 13 bar/[V] | H2: Cell V @ 13 bar/[V] | I2: Cell V @ 0 bar [V] | J2: Voltage Diff. / [V] | K2: H2 Prod / [nmL/A] | L2: Typ | M2: Anzahl Layer | N2: Strom / [A] | O2: FA # | P2: Bemerkungen | R2: Visum | S2: Jahr: | T2: 2018
B3: 18C-0001Z | C3: FA703434 | D3: 25.8 | E3: 0.3 | F3: 857 | G3: 1.83 | H3: 5.49 | I3: 5.443 | J3: =IF(M3<>"",(H3-I3)/M3,"") -> 0.015666667 | K3: =(F3*(273.15+D3)/273.15)/(M3*N3) -> 7.8162228 | L3: MU3 | M3: =VLOOKUP(L3,allgemein!$B$3:$C$13,2,FALSE) -> 3 | N3: 40 | O3: FA703707 | P3: H-Elektr. 4 | Q3: Mem. FA703434 grobes Edelstahl- Vlies
C4: " | G4: 1.828 | J4: =IF(M4<>"",(H4-I4)/M4,"") | P4: Z-Elektr. 7 | Q4: "
C5: " | G5: 1.832 | J5: =IF(M5<>"",(H5-I5)/M5,"") | P5: Z-Elektr. 8 | Q5: "
B6: 18C-0002Z | C6: " | D6: 24.6 | E6: 0.4 | F6: 572 | G6: 1.856 | H6: 3.726 | I6: 3.69 | J6: =IF(M6<>"",(H6-I6)/M6,"") -> 0.018 | K6: =(F6*(273.15+D6)/273.15)/(M6*N6) -> 7.7939319 | L6: MU2 | M6: =VLOOKUP(L6,allgemein!$B$3:$C$13,2,FALSE) -> 2 | N6: 40 | O6: FA703708 | P6: H-Elektr.5/ WZauf0.7/3T | Q6: Mem. FA703434 grobes Edelstahl- Vlies
C7: FA703432 | G7: 1.87 | J7: =IF(M7<>"",(H7-I7)/M7,"") | P7: Z-Elektr. D8 | Q7: auf Spülanl.1.875;Mem. feines Vlies gewechselt= 1.830
B8: 18C-0003Z | C8: FA703434 | D8: 24.3 | E8: 0.1 | F8: 285 | H8: 1.861 | I8: 1.838 | J8: =IF(M8<>"",(H8-I8)/M8,"") -> 0.023 | K8: =(F8*(273.15+D8)/273.15)/(M8*N8) -> 7.758855 | L8: MU1 | M8: =VLOOKUP(L8,allgemein!$B$3:$C$13,2,FALSE) -> 1 | N8: 40 | O8: FA703597 | P8: WZauf0.7/3T | Q8: Mem. FA703434 grobes Edelstahl- Vlies (einges. Mem. vorher eingesetzt s.Spalte7
C9: " | D9: 24.6 | E9: 0.3 | F9: 285 | H9: 1.856 | I9: 1.833 | J9: =IF(M9<>"",(H9-I9)/M9,"") -> 0.023 | K9: =(F9*(273.15+D9)/273.15)/(M9*N9) -> 7.7666804 | L9: MU1 | M9: =VLOOKUP(L9,allgemein!$B$3:$C$13,2,FALSE) -> 1 | N9: 40 | O9: " | P9: mit 3.2Nm angezogen
C10: " | D10: 21.4 | E10: 0 | F10: 285 | H10: 1.853 | I10: 1.841 | J10: =IF(M10<>"",(H10-I10)/M10,"") -> 0.012 | K10: =(F10*(273.15+D10)/273.15)/(M10*N10) -> 7.6832098 | L10: MU1 | M10: =VLOOKUP(L10,allgemein!$B$3:$C$13,2,FALSE) -> 1 | N10: 40 | O10: " | P10: Mem. mit feinem Vlies
B11: 18C-0004Z | C11: FA703433 | D11: 25.3 | E11: 0.5 | F11: 284 | H11: 1.854 | I11: 1.834 | J11: =IF(M11<>"",(H11-I11)/M11,"") -> 0.02 | K11: =(F11*(273.15+D11)/273.15)/(M11*N11) -> 7.757624 | L11: MU1 | M11: =VLOOKUP(L11,allgemein!$B$3:$C$13,2,FALSE) -> 1 | N11: 40 | O11: " | P11: Mem. FA703433 grobes Edelstahl- Vlies
B12: 18C-0005Z | C12: " | D12: 25.2 | E12: 0.5 | F12: 285 | H12: 1.847 | I12: 1.831 | J12: =IF(M12<>"",(H12-I12)/M12,"") -> 0.016 | K12: =(F12*(273.15+D12)/273.15)/(M12*N12) -> 7.7823311 | L12: MU1 | M12: =VLOOKUP(L12,allgemein!$B$3:$C$13,2,FALSE) -> 1 | N12: 40 | O12: " | P12: "
B13: 18C-0006Z | C13: " | D13: 25.2 | E13: 0.4 | F13: 284 | H13: 1.845 | I13: 1.827 | J13: =IF(M13<>"",(H13-I13)/M13,"") -> 0.018 | K13: =(F13*(273.15+D13)/273.15)/(M13*N13) -> 7.7550247 | L13: MU1 | M13: =VLOOKUP(L13,allgemein!$B$3:$C$13,2,FALSE) -> 1 | N13: 40 | O13: " | P13: "
B14: 18C-0007Z | C14: " | D14: 25.1 | E14: 0.3 | F14: 284 | H14: 1.857 | I14: 1.839 | J14: =IF(M14<>"",(H14-I14)/M14,"") -> 0.018 | K14: =(F14*(273.15+D14)/273.15)/(M14*N14) -> 7.7524254 | L14: MU1 | M14: =VLOOKUP(L14,allgemein!$B$3:$C$13,2,FALSE) -> 1 | N14: 40 | O14: " | P14: "
B15: 18C-0008Z | C15: " | D15: 24.8 | E15: 0.1 | F15: 284 | H15: 1.865 | I15: 1.837 | J15: =IF(M15<>"",(H15-I15)/M15,"") -> 0.028 | K15: =(F15*(273.15+D15)/273.15)/(M15*N15) -> 7.7446275 | L15: MU1 | M15: =VLOOKUP(L15,allgemein!$B$3:$C$13,2,FALSE) -> 1 | N15: 40 | O15: " | P15: " | Q15: H-Elektr. (D-09_06) mit leichter Toleranzabweich.
B16: 18C-0009Z-R | C16: " | D16: 25.2 | E16: 0.6 | F16: 284 | H16: 1.909 | I16: 1.895 | J16: =IF(M16<>"",(H16-I16)/M16,"") -> 0.014 | K16: =(F16*(273.15+D16)/273.15)/(M16*N16) -> 7.7550247 | L16: MA_V1 | M16: =VLOOKUP(L16,allgemein!$B$3:$C$13,2,FALSE) -> 1 | N16: 40 | O16: FA703809 | P16: "
B17: 18C-0010Z-R | C17: " | D17: 25.5 | E17: 0.7 | F17: 283 | H17: 1.9 | I17: 1.887 | J17: =IF(M17<>"",(H17-I17)/M17,"") -> 0.013 | K17: =(F17*(273.15+D17)/273.15)/(M17*N17) -> 7.7354887 | L17: MA_V1 | M17: =VLOOKUP(L17,allgemein!$B$3:$C$13,2,FALSE) -> 1 | N17: 40 | O17: " | P17: "
B18: 18C-0011Z-R | C18: " | D18: 25.2 | E18: 0.6 | F18: 284 | H18: 1.904 | I18: 1.888 | J18: =IF(M18<>"",(H18-I18)/M18,"") -> 0.016 | K18: =(F18*(273.15+D18)/273.15)/(M18*N18) -> 7.7550247 | L18: MA_V1 | M18: =VLOOKUP(L18,allgemein!$B$3:$C$13,2,FALSE) -> 1 | N18: 40 | O18: " | P18: "
B19: 18C-0012Z-R | C19: " | D19: 25.3 | E19: 0.7 | F19: 284 | H19: 1.905 | I19: 1.894 | J19: =IF(M19<>"",(H19-I19)/M19,"") -> 0.011 | K19: =(F19*(273.15+D19)/273.15)/(M19*N19) -> 7.757624 | L19: MA_V1 | M19: =VLOOKUP(L19,allgemein!$B$3:$C$13,2,FALSE) -> 1 | N19: 40 | O19: " | P19: "
B20: 18C-0013Z-R | C20: " | D20: 25.3 | E20: 0.2 | F20: 285 | H20: 1.903 | I20: 1.89 | J20: =IF(M20<>"",(H20-I20)/M20,"") -> 0.013 | K20: =(F20*(273.15+D20)/273.15)/(M20*N20) -> 7.7849396 | L20: MA_V1 | M20: =VLOOKUP(L20,allgemein!$B$3:$C$13,2,FALSE) -> 1 | N20: 40 | O20: " | P20: "
B21: 18C-0014Z-R | C21: " | D21: 24.9 | E21: 0.4 | F21: 286 | H21: 1.911 | I21: 1.895 | J21: =IF(M21<>"",(H21-I21)/M21,"") -> 0.016 | K21: =(F21*(273.15+D21)/273.15)/(M21*N21) -> 7.8017847 | L21: MA_V1 | M21: =VLOOKUP(L21,allgemein!$B$3:$C$13,2,FALSE) -> 1 | N21: 40 | O21: " | P21: "
B22: 18C-0015Z-R | C22: FA703434 | D22: 25 | E22: 0.3 | F22: 286 | H22: 1.911 | I22: 1.897 | J22: =IF(M22<>"",(H22-I22)/M22,"") -> 0.014 | K22: =(F22*(273.15+D22)/273.15)/(M22*N22) -> 7.8044023 | L22: MA_V1 | M22: =VLOOKUP(L22,allgemein!$B$3:$C$13,2,FALSE) -> 1 | N22: 40 | O22: " | P22: Mem. FA703434 grobes Edelstahl- Vlies Mem. aus 18C-0003Z
B23: 18C-0016Z-R | D23: 25.1 | E23: 0.6 | F23: 285 | H23: 1.914 | I23: 1.902 | J23: =IF(M23<>"",(H23-I23)/M23,"") -> 0.012 | K23: =(F23*(273.15+D23)/273.15)/(M23*N23) -> 7.7797227 | L23: MA_V1 | M23: =VLOOKUP(L23,allgemein!$B$3:$C$13,2,FALSE) -> 1 | N23: 40 | O23: "
B24: 18C-0017Z-R | D24: 24.8 | E24: 0.4 | F24: 284 | H24: 1.889 | I24: 1.878 | J24: =IF(M24<>"",(H24-I24)/M24,"") -> 0.011 | K24: =(F24*(273.15+D24)/273.15)/(M24*N24) -> 7.7446275 | L24: MA_V1 | M24: =VLOOKUP(L24,allgemein!$B$3:$C$13,2,FALSE) -> 1 | N24: 40 | O24: "
B25: 18C-0018Z-R | D25: 24.9 | E25: 0.4 | F25: 284 | H25: 1.923 | I25: 1.911 | J25: =IF(M25<>"",(H25-I25)/M25,"") -> 0.012 | K25: =(F25*(273.15+D25)/273.15)/(M25*N25) -> 7.7472268 | L25: MA_V1 | M25: =VLOOKUP(L25,allgemein!$B$3:$C$13,2,FALSE) -> 1 | N25: 40 | O25: "
J26: =IF(M26<>"",(H26-I26)/M26,"")
J27: =IF(M27<>"",(H27-I27)/M27,"")
J28: =IF(M28<>"",(H28-I28)/M28,"")
J29: =IF(M29<>"",(H29-I29)/M29,"")
J30: =IF(M30<>"",(H30-I30)/M30,"")
B31: Reparaturen | J31: =IF(M31<>"",(H31-I31)/M31,"")
B32: 17E-0035Z | C32: FA701912 | J32: =H32-I32 -> 0 | K32: =(F32*(273.15+D32)/273.15)/(M32*N32) -> 0 | L32: MI_V3 | M32: =VLOOKUP(L32,allgemein!$B$3:$C$13,2,FALSE) -> 1 | N32: 25 | P32: 2.25V/ KatTemp rasant >>75°>>>>
J33: =IF(M33<>"",(H33-I33)/M33,"")
J34: =IF(M34<>"",(H34-I34)/M34,"")
J35: =IF(M35<>"",(H35-I35)/M35,"")
J36: =IF(M36<>"",(H36-I36)/M36,"")
J37: =IF(M37<>"",(H37-I37)/M37,"")
J38: =IF(M38<>"",(H38-I38)/M38,"")
J39: =IF(M39<>"",(H39-I39)/M39,"")
J40: =IF(M40<>"",(H40-I40)/M40,"")
J41: =IF(M41<>"",(H41-I41)/M41,"")
...

Sheet Apr
B2: Cell # | C2: Membran # ¦ Batch # | D2: Temp Gas / [°C] | E2: Temp Kat T1-T2 / [°C] | F2: Gasfluss / [sccm / min] | G2: Membrane V @ 13 bar/[V] | H2: Cell V @ 13 bar/[V] | I2: Cell V @ 0 bar [V] | J2: Voltage Diff. / [V] | K2: H2 Prod / [nmL/A] | L2: Typ | M2: Anzahl Layer | N2: Strom / [A] | O2: FA # | P2: Elektrode | Q2: Bemerkungen | R2: Visum | S2: Jahr: | T2: 2018
B3: 18D-0001Z | C3: FA703434 | G3: 1.792 | L3: MU12 | M3: =VLOOKUP(L3,allgemein!$B$3:$C$13,2,FALSE) -> 12 | N3: 40 | O3: FA703834
C4: " | G4: 1.791
C5: " | G5: 1.788
C6: " | G6: 1.799
C7: " | G7: 1.793
C8: FA703564 | G8: 1.785
C9: " | G9: 1.788
C10: " | G10: 1.787
C11: " | G11: 1.789
C12: " | G12: 1.788
C13: " | G13: 1.787
C14: " | G14: 1.782
B15: 18D-0002Z | C15: FA703434 | D15: 26.8 | E15: 0.4 | F15: 568 | G15: 1.837 | H15: 3.665 | I15: 3.634 | J15: =IF(M15<>"",(H15-I15)/M15,"") -> 0.0155 | K15: =(F15*(273.15+D15)/273.15)/(M15*N15) -> 7.7966136 | L15: MU2 | M15: =VLOOKUP(L15,allgemein!$B$3:$C$13,2,FALSE) -> 2 | N15: 40 | O15: FA703641 | P15: D-09_09
C16: " | G16: 1.828 | P16: B-07_17
B17: 18D-0003Z | C17: " | D17: 26.7 | E17: 0.5 | F17: 568 | G17: 1.84 | H17: 3.682 | I17: 3.652 | J17: =IF(M17<>"",(H17-I17)/M17,"") -> 0.015 | K17: =(F17*(273.15+D17)/273.15)/(M17*N17) -> 7.7940143 | L17: MU2 | M17: =VLOOKUP(L17,allgemein!$B$3:$C$13,2,FALSE) -> 2 | N17: 40 | O17: " | P17: D-09_10
C18: " | G18: 1.842 | P18: B-07_20
B19: 18D-0004Z | C19: " | D19: 26.5 | E19: 0.7 | F19: 567 | G19: 1.846 | H19: 3.679 | I19: 3.653 | J19: =IF(M19<>"",(H19-I19)/M19,"") -> 0.013 | K19: =(F19*(273.15+D19)/273.15)/(M19*N19) -> 7.775103 | L19: MU2 | M19: =VLOOKUP(L19,allgemein!$B$3:$C$13,2,FALSE) -> 2 | N19: 40 | O19: " | P19: D-09_13
C20: " | G20: 1.833 | P20: B-07_32
B21: 18D-0005Z | C21: " | D21: 26.2 | E21: 0.2 | F21: 568 | G21: 1.823 | H21: 3.649 | I21: 3.621 | J21: =IF(M21<>"",(H21-I21)/M21,"") -> 0.014 | K21: =(F21*(273.15+D21)/273.15)/(M21*N21) -> 7.7810178 | L21: MU2 | M21: =VLOOKUP(L21,allgemein!$B$3:$C$13,2,FALSE) -> 2 | N21: 40 | O21: " | P21: D-09_16
C22: " | G22: 1.826 | P22: B-07_51
B23: 18D-0006Z | C23: " | D23: 25.8 | E23: 0.1 | F23: 568 | G23: 1.845 | H23: 3.689 | I23: 3.654 | J23: =IF(M23<>"",(H23-I23)/M23,"") -> 0.0175 | K23: =(F23*(273.15+D23)/273.15)/(M23*N23) -> 7.7706205 | L23: MU2 | M23: =VLOOKUP(L23,allgemein!$B$3:$C$13,2,FALSE) -> 2 | N23: 40 | O23: " | P23: D-09_19
C24: " | G24: 1.844 | P24: B-07_52
B25: 18D-0007Z | C25: " | D25: 26.2 | E25: 0.2 | F25: 569 | G25: 1.833 | H25: 3.668 | I25: 3.644 | J25: =IF(M25<>"",(H25-I25)/M25,"") -> 0.012 | K25: =(F25*(273.15+D25)/273.15)/(M25*N25) -> 7.7947167 | L25: MU2 | M25: =VLOOKUP(L25,allgemein!$B$3:$C$13,2,FALSE) -> 2 | N25: 40 | O25: " | P25: B-09_05
C26: " | G26: 1.835 | P26: D-07_09
B27: 18D-0008Z | C27: FA703563 | D27: 25.9 | E27: 0.4 | F27: 569 | G27: 1.832 | H27: 3.668 | I27: 3.643 | J27: =IF(M27<>"",(H27-I27)/M27,"") -> 0.0125 | K27: =(F27*(273.15+D27)/273.15)/(M27*N27) -> 7.7869051 | L27: MU2 | M27: =VLOOKUP(L27,allgemein!$B$3:$C$13,2,FALSE) -> 2 | N27: 40 | O27: " | P27: B-09_02
C28: " | G28: 1.836 | P28: D-07_18
B29: 18D-0009Z | C29: " | D29: 26.2 | E29: 0.3 | F29: 569 | G29: 1.827 | H29: 3.676 | I29: 3.636 | J29: =IF(M29<>"",(H29-I29)/M29,"") -> 0.02 | K29: =(F29*(273.15+D29)/273.15)/(M29*N29) -> 7.7947167 | L29: MU2 | M29: =VLOOKUP(L29,allgemein!$B$3:$C$13,2,FALSE) -> 2 | N29: 40 | O29: " | P29: D-09_21
C30: " | G30: 1.849 | P30: D-07_29
B31: 18D-0010Z | C31: " | D31: 25.9 | E31: 0.7 | F31: 567 | G31: 1.834 | H31: 3.67 | I31: 3.65 | J31: =IF(M31<>"",(H31-I31)/M31,"") -> 0.01 | K31: =(F31*(273.15+D31)/273.15)/(M31*N31) -> 7.7595346 | L31: MU2 | M31: =VLOOKUP(L31,allgemein!$B$3:$C$13,2,FALSE) -> 2 | N31: 40 | O31: " | P31: D-09_23
C32: " | G32: 1.836 | P32: D-07_30
B33: 18D-0011Z | C33: " | D33: 25.4 | E33: 0 | F33: 569 | G33: 1.831 | H33: 3.668 | I33: 3.643 | J33: =IF(M33<>"",(H33-I33)/M33,"") -> 0.0125 | K33: =(F33*(273.15+D33)/273.15)/(M33*N33) -> 7.7738857 | L33: MU2 | M33: =VLOOKUP(L33,allgemein!$B$3:$C$13,2,FALSE) -> 2 | N33: 40 | O33: " | P33: D-09_24
C34: " | G34: 1.837 | P34: D-07_32
B35: 18D-0012Z | C35: " | D35: 26.9 | E35: 1.2 | F35: 568 | G35: 1.828 | H35: 3.657 | I35: 3.632 | J35: =IF(M35<>"",(H35-I35)/M35,"") -> 0.0125 | K35: =(F35*(273.15+D35)/273.15)/(M35*N35) -> 7.7992129 | L35: MU2 | M35: =VLOOKUP(L35,allgemein!$B$3:$C$13,2,FALSE) -> 2 | N35: 40 | O35: " | P35: B-09_02
C36: " | G36: 1.829 | P36: B-07_09
B37: 18D-0013Z | C37: " | D37: 26.8 | E37: 1.2 | F37: 568 | G37: 1.829 | H37: 3.66 | I37: 3.635 | J37: =IF(M37<>"",(H37-I37)/M37,"") -> 0.0125 | K37: =(F37*(273.15+D37)/273.15)/(M37*N37) -> 7.7966136 | L37: MU2 | M37: =VLOOKUP(L37,allgemein!$B$3:$C$13,2,FALSE) -> 2 | N37: 40 | O37: " | P37: B-09_03
C38: " | G38: 1.831 | P38: B-07_14
B39: 18D-0014Z | C39: " | D39: 26.9 | E39: 1.2 | F39: 569 | G39: 1.81 | H39: 3.637 | I39: 3.611 | J39: =IF(M39<>"",(H39-I39)/M39,"") -> 0.013 | K39: =(F39*(273.15+D39)/273.15)/(M39*N39) -> 7.8129439 | L39: MU2 | M39: =VLOOKUP(L39,allgemein!$B$3:$C$13,2,FALSE) -> 2 | N39: 40 | O39: " | P39: B-09_04
C40: " | G40: 1.827 | P40: B-07_26
B41: 18D-0015Z | C41: " | D41: 26.7 | E41: 0.9 | F41: 568 | G41: 1.818 | H41: 3.649 | I41: 3.627 | J41: =IF(M41<>"",(H41-I41)/M41,"") -> 0.011 | K41: =(F41*(273.15+D41)/273.15)/(M41*N41) -> 7.7940143 | L41: MU2 | M41: =VLOOKUP(L41,allgemein!$B$3:$C$13,2,FALSE) -> 2 | N41: 40 | O41: " | P41: B-09_06
...

Sheet May
B3: Cell # | C3: Membran # ¦ Batch # | D3: Temp Gas / [°C] | E3: Temp Kat T1-T2 / [°C] | F3: Gasfluss / [sccm / min] | G3: Membrane V @ 13 bar/[V] | H3: Cell V @ 13 bar/[V] | I3: Cell V @ 0 bar [V] | J3: Voltage Diff. / [V] | K3: H2 Prod / [nmL/A] | L3: Typ | M3: Anzahl Layer | N3: Strom / [A] | O3: FA # | P3: Elektrode | Q3: Bemerkungen | R3: Visum | S3: Jahr: | T3: 2018
B4: 18E-0001Z | C4: FA703682 | D4: kann nicht getestet | J4: =IF(M4<>"",(H4-I4)/M4,"") -> 0 | K4: =(F4*(273.15+D4)/273.15)/(M4*N4) -> #VALUE! | L4: MU4 | M4: =VLOOKUP(L4,allgemein!$B$3:$C$13,2,FALSE) -> 4 | O4: FA703876 | P4: B-09_32
C5: " | P5: B-07-36
C6: " | P6: B-07-39
C7: " | P7: B-07-50 | Q7: Mem. kleiner Faden
B8: 18E-0002Z | C8: " | D8: kann nicht getestet | J8: =IF(M8<>"",(H8-I8)/M8,"") -> 0 | K8: =(F8*(273.15+#REF!)/273.15)/(M8*N8) -> #REF! | L8: MU4 | M8: =VLOOKUP(L8,allgemein!$B$3:$C$13,2,FALSE) -> 4 | O8: " | P8: B-09_33
C9: FA703683 | P9: D-07-04
C10: " | P10: D-07-08
C11: " | P11: D-07-13
B12: 18E-0003Z | C12: " | D12: 26.5 | E12: 0.4 | F12: 853 | G12: 1.84 | H12: 5.526 | I12: 5.481 | J12: =IF(M12<>"",(H12-I12)/M12,"") -> 0.015 | K12: =(F12*(273.15+D12)/273.15)/(M12*N12) -> 7.7979575 | L12: MU3 | M12: =VLOOKUP(L12,allgemein!$B$3:$C$13,2,FALSE) -> 3 | N12: 40 | O12: FA703642 | P12: B-09_19
C13: " | G13: 1.843 | P13: B-07-75
C14: " | G14: 1.843 | P14: B-07-80
B15: 18E-0004Z | C15: " | D15: 25.7 | E15: 0.2 | F15: 850 | G15: 1.827 | H15: 5.483 | I15: 5.451 | J15: =IF(M15<>"",(H15-I15)/M15,"") -> 0.010666667 | K15: =(F15*(273.15+D15)/273.15)/(M15*N15) -> 7.7497864 | L15: MU3 | M15: =VLOOKUP(L15,allgemein!$B$3:$C$13,2,FALSE) -> 3 | N15: 40 | O15: " | P15: B-09_24
C16: " | G16: 1.824 | P16: B-07-86
C17: " | G17: 1.832 | P17: B-07-90
B18: 18E-0005Z | C18: " | D18: 24.5 | E18: 0 | F18: 855 | G18: 1.842 | H18: 5.529 | I18: 5.491 | J18: =IF(M18<>"",(H18-I18)/M18,"") -> 0.012666667 | K18: =(F18*(273.15+D18)/273.15)/(M18*N18) -> 7.7640719 | L18: MU3 | M18: =VLOOKUP(L18,allgemein!$B$3:$C$13,2,FALSE) -> 3 | N18: 40 | O18: " | P18: B-09_26
C19: " | G19: 1.842 | P19: B-07-94
C20: " | G20: 1.845 | P20: B-07-96
B21: 18E-0006Z | C21: " | D21: 27.1 | E21: 0.6 | F21: 568 | G21: 1.839 | H21: 3.68 | I21: 3.651 | J21: =IF(M21<>"",(H21-I21)/M21,"") -> 0.0145 | K21: =(F21*(273.15+D21)/273.15)/(M21*N21) -> 7.8044115 | L21: MU2 | M21: =VLOOKUP(L21,allgemein!$B$3:$C$13,2,FALSE) -> 2 | N21: 40 | O21: FA703836 | P21: B-09_17
C22: " | G22: 1.841 | P22: B-07-66
B23: 18E-0007Z | C23: " | D23: 27.2 | E23: 0.6 | F23: 568 | G23: 1.841 | H23: 3.687 | I23: 3.661 | J23: =IF(M23<>"",(H23-I23)/M23,"") -> 0.013 | K23: =(F23*(273.15+D23)/273.15)/(M23*N23) -> 7.8070108 | L23: MU2 | M23: =VLOOKUP(L23,allgemein!$B$3:$C$13,2,FALSE) -> 2 | N23: 40 | O23: " | P23: B-09_25
C24: " | G24: 1.846 | P24: B-07-93
B25: 18E-0008Z | C25: " | D25: 27.2 | E25: 0.4 | F25: 568 | G25: 1.828 | H25: 3.659 | I25: 3.633 | J25: =IF(M25<>"",(H25-I25)/M25,"") -> 0.013 | K25: =(F25*(273.15+D25)/273.15)/(M25*N25) -> 7.8070108 | L25: MU2 | M25: =VLOOKUP(L25,allgemein!$B$3:$C$13,2,FALSE) -> 2 | N25: 40 | O25: " | P25: B-09_28
C26: " | G26: 1.831 | P26: B-07-95
B27: 18E-0009Z | C27: " | D27: 27.1 | E27: 0.2 | F27: 568 | G27: 1.843 | H27: 3.692 | I27: 3.667 | J27: =IF(M27<>"",(H27-I27)/M27,"") -> 0.0125 | K27: =(F27*(273.15+D27)/273.15)/(M27*N27) -> 7.8044115 | L27: MU2 | M27: =VLOOKUP(L27,allgemein!$B$3:$C$13,2,FALSE) -> 2 | N27: 40 | O27: " | P27: B-09_29
C28: " | G28: 1.849 | P28: B-07-97
B29: 18E-0010Z | C29: FA702672 | D29: 24.6 | E29: 0.3 | F29: 178 | H29: 1.891 | I29: 1.877 | J29: =IF(M29<>"",(H29-I29)/M29,"") -> 0.014 | K29: =(F29*(273.15+D29)/273.15)/(M29*N29) -> 7.7612301 | L29: MI_V3 | M29: =VLOOKUP(L29,allgemein!$B$3:$C$13,2,FALSE) -> 1 | N29: 25 | O29: FA703560
B30: 18E-0011Z | C30: " | D30: 24.7 | E30: 0.4 | F30: 179 | H30: 1.891 | I30: 1.881 | J30: =IF(M30<>"",(H30-I30)/M30,"") -> 0.01 | K30: =(F30*(273.15+D30)/273.15)/(M30*N30) -> 7.8074538 | L30: MI_V3 | M30: =VLOOKUP(L30,allgemein!$B$3:$C$13,2,FALSE) -> 1 | N30: 25 | O30: "
B31: 18E-0012Z | C31: " | D31: 24.8 | E31: 0.4 | F31: 178 | H31: 1.88 | I31: 1.868 | J31: =IF(M31<>"",(H31-I31)/M31,"") -> 0.012 | K31: =(F31*(273.15+D31)/273.15)/(M31*N31) -> 7.7664433 | L31: MI_V3 | M31: =VLOOKUP(L31,allgemein!$B$3:$C$13,2,FALSE) -> 1 | N31: 25 | O31: "
B32: 18E-0013Z | C32: " | D32: 24.9 | E32: 0.3 | F32: 177 | H32: 1.88 | I32: 1.865 | J32: =IF(M32<>"",(H32-I32)/M32,"") -> 0.015 | K32: =(F32*(273.15+D32)/273.15)/(M32*N32) -> 7.7254036 | L32: MI_V3 | M32: =VLOOKUP(L32,allgemein!$B$3:$C$13,2,FALSE) -> 1 | N32: 25 | O32: "
B33: 18E-0014Z | C33: " | D33: 24.9 | E33: 0.3 | F33: 178 | H33: 1.878 | I33: 1.866 | J33: =IF(M33<>"",(H33-I33)/M33,"") -> 0.012 | K33: =(F33*(273.15+D33)/273.15)/(M33*N33) -> 7.76905 | L33: MI_V3 | M33: =VLOOKUP(L33,allgemein!$B$3:$C$13,2,FALSE) -> 1 | N33: 25 | O33: "
B34: 18E-0015Z | C34: " | D34: 25.2 | E34: 0.5 | F34: 177 | H34: 1.88 | I34: 1.87 | J34: =IF(M34<>"",(H34-I34)/M34,"") -> 0.01 | K34: =(F34*(273.15+D34)/273.15)/(M34*N34) -> 7.7331796 | L34: MI_V3 | M34: =VLOOKUP(L34,allgemein!$B$3:$C$13,2,FALSE) -> 1 | N34: 25 | O34: "
B35: 18E-0016Z | C35: " | D35: 25.3 | E35: 0.3 | F35: 177 | H35: 1.869 | I35: 1.858 | J35: =IF(M35<>"",(H35-I35)/M35,"") -> 0.011 | K35: =(F35*(273.15+D35)/273.15)/(M35*N35) -> 7.7357716 | L35: MI_V3 | M35: =VLOOKUP(L35,allgemein!$B$3:$C$13,2,FALSE) -> 1 | N35: 25 | O35: "
B36: 18E-0017Z | C36: " | D36: 25.5 | E36: 0.2 | F36: 177 | H36: 1.872 | I36: 1.861 | J36: =IF(M36<>"",(H36-I36)/M36,"") -> 0.011 | K36: =(F36*(273.15+D36)/273.15)/(M36*N36) -> 7.7409555 | L36: MI_V3 | M36: =VLOOKUP(L36,allgemein!$B$3:$C$13,2,FALSE) -> 1 | N36: 25 | O36: "
B37: 18E-0018Z | C37: " | D37: 24.6 | E37: 0.3 | F37: 177 | H37: 1.894 | I37: 1.883 | J37: =IF(M37<>"",(H37-I37)/M37,"") -> 0.011 | K37: =(F37*(273.15+D37)/273.15)/(M37*N37) -> 7.7176277 | L37: MI_V3 | M37: =VLOOKUP(L37,allgemein!$B$3:$C$13,2,FALSE) -> 1 | N37: 25 | O37: "
B38: 18E-0019Z | C38: FA702716 | D38: 24.6 | E38: 0.4 | F38: 178 | H38: 1.889 | I38: 1.877 | J38: =IF(M38<>"",(H38-I38)/M38,"") -> 0.012 | K38: =(F38*(273.15+D38)/273.15)/(M38*N38) -> 7.7612301 | L38: MI_V3 | M38: =VLOOKUP(L38,allgemein!$B$3:$C$13,2,FALSE) -> 1 | N38: 25 | O38: "
B39: 18E-0020Z | C39: " | D39: 24.6 | E39: 0.3 | F39: 178 | H39: 1.879 | I39: 1.866 | J39: =IF(M39<>"",(H39-I39)/M39,"") -> 0.013 | K39: =(F39*(273.15+D39)/273.15)/(M39*N39) -> 7.7612301 | L39: MI_V3 | M39: =VLOOKUP(L39,allgemein!$B$3:$C$13,2,FALSE) -> 1 | N39: 25 | O39: "
B40: 18E-0021Z | C40: " | D40: 24.6 | E40: 0.4 | F40: 177 | H40: 1.89 | I40: 1.873 | J40: =IF(M40<>"",(H40-I40)/M40,"") -> 0.017 | K40: =(F40*(273.15+D40)/273.15)/(M40*N40) -> 7.7176277 | L40: MI_V3 | M40: =VLOOKUP(L40,allgemein!$B$3:$C$13,2,FALSE) -> 1 | N40: 25 | O40: "
... B61: 18E-0042Z | C61: " | D61: 27.1 | E61: 0.5 | F61: 177 | H61: 1.852 | I61: 1.84 | J61: =IF(M61<>"",(H61-I61)/M61,"") -> 0.012 | K61: =(F61*(273.15+D61)/273.15)/(M61*N61) -> 7.7824272 | L61: MI_V3 | M61: =VLOOKUP(L61,allgemein!$B$3:$C$13,2,FALSE) -> 1 | N61: 25 | O61: "
B62: 18E-0043Z | C62: " | D62: 28.1 | E62: 0.6 | F62: 177 | H62: 1.837 | I62: 1.827 | J62: =IF(M62<>"",(H62-I62)/M62,"") -> 0.01 | K62: =(F62*(273.15+D62)/273.15)/(M62*N62) -> 7.8083471 | L62: MI_V3 | M62: =VLOOKUP(L62,allgemein!$B$3:$C$13,2,FALSE) -> 1 | N62: 25 | O62: " | Q62: Messung erfolgte bei Wassertemp. 40°
...

Sheet Jun
B3: Cell # | C3: Membran # ¦ Batch # | D3: Temp Gas / [°C] | E3: Temp Kat T1-T2 / [°C] | F3: Gasfluss / [sccm / min] | G3: Membrane V @ 13 bar/[V] | H3: Cell V @ 13 bar/[V] | I3: Cell V @ 0 bar [V] | J3: Voltage Diff. / [V] | K3: H2 Prod / [nmL/A] | L3: Typ | M3: Anzahl Layer | N3: Strom / [A] | O3: FA # | P3: Elektrode | Q3: Bemerkungen | R3: Visum | S3: Jahr: | T3: 2018
B4: 18F-0001Z | C4: FA703712 | D4: 27.4 | E4: 1 | F4: 570 | G4: 1.852 | H4: 3.699 | I4: 3.672 | J4: =IF(M4<>"",(H4-I4)/M4,"") -> 0.0135 | K4: =(F4*(273.15+D4)/273.15)/(M4*N4) -> 7.8397172 | L4: MU2 | M4: =VLOOKUP(L4,allgemein!$B$3:$C$13,2,FALSE) -> 2 | N4: 40 | O4: FA703836 | P4: B-09-41
C5: " | G5: 1.847 | P5: B-07-58
B6: 18F-0002Z | C6: " | D6: 27.1 | E6: 1.1 | F6: 569 | G6: 1.847 | H6: 3.701 | I6: 3.678 | J6: =IF(M6<>"",(H6-I6)/M6,"") -> 0.0115 | K6: =(F6*(273.15+D6)/273.15)/(M6*N6) -> 7.8181517 | L6: MU2 | M6: =VLOOKUP(L6,allgemein!$B$3:$C$13,2,FALSE) -> 2 | N6: 40 | O6: " | P6: B-09-49
C7: " | G7: 1.854 | P7: B-07-69
B8: 18F-0003Z | C8: " | D8: 26.2 | E8: 0.7 | F8: 564 | G8: 1.855 | H8: 3.709 | I8: 3.69 | J8: =IF(M8<>"",(H8-I8)/M8,"") -> 0.0095 | K8: =(F8*(273.15+D8)/273.15)/(M8*N8) -> 7.7262219 | L8: MU2 | M8: =VLOOKUP(L8,allgemein!$B$3:$C$13,2,FALSE) -> 2 | N8: 40 | O8: " | P8: B-09-42
C9: " | G9: 1.854 | P9: B-07-72
B10: 18F-0004Z | C10: " | D10: 26.8 | E10: 0.3 | F10: 569 | G10: 1.849 | H10: 3.693 | I10: 3.667 | J10: =IF(M10<>"",(H10-I10)/M10,"") -> 0.013 | K10: =(F10*(273.15+D10)/273.15)/(M10*N10) -> 7.81034 | L10: MU2 | M10: =VLOOKUP(L10,allgemein!$B$3:$C$13,2,FALSE) -> 2 | N10: 40 | O10: " | P10: B-09-43
C11: " | G11: 1.844 | P11: B-07-77
B12: 18F-0005Z | C12: " | D12: 26.3 | E12: 0.2 | F12: 568 | G12: 1.846 | H12: 3.699 | I12: 3.676 | J12: =IF(M12<>"",(H12-I12)/M12,"") -> 0.0115 | K12: =(F12*(273.15+D12)/273.15)/(M12*N12) -> 7.7836171 | L12: MU2 | M12: =VLOOKUP(L12,allgemein!$B$3:$C$13,2,FALSE) -> 2 | N12: 40 | O12: " | P12: B-09-44
C13: " | G13: 1.853 | P13: B-07-119
B14: 18F-0006Z-R | C14: " | D14: 27.1 | E14: 0.1 | F14: 285 | H14: 1.88 | I14: 1.868 | J14: =IF(M14<>"",(H14-I14)/M14,"") -> 0.012 | K14: =(F14*(273.15+D14)/273.15)/(M14*N14) -> 7.8318918 | L14: MA_V1 | M14: =VLOOKUP(L14,allgemein!$B$3:$C$13,2,FALSE) -> 1 | N14: 40 | O14: FA704146 | Q14: Fa. Schmid. Neuh.
B15: 18F-0007Z-R | C15: " | D15: 27.1 | E15: 0.1 | F15: 284 | H15: 1.889 | I15: 1.877 | J15: =IF(M15<>"",(H15-I15)/M15,"") -> 0.012 | K15: =(F15*(273.15+D15)/273.15)/(M15*N15) -> 7.8044115 | L15: MA_V1 | M15: =VLOOKUP(L15,allgemein!$B$3:$C$13,2,FALSE) -> 1 | N15: 40 | O15: "
B16: 18F-0008Z-R | C16: " | D16: 27.1 | E16: 0.1 | F16: 284 | H16: 1.892 | I16: 1.88 | J16: =IF(M16<>"",(H16-I16)/M16,"") -> 0.012 | K16: =(F16*(273.15+D16)/273.15)/(M16*N16) -> 7.8044115 | L16: MA_V1 | M16: =VLOOKUP(L16,allgemein!$B$3:$C$13,2,FALSE) -> 1 | N16: 40 | O16: "
B17: 18F-0009Z-R | C17: " | D17: 27.1 | E17: 0 | F17: 285 | H17: 1.885 | I17: 1.873 | J17: =IF(M17<>"",(H17-I17)/M17,"") -> 0.012 | K17: =(F17*(273.15+D17)/273.15)/(M17*N17) -> 7.8318918 | L17: MA_V1 | M17: =VLOOKUP(L17,allgemein!$B$3:$C$13,2,FALSE) -> 1 | N17: 40 | O17: "
B18: 18F-0010Z-R | C18: FA703870 | D18: 27.2 | E18: 0 | F18: 284 | H18: 1.873 | I18: 1.86 | J18: =IF(M18<>"",(H18-I18)/M18,"") -> 0.013 | K18: =(F18*(273.15+D18)/273.15)/(M18*N18) -> 7.8070108 | L18: MA_V1 | M18: =VLOOKUP(L18,allgemein!$B$3:$C$13,2,FALSE) -> 1 | N18: 40 | O18: "
B19: 18F-0011Z-R | C19: " | D19: 27.2 | E19: 0 | F19: 284 | H19: 1.869 | I19: 1.855 | J19: =IF(M19<>"",(H19-I19)/M19,"") -> 0.014 | K19: =(F19*(273.15+D19)/273.15)/(M19*N19) -> 7.8070108 | L19: MA_V1 | M19: =VLOOKUP(L19,allgemein!$B$3:$C$13,2,FALSE) -> 1 | N19: 40 | Q19: Anfrage Vroni
B20: 18F-0012Z-R | C20: " | D20: 27.2 | E20: 0 | F20: 282 | H20: 1.877 | I20: 1.864 | J20: =IF(M20<>"",(H20-I20)/M20,"") -> 0.013 | K20: =(F20*(273.15+D20)/273.15)/(M20*N20) -> 7.7520319 | L20: MA_V2 | M20: =VLOOKUP(L20,allgemein!$B$3:$C$13,2,FALSE) -> 1 | N20: 40 | Q20: Fa. Schmid. Neuh.
B21: 18F-0013Z | C21: " | D21: 26.9 | E21: 1.2 | F21: 856 | G21: 1.837 | H21: 5.532 | I21: 5.491 | J21: =IF(M21<>"",(H21-I21)/M21,"") -> 0.013666667 | K21: =(F21*(273.15+D21)/273.15)/(M21*N21) -> 7.8358289 | L21: MU3 | M21: =VLOOKUP(L21,allgemein!$B$3:$C$13,2,FALSE) -> 3 | N21: 40 | O21: FA703642 | P21: B-09-36
C22: " | G22: 1.843 | P22: B-07-55
C23: " | G23: 1.852 | P23: B-07-130
B24: 18F-0014Z | C24: " | D24: 26.4 | E24: 1.1 | F24: 854 | G24: 1.847 | H24: 5.529 | I24: 5.486 | J24: =IF(M24<>"",(H24-I24)/M24,"") -> 0.014333333 | K24: =(F24*(273.15+D24)/273.15)/(M24*N24) -> 7.8044939 | L24: MU3 | M24: =VLOOKUP(L24,allgemein!$B$3:$C$13,2,FALSE) -> 3 | N24: 40 | O24: " | P24: B-09-38
C25: " | G25: 1.841 | P25: B-07-133
C26: " | G26: 1.841 | P26: B-07-144
B27: 18F-0015Z | C27: " | D27: 27.7 | E27: 1.1 | F27: 856 | G27: 1.816 | H27: 5.467 | I27: 5.424 | J27: =IF(M27<>"",(H27-I27)/M27,"") -> 0.014333333 | K27: =(F27*(273.15+D27)/273.15)/(M27*N27) -> 7.856721 | L27: MU3 | M27: =VLOOKUP(L27,allgemein!$B$3:$C$13,2,FALSE) -> 3 | N27: 40 | O27: " | P27: B-09-39
C28: " | G28: 1.826 | P28: B-07-152
C29: " | G29: 1.825 | P29: B-07-155
B30: 18F-0016Z | C30: " | D30: 25.9 | E30: 0.6 | F30: 284 | H30: 1.862 | I30: 1.849 | J30: =IF(M30<>"",(H30-I30)/M30,"") -> 0.013 | K30: =(F30*(273.15+D30)/273.15)/(M30*N30) -> 7.7732198 | L30: MU1 | M30: =VLOOKUP(L30,allgemein!$B$3:$C$13,2,FALSE) -> 1 | N30: 40 | O30: FA703756 | P30: B-09-37
B31: 18F-0017Z | C31: " | D31: 26.2 | E31: 0.9 | F31: 285 | H31: 1.836 | I31: 1.822 | J31: =IF(M31<>"",(H31-I31)/M31,"") -> 0.014 | K31: =(F31*(273.15+D31)/273.15)/(M31*N31) -> 7.8084157 | L31: MU1 | M31: =VLOOKUP(L31,allgemein!$B$3:$C$13,2,FALSE) -> 1 | N31: 40 | O31: " | P31: B-09-40
B32: 18F-0018Z | C32: " | D32: 26.4 | E32: 0.7 | F32: 283 | H32: 1.866 | I32: 1.855 | J32: =IF(M32<>"",(H32-I32)/M32,"") -> 0.011 | K32: =(F32*(273.15+D32)/273.15)/(M32*N32) -> 7.7588001 | L32: MU1 | M32: =VLOOKUP(L32,allgemein!$B$3:$C$13,2,FALSE) -> 1 | N32: 40 | O32: " | P32: B-09-45
B33: 18F-0019Z | C33: " | D33: 26.4 | E33: 0.4 | F33: 284 | H33: 1.845 | I33: 1.828 | J33: =IF(M33<>"",(H33-I33)/M33,"") -> 0.017 | K33: =(F33*(273.15+D33)/273.15)/(M33*N33) -> 7.7862164 | L33: MU1 | M33: =VLOOKUP(L33,allgemein!$B$3:$C$13,2,FALSE) -> 1 | N33: 40 | O33: " | P33: B-09-46
B34: 18F-0020Z | C34: " | D34: 26.5 | E34: 0.4 | F34: 284 | H34: 1.871 | I34: 1.857 | J34: =IF(M34<>"",(H34-I34)/M34,"") -> 0.014 | K34: =(F34*(273.15+D34)/273.15)/(M34*N34) -> 7.7888157 | L34: MU1 | M34: =VLOOKUP(L34,allgemein!$B$3:$C$13,2,FALSE) -> 1 | N34: 40 | O34: " | P34: B-09-48
B35: 18F-0021Z | C35: FA703431 | D35: 25 | E35: 0.3 | F35: 178 | H35: 1.881 | I35: 1.87 | J35: =IF(M35<>"",(H35-I35)/M35,"") -> 0.011 | K35: =(F35*(273.15+D35)/273.15)/(M35*N35) -> 7.7716566 | L35: MI_V3 | M35: =VLOOKUP(L35,allgemein!$B$3:$C$13,2,FALSE) -> 1 | N35: 25 | O35: FA703970
B36: 18F-0022Z | C36: " | D36: 25.1 | E36: 0.3 | F36: 177 | H36: 1.88 | I36: 1.869 | J36: =IF(M36<>"",(H36-I36)/M36,"") -> 0.011 | K36: =(F36*(273.15+D36)/273.15)/(M36*N36) -> 7.7305876 | L36: MI_V3 | M36: =VLOOKUP(L36,allgemein!$B$3:$C$13,2,FALSE) -> 1 | N36: 25 | O36: "
B37: 18F-0023Z | C37: " | D37: 25.2 | E37: 0.4 | F37: 177 | H37: 1.884 | I37: 1.873 | J37: =IF(M37<>"",(H37-I37)/M37,"") -> 0.011 | K37: =(F37*(273.15+D37)/273.15)/(M37*N37) -> 7.7331796 | L37: MI_V3 | M37: =VLOOKUP(L37,allgemein!$B$3:$C$13,2,FALSE) -> 1 | N37: 25 | O37: "
B38: 18F-0024Z | C38: " | D38: 25.2 | E38: 0.8 | F38: 177 | H38: 1.888 | I38: 1.879 | J38: =IF(M38<>"",(H38-I38)/M38,"") -> 0.009 | K38: =(F38*(273.15+D38)/273.15)/(M38*N38) -> 7.7331796 | L38: MI_V3 | M38: =VLOOKUP(L38,allgemein!$B$3:$C$13,2,FALSE) -> 1 | N38: 25 | O38: "
A39: 25.3 | B39: 18F-0025Z | C39: " | D39: 25.3 | E39: 0.3 | F39: 177 | H39: 1.859 | I39: 1.845 | J39: =IF(M39<>"",(H39-I39)/M39,"") -> 0.014 | K39: =(F39*(273.15+D39)/273.15)/(M39*N39) -> 7.7357716 | L39: MI_V3 | M39: =VLOOKUP(L39,allgemein!$B$3:$C$13,2,FALSE) -> 1 | N39: 25 | O39: "
B40: 18F-0026Z | C40: " | D40: 25.5 | E40: 0.3 | F40: 178 | H40: 1.875 | I40: 1.862 | J40: =IF(M40<>"",(H40-I40)/M40,"") -> 0.013 | K40: =(F40*(273.15+D40)/273.15)/(M40*N40) -> 7.7846897 | L40: MI_V3 | M40: =VLOOKUP(L40,allgemein!$B$3:$C$13,2,FALSE) -> 1 | N40: 25 | O40: "
B41: 18F-0027Z | C41: " | D41: 25.6 | E41: 0.3 | F41: 178 | H41: 1.874 | I41: 1.862 | J41: =IF(M41<>"",(H41-I41)/M41,"") -> 0.012 | K41: =(F41*(273.15+D41)/273.15)/(M41*N41) -> 7.7872964 | L41: MI_V3 | M41: =VLOOKUP(L41,allgemein!$B$3:$C$13,2,FALSE) -> 1 | N41: 25 | O41: "
B42: 18F-0028Z | C42: " | D42: 25.8 | E42: 0.3 | F42: 177 | H42: 1.865 | I42: 1.855 | J42: =IF(M42<>"",(H42-I42)/M42,"") -> 0.01 | K42: =(F42*(273.15+D42)/273.15)/(M42*N42) -> 7.7487315 | L42: MI_V3 | M42: =VLOOKUP(L42,allgemein!$B$3:$C$13,2,FALSE) -> 1 | N42: 25 | O42: "
...

Sheet Jul
B3: Cell # | C3: Membran # ¦ Batch # | D3: Temp Gas / [°C] | E3: Temp Kat T1-T2 / [°C] | F3: Gasfluss / [sccm / min] | G3: Membrane V @ 13 bar/[V] | H3: Cell V @ 13 bar/[V] | I3: Cell V @ 0 bar [V] | J3: Voltage Diff. / [V] | K3: H2 Prod / [nmL/A] | L3: Typ | M3: Anzahl Layer | N3: Strom / [A] | O3: FA # | P3: Elektrode | R3: Bemerkungen | S3: Visum | T3: Jahr: | U3: 2018
B4: 18G-0001Z | C4: 702776 | D4: 26.6 | E4: 0.3 | F4: 178 | H4: 1.879 | I4: 1.868 | J4: =IF(M4<>"",(H4-I4)/M4,"") -> 0.011 | K4: =(F4*(273.15+D4)/273.15)/(M4*N4) -> 7.8133626 | L4: MI_V3 | M4: =VLOOKUP(L4,allgemein!$B$3:$C$13,2,FALSE) -> 1 | N4: 25 | O4: 704065
B5: 18G-0002Z | C5: " | D5: 26.7 | E5: 0.1 | F5: 178 | H5: 1.871 | I5: 1.856 | J5: =IF(M5<>"",(H5-I5)/M5,"") -> 0.015 | K5: =(F5*(273.15+D5)/273.15)/(M5*N5) -> 7.8159692 | L5: MI_V3 | M5: =VLOOKUP(L5,allgemein!$B$3:$C$13,2,FALSE) -> 1 | N5: 25 | O5: "
B6: 18G-0003Z | C6: " | D6: 26.8 | E6: 0.4 | F6: 178 | H6: 1.876 | I6: 1.864 | J6: =IF(M6<>"",(H6-I6)/M6,"") -> 0.012 | K6: =(F6*(273.15+D6)/273.15)/(M6*N6) -> 7.8185759 | L6: MI_V3 | M6: =VLOOKUP(L6,allgemein!$B$3:$C$13,2,FALSE) -> 1 | N6: 25 | O6: "
B7: 18G-0004Z | C7: " | D7: 26.8 | E7: 0.3 | F7: 178 | H7: 1.886 | I7: 1.874 | J7: =IF(M7<>"",(H7-I7)/M7,"") -> 0.012 | K7: =(F7*(273.15+D7)/273.15)/(M7*N7) -> 7.8185759 | L7: MI_V3 | M7: =VLOOKUP(L7,allgemein!$B$3:$C$13,2,FALSE) -> 1 | N7: 25 | O7: "
B8: 18G-0005Z | C8: " | D8: 26.9 | E8: 0.4 | F8: 178 | H8: 1.886 | I8: 1.875 | J8: =IF(M8<>"",(H8-I8)/M8,"") -> 0.011 | K8: =(F8*(273.15+D8)/273.15)/(M8*N8) -> 7.8211825 | L8: MI_V3 | M8: =VLOOKUP(L8,allgemein!$B$3:$C$13,2,FALSE) -> 1 | N8: 25 | O8: "
B9: 18G-0006Z | C9: " | D9: 27.1 | E9: 0.2 | F9: 178 | H9: 1.875 | I9: 1.862 | J9: =IF(M9<>"",(H9-I9)/M9,"") -> 0.013 | K9: =(F9*(273.15+D9)/273.15)/(M9*N9) -> 7.8263958 | L9: MI_V3 | M9: =VLOOKUP(L9,allgemein!$B$3:$C$13,2,FALSE) -> 1 | N9: 25 | O9: "
B10: 18G-0007Z | C10: " | D10: 27.2 | E10: 0.2 | F10: 177 | H10: 1.877 | I10: 1.865 | J10: =IF(M10<>"",(H10-I10)/M10,"") -> 0.012 | K10: =(F10*(273.15+D10)/273.15)/(M10*N10) -> 7.7850192 | L10: MI_V3 | M10: =VLOOKUP(L10,allgemein!$B$3:$C$13,2,FALSE) -> 1 | N10: 25 | O10: "
B11: 18G-0008Z | C11: 702777 | D11: 27.5 | E11: 0 | F11: 178 | H11: 1.869 | I11: 1.855 | J11: =IF(M11<>"",(H11-I11)/M11,"") -> 0.014 | K11: =(F11*(273.15+D11)/273.15)/(M11*N11) -> 7.8368223 | L11: MI_V3 | M11: =VLOOKUP(L11,allgemein!$B$3:$C$13,2,FALSE) -> 1 | N11: 25 | O11: "
B12: 18G-0009Z | C12: " | D12: 25.9 | E12: 0.3 | F12: 178 | H12: 1.877 | I12: 1.864 | J12: =IF(M12<>"",(H12-I12)/M12,"") -> 0.013 | K12: =(F12*(273.15+D12)/273.15)/(M12*N12) -> 7.7951162 | L12: MI_V3 | M12: =VLOOKUP(L12,allgemein!$B$3:$C$13,2,FALSE) -> 1 | N12: 25 | O12: "
B13: 18G-0010Z | C13: " | D13: 25.9 | E13: 0.4 | F13: 178 | H13: 1.873 | I13: 1.86 | J13: =IF(M13<>"",(H13-I13)/M13,"") -> 0.013 | K13: =(F13*(273.15+D13)/273.15)/(M13*N13) -> 7.7951162 | L13: MI_V3 | M13: =VLOOKUP(L13,allgemein!$B$3:$C$13,2,FALSE) -> 1 | N13: 25 | O13: "
B14: 18G-0011Z | C14: " | D14: 25.8 | E14: 0.7 | F14: 177 | H14: 1.88 | I14: 1.87 | J14: =IF(M14<>"",(H14-I14)/M14,"") -> 0.01 | K14: =(F14*(273.15+D14)/273.15)/(M14*N14) -> 7.7487315 | L14: MI_V3 | M14: =VLOOKUP(L14,allgemein!$B$3:$C$13,2,FALSE) -> 1 | N14: 25 | O14: "
B15: 18G-0012Z | C15: " | D15: 25.8 | E15: 0.2 | F15: 178 | H15: 1.86 | I15: 1.847 | J15: =IF(M15<>"",(H15-I15)/M15,"") -> 0.013 | K15: =(F15*(273.15+D15)/273.15)/(M15*N15) -> 7.7925096 | L15: MI_V3 | M15: =VLOOKUP(L15,allgemein!$B$3:$C$13,2,FALSE) -> 1 | N15: 25 | O15: "
B16: 18G-0013Z | C16: " | D16: 25.8 | E16: 0.5 | F16: 177 | H16: 1.862 | I16: 1.851 | J16: =IF(M16<>"",(H16-I16)/M16,"") -> 0.011 | K16: =(F16*(273.15+D16)/273.15)/(M16*N16) -> 7.7487315 | L16: MI_V3 | M16: =VLOOKUP(L16,allgemein!$B$3:$C$13,2,FALSE) -> 1 | N16: 25 | O16: "
B17: 18G-0014Z | C17: " | D17: 25.8 | E17: 0.3 | F17: 177 | H17: 1.867 | I17: 1.855 | J17: =IF(M17<>"",(H17-I17)/M17,"") -> 0.012 | K17: =(F17*(273.15+D17)/273.15)/(M17*N17) -> 7.7487315 | L17: MI_V3 | M17: =VLOOKUP(L17,allgemein!$B$3:$C$13,2,FALSE) -> 1 | N17: 25 | O17: "
B18: 18G-0015Z | C18: " | D18: 25.7 | E18: 0.2 | F18: 177 | H18: 1.879 | I18: 1.864 | J18: =IF(M18<>"",(H18-I18)/M18,"") -> 0.015 | K18: =(F18*(273.15+D18)/273.15)/(M18*N18) -> 7.7461395 | L18: MI_V3 | M18: =VLOOKUP(L18,allgemein!$B$3:$C$13,2,FALSE) -> 1 | N18: 25 | O18: "
B19: 18G-0016Z | C19: " | D19: 25.6 | E19: 0.2 | F19: 178 | H19: 1.872 | I19: 1.859 | J19: =IF(M19<>"",(H19-I19)/M19,"") -> 0.013 | K19: =(F19*(273.15+D19)/273.15)/(M19*N19) -> 7.7872964 | L19: MI_V3 | M19: =VLOOKUP(L19,allgemein!$B$3:$C$13,2,FALSE) -> 1 | N19: 25 | O19: "
B22: 18G-0017Z-R | C22: FA703871 | D22: 26.1 | E22: 14.8 | F22: 276 | H22: 1.898 | I22: 1.889 | J22: =IF(M22<>"",(H22-I22)/M22,"") -> 0.009 | K22: =(F22*(273.15+D22)/273.15)/(M22*N22) -> 7.5593081 | L22: SP-H2 | M22: =VLOOKUP(L22,allgemein!$B$3:$C$13,2,FALSE) -> 1 | N22: 40 | O22: FA704194 | R22: Messung vor Spülen
C23: " | D23: 26.8 | E23: 0.8 | F23: 277 | H23: 1.911 | I23: 1.903 | J23: =IF(M23<>"",(H23-I23)/M23,"") -> 0.008 | K23: =(F23*(273.15+D23)/273.15)/(M23*N23) -> 7.6044435 | L23: SP-H2 | M23: =VLOOKUP(L23,allgemein!$B$3:$C$13,2,FALSE) -> 1 | N23: 40 | O23: " | R23: Messung nach Spülen
B24: Test: Membrane mit Sprühanlage MembranBatch FA 704158/ 26.06.18; 03.07.18
C25: Mem. Nr
B26: 18G-0018Z-R | C26: 4 | D26: 26.5 | E26: 0.5 | F26: 278 | H26: 1.923 | I26: 1.909 | J26: =IF(M26<>"",(H26-I26)/M26,"") -> 0.014 | K26: =(F26*(273.15+D26)/273.15)/(M26*N26) -> 7.6242632 | L26: SP-H2 | M26: =VLOOKUP(L26,allgemein!$B$3:$C$13,2,FALSE) -> 1 | N26: 40 | O26: "
B27: 18G-0019Z-R | C27: 5 | D27: 26.4 | E27: 0.7 | F27: 278 | H27: 1.946 | I27: 1.933 | J27: =IF(M27<>"",(H27-I27)/M27,"") -> 0.013 | K27: =(F27*(273.15+D27)/273.15)/(M27*N27) -> 7.6217188 | L27: SP-H2 | M27: =VLOOKUP(L27,allgemein!$B$3:$C$13,2,FALSE) -> 1 | N27: 40 | O27: "
B28: 18G-0020Z | C28: 1 | D28: 27.2 | E28: 0.6 | F28: 283 | H28: 1.856 | I28: 1.842 | J28: =IF(M28<>"",(H28-I28)/M28,"") -> 0.014 | K28: =(F28*(273.15+D28)/273.15)/(M28*N28) -> 7.7795213 | L28: MU1 | M28: =VLOOKUP(L28,allgemein!$B$3:$C$13,2,FALSE) -> 1 | N28: 40 | O28: FA704160 | P28: B-09 2 20
B29: 18G-0021Z | C29: 2 | D29: 27.1 | E29: 0.5 | F29: 284 | H29: 1.861 | I29: 1.843 | J29: =IF(M29<>"",(H29-I29)/M29,"") -> 0.018 | K29: =(F29*(273.15+D29)/273.15)/(M29*N29) -> 7.8044115 | L29: MU1 | M29: =VLOOKUP(L29,allgemein!$B$3:$C$13,2,FALSE) -> 1 | N29: 40 | O29: " | P29: B-09 2 47
B30: 18G-0022Z | C30: 3 | D30: 27 | E30: 0.2 | F30: 284 | H30: 1.87 | I30: 1.835 | J30: =IF(M30<>"",(H30-I30)/M30,"") -> 0.035 | K30: =(F30*(273.15+D30)/273.15)/(M30*N30) -> 7.8018122 | L30: MU1 | M30: =VLOOKUP(L30,allgemein!$B$3:$C$13,2,FALSE) -> 1 | N30: 40 | O30: " | P30: B-09 2 49
B32: 18G-0020Z(mit 18G-0022Z OElectr) | C32: 1 | H32: 1.865 | I32: 1.852 | J32: =IF(M32<>"",(H32-I32)/M32,"") -> 0.013 | K32: =(F32*(273.15+D32)/273.15)/(M32*N32) -> 0 | L32: MU1 | M32: =VLOOKUP(L32,allgemein!$B$3:$C$13,2,FALSE) -> 1 | N32: 40 | O32: "
B33: 18G-0022Z(mit 18G-0020Z OElectr) | C33: 3 | H33: 1.875 | I33: 1.835 | J33: =IF(M33<>"",(H33-I33)/M33,"") -> 0.04 | K33: =(F33*(273.15+D33)/273.15)/(M33*N33) -> 0 | L33: MU1 | M33: =VLOOKUP(L33,allgemein!$B$3:$C$13,2,FALSE) -> 1 | N33: 40 | O33: "
B35: 18G-0020Z | C35: 3 | D35: (incl FD) | H35: 1.906 | I35: 1.847 | J35: =IF(M35<>"",(H35-I35)/M35,"") -> 0.059 | L35: MU1 | M35: =VLOOKUP(L35,allgemein!$B$3:$C$13,2,FALSE) -> 1 | N35: 40 | O35: "
C36: 3 | D36: (incl FD) | H36: 1.903 | I36: 1.845 | J36: =IF(M36<>"",(H36-I36)/M36,"") -> 0.058 | L36: MU1 | M36: =VLOOKUP(L36,allgemein!$B$3:$C$13,2,FALSE) -> 1 | N36: 40
B37: 18G-0022Z | C37: 1 | D37: (incl FD) | H37: 1.865 | I37: 1.852 | J37: =IF(M37<>"",(H37-I37)/M37,"") -> 0.013 | L37: MU1 | M37: =VLOOKUP(L37,allgemein!$B$3:$C$13,2,FALSE) -> 1 | N37: 40 | O37: "
B39: 18G-0020Z | C39: 1 | H39: 1.892 | I39: 1.872 | J39: =IF(M39<>"",(H39-I39)/M39,"") -> 0.02 | K39: =(F39*(273.15+D39)/273.15)/(M39*N39) -> 0 | L39: MU1 | M39: =VLOOKUP(L39,allgemein!$B$3:$C$13,2,FALSE) -> 1 | N39: 40 | O39: "
B40: 18G-0022Z | C40: 3 | H40: 1.881 | I40: 1.859 | J40: =IF(M40<>"",(H40-I40)/M40,"") -> 0.022 | K40: =(F40*(273.15+D40)/273.15)/(M40*N40) -> 0 | L40: MU1 | M40: =VLOOKUP(L40,allgemein!$B$3:$C$13,2,FALSE) -> 1 | N40: 40 | O40: "
C41: 3 | H41: 1.882 | I41: 1.86 | J41: =IF(M41<>"",(H41-I41)/M41,"") -> 0.022 | K41: =(F41*(273.15+D41)/273.15)/(M41*N41) -> 0 | L41: MU1 | M41: =VLOOKUP(L41,allgemein!$B$3:$C$13,2,FALSE) -> 1 | N41: 40
B42: 18G-0020Z | C42: 1 | H42: 1.879 | I42: 1.859 | J42: =IF(M42<>"",(H42-I42)/M42,"") -> 0.02 | K42: =(F42*(273.15+D42)/273.15)/(M42*N42) -> 0 | L42: MU1 | M42: =VLOOKUP(L42,allgemein!$B$3:$C$13,2,FALSE) -> 1 | N42: 40 | O42: "
C43: 7 | D43: 26.2 | E43: 5 | F43: 283 | H43: 1.868 | I43: 1.834 | J43: =IF(M43<>"",(H43-I43)/M43,"") -> 0.034 | K43: =(F43*(273.15+D43)/273.15)/(M43*N43) -> 7.7536198 | L43: MU1 | M43: =VLOOKUP(L43,allgemein!$B$3:$C$13,2,FALSE) -> 1 | N43: 40 | R43: Messung vor Spülen
C44: " | D44: 23.9 | E44: 0 | F44: 285 | H44: 1.857 | I44: 1.833 | J44: =IF(M44<>"",(H44-I44)/M44,"") -> 0.024 | K44: =(F44*(273.15+D44)/273.15)/(M44*N44) -> 7.7484212 | L44: MU1 | M44: =VLOOKUP(L44,allgemein!$B$3:$C$13,2,FALSE) -> 1 | N44: 40 | R44: Messung nach Spülen
C45: " | D45: 23.7 | E45: 0 | F45: 285 | H45: 1.879 | I45: 1.844 | J45: =IF(M45<>"",(H45-I45)/M45,"") -> 0.035 | K45: =(F45*(273.15+D45)/273.15)/(M45*N45) -> 7.7432043 | L45: MU1 | M45: =VLOOKUP(L45,allgemein!$B$3:$C$13,2,FALSE) -> 1 | N45: 40 | Q45: Nachprüfung nach 5 Tg
C46: " | D46: 24 | E46: 0 | F46: 285 | H46: 1.869 | I46: 1.849 | J46: =IF(M46<>"",(H46-I46)/M46,"") -> 0.02 | K46: =(F46*(273.15+D46)/273.15)/(M46*N46) -> 7.7510297 | L46: MU1 | M46: =VLOOKUP(L46,allgemein!$B$3:$C$13,2,FALSE) -> 1 | N46: 40 | Q46: Vlies mit 2T verpresst
B47: 18G-0021Z | C47: 8 | D47: 26.1 | E47: 4.9 | F47: 283 | H47: 1.873 | I47: 1.847 | J47: =IF(M47<>"",(H47-I47)/M47,"") -> 0.026 | K47: =(F47*(273.15+D47)/273.15)/(M47*N47) -> 7.7510297 | L47: MU1 | M47: =VLOOKUP(L47,allgemein!$B$3:$C$13,2,FALSE) -> 1 | N47: 40 | O47: " | R47: Messung vor Spülen
...

Sheet Aug
B3: Cell # | C3: Membran # ¦ Batch FA | D3: Temp Gas / [°C] | E3: Temp Kat T1-T2 / [°C] | F3: Gasfluss / [sccm / min] | G3: Membrane V @ 13 bar/[V] | H3: Cell V @ 13 bar/[V] | I3: Cell V @ 0 bar [V] | J3: Voltage Diff. / [V] | K3: H2 Prod / [nmL/A] | L3: Typ | M3: Anzahl Layer | N3: Strom / [A] | O3: FA # | P3: Elektrode | R3: Bemerkungen | S3: Visum | T3: Jahr: | U3: 2018
B4: 18H-0001Z | C4: 704268 | D4: 27.4 | E4: 0 | F4: 178 | H4: 1.869 | I4: 1.851 | J4: =IF(M4<>"",(H4-I4)/M4,"") -> 0.018 | K4: =(F4*(273.15+D4)/273.15)/(M4*N4) -> 7.8342156 | L4: MI_V3 | M4: =VLOOKUP(L4,allgemein!$B$3:$C$13,2,FALSE) -> 1 | N4: 25 | O4: FA704065 | Q4: Besprüh. Varante3
B5: 18H-0002Z | C5: " | D5: 27.4 | E5: 0.1 | F5: 177 | H5: 1.854 | I5: 1.839 | J5: =IF(M5<>"",(H5-I5)/M5,"") -> 0.015 | K5: =(F5*(273.15+D5)/273.15)/(M5*N5) -> 7.7902032 | L5: MI_V3 | M5: =VLOOKUP(L5,allgemein!$B$3:$C$13,2,FALSE) -> 1 | N5: 25 | O5: " | Q5: "
B6: 18H-0003Z | C6: " | D6: 27.4 | E6: 0.1 | F6: 178 | H6: 1.848 | I6: 1.832 | J6: =IF(M6<>"",(H6-I6)/M6,"") -> 0.016 | K6: =(F6*(273.15+D6)/273.15)/(M6*N6) -> 7.8342156 | L6: MI_V3 | M6: =VLOOKUP(L6,allgemein!$B$3:$C$13,2,FALSE) -> 1 | N6: 25 | O6: " | Q6: "
B7: 18H-0004Z | C7: 702777 | D7: 27.4 | E7: 0.3 | F7: 178 | H7: 1.88 | I7: 1.868 | J7: =IF(M7<>"",(H7-I7)/M7,"") -> 0.012 | K7: =(F7*(273.15+D7)/273.15)/(M7*N7) -> 7.8342156 | L7: MI_V3 | M7: =VLOOKUP(L7,allgemein!$B$3:$C$13,2,FALSE) -> 1 | N7: 25 | O7: "
B8: 18H-0005Z | C8: " | D8: 27.4 | E8: 0.2 | F8: 178 | H8: 1.884 | I8: 1.869 | J8: =IF(M8<>"",(H8-I8)/M8,"") -> 0.015 | K8: =(F8*(273.15+D8)/273.15)/(M8*N8) -> 7.8342156 | L8: MI_V3 | M8: =VLOOKUP(L8,allgemein!$B$3:$C$13,2,FALSE) -> 1 | N8: 25 | O8: "
B9: 18H-0006Z | C9: " | D9: 27.4 | E9: 0.2 | F9: 177 | H9: 1.89 | I9: 1.877 | J9: =IF(M9<>"",(H9-I9)/M9,"") -> 0.013 | K9: =(F9*(273.15+D9)/273.15)/(M9*N9) -> 7.7902032 | L9: MI_V3 | M9: =VLOOKUP(L9,allgemein!$B$3:$C$13,2,FALSE) -> 1 | N9: 25 | O9: FA702368
B10: 18H-0007Z | C10: " | D10: 27.4 | E10: 0.1 | F10: 177 | H10: 1.885 | I10: 1.869 | J10: =IF(M10<>"",(H10-I10)/M10,"") -> 0.016 | K10: =(F10*(273.15+D10)/273.15)/(M10*N10) -> 7.7902032 | L10: MI_V3 | M10: =VLOOKUP(L10,allgemein!$B$3:$C$13,2,FALSE) -> 1 | N10: 25 | O10: "
B11: 18H-0008Z | C11: " | D11: 27.2 | E11: 0.1 | F11: 177 | H11: 1.888 | I11: 1.875 | J11: =IF(M11<>"",(H11-I11)/M11,"") -> 0.013 | K11: =(F11*(273.15+D11)/273.15)/(M11*N11) -> 7.7850192 | L11: MI_V3 | M11: =VLOOKUP(L11,allgemein!$B$3:$C$13,2,FALSE) -> 1 | N11: 25 | O11: "
B12: 18H-0009Z | C12: " | D12: 27 | E12: 0.2 | F12: 178 | H12: 1.885 | I12: 1.873 | J12: =IF(M12<>"",(H12-I12)/M12,"") -> 0.012 | K12: =(F12*(273.15+D12)/273.15)/(M12*N12) -> 7.8237891 | L12: MI_V3 | M12: =VLOOKUP(L12,allgemein!$B$3:$C$13,2,FALSE) -> 1 | N12: 25 | O12: "
