Workbook

Sheet Jan
B3: Cell # | C3: Membran Batch FA | D3: Temp Gas / [°C] | E3: Temp Kat T1-T2 / [°C] | F3: Gasfluss / [sccm / min] | G3: Membrane V @ 13 bar/[V] | H3: Cell V @ 13 bar/[V] | I3: Cell V @ 0 bar [V] | J3: Voltage Diff. / [V] | K3: H2 Prod / [nmL/A] | L3: Typ | M3: Anzahl Layer | N3: Strom / [A] | O3: FA # | P3: Bemerkungen | R3: Bemerkungen | S3: Visum | T3: Jahr: | U3: 2019
B4: 19A-0001Z | C4: 704932 | D4: 26 | E4: 0 | F4: 861 | G4: 1.839 | H4: 5.515 | I4: 5.462 | J4: =IF(M4<>"",(H4-I4)/M4,"") -> 0.017666667 | K4: =(F4*(273.15+D4)/273.15)/(M4*N4) -> 7.8579581 | L4: MU3 | M4: =VLOOKUP(L4,allgemein!$B$3:$C$13,2,FALSE) -> 3 | N4: 40 | O4: FA496318
C5: " | G5: 1.838
C6: " | G6: 1.838
B7: 19A-0002Z | C7: 704933 | D7: 25.6 | E7: 0 | F7: 861 | G7: 1.845 | H7: 5.523 | I7: 5.465 | J7: =IF(M7<>"",(H7-I7)/M7,"") -> 0.019333333 | K7: =(F7*(273.15+D7)/273.15)/(M7*N7) -> 7.847451 | L7: MU3 | M7: =VLOOKUP(L7,allgemein!$B$3:$C$13,2,FALSE) -> 3 | N7: 40 | O7: "
C8: " | G8: 1.835
C9: " | G9: 1.843
B10: 19A-0003Z | C10: " | D10: 25 | E10: 0 | F10: 858 | G10: 1.85 | H10: 5.535 | I10: 5.49 | J10: =IF(M10<>"",(H10-I10)/M10,"") -> 0.015 | K10: =(F10*(273.15+D10)/273.15)/(M10*N10) -> 7.8044023 | L10: MU3 | M10: =VLOOKUP(L10,allgemein!$B$3:$C$13,2,FALSE) -> 3 | N10: 40 | O10: "
C11: " | G11: 1.841
C12: " | G12: 1.844 | P12: Mem. O-seitig feine, silbrige Ablagerung
B13: 19A-0004Z | C13: 704694 | D13: 23.7 | E13: 0.1 | F13: 178 | H13: 1.878 | I13: 1.864 | J13: =IF(M13<>"",(H13-I13)/M13,"") -> 0.014 | K13: =(F13*(273.15+D13)/273.15)/(M13*N13) -> 7.7377705 | L13: MI_V3 | M13: =VLOOKUP(L13,[1]allgemein!$B$3:$C$13,2,FALSE) -> 1 | N13: 25 | O13: FA496305
B14: 19A-0005Z | C14: " | D14: 23.9 | E14: 0.2 | F14: 177 | H14: 1.879 | I14: 1.864 | J14: =IF(M14<>"",(H14-I14)/M14,"") -> 0.015 | K14: =(F14*(273.15+D14)/273.15)/(M14*N14) -> 7.6994838 | L14: MI_V3 | M14: =VLOOKUP(L14,[1]allgemein!$B$3:$C$13,2,FALSE) -> 1 | N14: 25 | O14: "
B15: 19A-0006Z | C15: " | D15: 24.2 | E15: 0.2 | F15: 177 | H15: 1.877 | I15: 1.858 | J15: =IF(M15<>"",(H15-I15)/M15,"") -> 0.019 | K15: =(F15*(273.15+D15)/273.15)/(M15*N15) -> 7.7072597 | L15: MI_V3 | M15: =VLOOKUP(L15,[1]allgemein!$B$3:$C$13,2,FALSE) -> 1 | N15: 25 | O15: " | P15: Mem. Blasen/ Kratzer
B16: 19A-0007Z | C16: " | D16: 24.5 | E16: 0.1 | F16: 177 | H16: 1.865 | I16: 1.85 | J16: =IF(M16<>"",(H16-I16)/M16,"") -> 0.015 | K16: =(F16*(273.15+D16)/273.15)/(M16*N16) -> 7.7150357 | L16: MI_V3 | M16: =VLOOKUP(L16,[1]allgemein!$B$3:$C$13,2,FALSE) -> 1 | N16: 25 | O16: " | P16: H-Elektr. alt
B17: 19A-0008Z | C17: " | D17: 25 | E17: 0.2 | F17: 177 | H17: 1.867 | I17: 1.85 | J17: =IF(M17<>"",(H17-I17)/M17,"") -> 0.017 | K17: =(F17*(273.15+D17)/273.15)/(M17*N17) -> 7.7279956 | L17: MI_V3 | M17: =VLOOKUP(L17,[1]allgemein!$B$3:$C$13,2,FALSE) -> 1 | N17: 25 | O17: " | P17: Mem. Blasen/ Kratzer
B18: 19A-0009Z | C18: " | D18: 25.6 | E18: 0.2 | F18: 177 | H18: 1.857 | I18: 1.842 | J18: =IF(M18<>"",(H18-I18)/M18,"") -> 0.015 | K18: =(F18*(273.15+D18)/273.15)/(M18*N18) -> 7.7435475 | L18: MI_V3 | M18: =VLOOKUP(L18,[1]allgemein!$B$3:$C$13,2,FALSE) -> 1 | N18: 25 | O18: " | P18: "
B19: 19A-0010Z | C19: " | D19: 26.3 | E19: 0.3 | F19: 177 | H19: 1.858 | I19: 1.844 | J19: =IF(M19<>"",(H19-I19)/M19,"") -> 0.014 | K19: =(F19*(273.15+D19)/273.15)/(M19*N19) -> 7.7616914 | L19: MI_V3 | M19: =VLOOKUP(L19,[1]allgemein!$B$3:$C$13,2,FALSE) -> 1 | N19: 25 | O19: " | P19: "
B20: 19A-0011Z | C20: 704781 | D20: 27.2 | E20: 0.2 | F20: 177 | H20: 1.866 | I20: 1.848 | J20: =IF(M20<>"",(H20-I20)/M20,"") -> 0.018 | K20: =(F20*(273.15+D20)/273.15)/(M20*N20) -> 7.7850192 | L20: MI_V3 | M20: =VLOOKUP(L20,[1]allgemein!$B$3:$C$13,2,FALSE) -> 1 | N20: 25 | O20: " | P20: "
B21: 19A-0012Z | C21: 704933 | D21: 25.8 | E21: 0 | F21: 869 | G21: 1.795 | H21: 7.18 | I21: 7.11 | J21: =IF(M21<>"",(H21-I21)/M21,"") -> 0.0175 | K21: =(F21*(273.15+D21)/273.15)/(M21*N21) -> 7.9256681 | L21: MU4 | M21: =VLOOKUP(L21,[1]allgemein!$B$3:$C$13,2,FALSE) -> 4 | N21: 30 | O21: FA496319
C22: " | G22: 1.793
C23: " | G23: 1.797
C24: " | G24: 1.795
B25: 19A-0013Z | C25: " | D25: 26 | E25: 0 | F25: 869 | G25: 1.784 | H25: 7.148 | I25: 7.09 | J25: =IF(M25<>"",(H25-I25)/M25,"") -> 0.0145 | K25: =(F25*(273.15+D25)/273.15)/(M25*N25) -> 7.9309705 | L25: MU4 | M25: =VLOOKUP(L25,[1]allgemein!$B$3:$C$13,2,FALSE) -> 4 | N25: 30 | O25: "
C26: " | G26: 1.786
C27: " | G27: 1.788
C28: " | G28: 1.79
B29: 19A-0014Z | C29: " | D29: 25.5 | E29: 0 | F29: 870 | G29: 1.801 | H29: 7.208 | I29: 7.15 | J29: =IF(M29<>"",(H29-I29)/M29,"") -> 0.0145 | K29: =(F29*(273.15+D29)/273.15)/(M29*N29) -> 7.9268259 | L29: MU4 | M29: =VLOOKUP(L29,[1]allgemein!$B$3:$C$13,2,FALSE) -> 4 | N29: 30 | O29: "
C30: " | G30: 1.802
C31: " | G31: 1.802
C32: " | G32: 1.803
B33: 19A-0015Z | C33: " | D33: 25.5 | E33: 0 | F33: 866 | G33: 1.808 | H33: 7.233 | I33: 7.17 | J33: =IF(M33<>"",(H33-I33)/M33,"") -> 0.01575 | K33: =(F33*(273.15+D33)/273.15)/(M33*N33) -> 7.8903807 | L33: MU4 | M33: =VLOOKUP(L33,[1]allgemein!$B$3:$C$13,2,FALSE) -> 4 | N33: 30 | O33: "
C34: " | G34: 1.816
C35: 704937 | G35: 1.805
C36: " | G36: 1.804
B37: 19A-0016Z | C37: " | D37: 24.5 | E37: 0.1 | F37: 853 | G37: 1.795 | H37: 7.157 | I37: 7.1 | J37: =IF(M37<>"",(H37-I37)/M37,"") -> 0.01425 | K37: =(F37*(273.15+D37)/273.15)/(M37*N37) -> 7.7459104 | L37: MU4 | M37: =VLOOKUP(L37,[1]allgemein!$B$3:$C$13,2,FALSE) -> 4 | N37: 30 | O37: " | P37: TDK Netzteil
C38: " | G38: 1.783
C39: " | G39: 1.788
C40: " | G40: 1.791
B41: " | C41: " | D41: 24.7 | E41: 0.2 | F41: 1143 | G41: 1.829 | H41: 7.308 | I41: 7.25 | J41: =IF(M41<>"",(H41-I41)/M41,"") -> 0.0145 | K41: =(F41*(273.15+D41)/273.15)/(M41*N41) -> 7.7897343 | L41: MU4 | M41: =VLOOKUP(L41,[1]allgemein!$B$3:$C$13,2,FALSE) -> 4 | N41: 40 | O41: "
C42: " | G42: 1.821
...

Sheet Feb
B3: Cell # | C3: Membran Batch FA | D3: Temp Gas / [°C] | E3: Temp Kat T1-T2 / [°C] | F3: Gasfluss / [sccm / min] | G3: Membrane V @ 13 bar/[V] | H3: Cell V @ 13 bar/[V] | I3: Cell V @ 0 bar [V] | J3: Voltage Diff. / [V] | K3: H2 Prod / [nmL/A] | L3: Typ | M3: Anzahl Layer | N3: Strom / [A] | O3: FA # | P3: Bemerkungen | Q3: Bemerkungen | S3: Visum | T3: Jahr: | U3: 2019
B4: 19B-0001Z | C4: 496139 | D4: 23.6 | E4: 0.1 | F4: 283 | H4: 1.887 | I4: 1.843 | J4: =IF(M4<>"",(H4-I4)/M4,"") -> 0.044 | K4: =(F4*(273.15+D4)/273.15)/(M4*N4) -> 7.6862759 | L4: MU1 | M4: =VLOOKUP(L4,allgemein!$B$3:$C$13,2,FALSE) -> 1 | N4: 40 | O4: FA496382
B5: 19B-0002Z | C5: " | D5: 23.6 | E5: 0 | F5: 282 | H5: 1.872 | I5: 1.839 | J5: =IF(M5<>"",(H5-I5)/M5,"") -> 0.033 | K5: =(F5*(273.15+D5)/273.15)/(M5*N5) -> 7.6591159 | L5: MU1 | M5: =VLOOKUP(L5,allgemein!$B$3:$C$13,2,FALSE) -> 1 | N5: 40 | O5: "
B6: 19B-0003Z | C6: " | D6: 23.7 | E6: 0 | F6: 283 | H6: 1.873 | I6: 1.841 | J6: =IF(M6<>"",(H6-I6)/M6,"") -> 0.032 | K6: =(F6*(273.15+D6)/273.15)/(M6*N6) -> 7.688866 | L6: MU1 | M6: =VLOOKUP(L6,allgemein!$B$3:$C$13,2,FALSE) -> 1 | N6: 40 | O6: " | P6: Mem. kleines Ptloch
B7: 19B-0004Z | C7: " | D7: 23.7 | E7: 0 | F7: 282 | H7: 1.858 | I7: 1.832 | J7: =IF(M7<>"",(H7-I7)/M7,"") -> 0.026 | K7: =(F7*(273.15+D7)/273.15)/(M7*N7) -> 7.6616969 | L7: MU1 | M7: =VLOOKUP(L7,allgemein!$B$3:$C$13,2,FALSE) -> 1 | N7: 40 | O7: "
B8: 19B-0005Z | C8: " | D8: 23.7 | E8: 0.1 | F8: 282 | H8: 1.861 | I8: 1.831 | J8: =IF(M8<>"",(H8-I8)/M8,"") -> 0.03 | K8: =(F8*(273.15+D8)/273.15)/(M8*N8) -> 7.6616969 | L8: MU1 | M8: =VLOOKUP(L8,allgemein!$B$3:$C$13,2,FALSE) -> 1 | N8: 40 | O8: "
B9: 19B-0006Z | C9: " | D9: 23.6 | E9: 0.2 | F9: 281 | H9: 1.91 | I9: 1.825 | J9: =IF(M9<>"",(H9-I9)/M9,"") -> 0.085 | K9: =(F9*(273.15+D9)/273.15)/(M9*N9) -> 7.6319559 | L9: MU1 | M9: =VLOOKUP(L9,allgemein!$B$3:$C$13,2,FALSE) -> 1 | N9: 40 | O9: " | P9: Mem. grosser Kratzer
B10: " | C10: 496138 | D10: 26 | E10: 0.2 | F10: 282 | H10: 1.82 | I10: 1.799 | J10: =IF(M10<>"",(H10-I10)/M10,"") -> 0.021 | K10: =(F10*(273.15+D10)/273.15)/(M10*N10) -> 7.7210599 | L10: MU1 | M10: =VLOOKUP(L10,allgemein!$B$3:$C$13,2,FALSE) -> 1 | N10: 40 | P10: Mem. gewechselt
B11: 19B-0007Z | C11: 496139 | D11: 24 | E11: 0.1 | F11: 282 | H11: 1.862 | I11: 1.833 | J11: =IF(M11<>"",(H11-I11)/M11,"") -> 0.029 | K11: =(F11*(273.15+D11)/273.15)/(M11*N11) -> 7.6694399 | L11: MU1 | M11: =VLOOKUP(L11,allgemein!$B$3:$C$13,2,FALSE) -> 1 | N11: 40 | O11: "
B12: 19B-0008Z | C12: " | D12: 24 | E12: 0.2 | F12: 282 | H12: 1.893 | I12: 1.827 | J12: =IF(M12<>"",(H12-I12)/M12,"") -> 0.066 | K12: =(F12*(273.15+D12)/273.15)/(M12*N12) -> 7.6694399 | L12: MU1 | M12: =VLOOKUP(L12,allgemein!$B$3:$C$13,2,FALSE) -> 1 | N12: 40 | O12: "
B13: " | C13: " | D13: 23.9 | E13: 0 | F13: 282 | H13: 1.87 | I13: 1.824 | J13: =IF(M13<>"",(H13-I13)/M13,"") -> 0.046 | K13: =(F13*(273.15+D13)/273.15)/(M13*N13) -> 7.6668589 | L13: MU1 | M13: =VLOOKUP(L13,allgemein!$B$3:$C$13,2,FALSE) -> 1 | N13: 40 | P13: geöffnet/ wieder verschraubt
B14: " | C14: " | D14: 23.9 | E14: 0 | F14: 282 | H14: 1.86 | I14: 1.815 | J14: =IF(M14<>"",(H14-I14)/M14,"") -> 0.045 | K14: =(F14*(273.15+D14)/273.15)/(M14*N14) -> 7.6668589 | L14: MU1 | M14: =VLOOKUP(L14,allgemein!$B$3:$C$13,2,FALSE) -> 1 | N14: 40
B15: 19B-0009Z | C15: " | D15: 24 | E15: 0 | F15: 282 | H15: 1.875 | I15: 1.826 | J15: =IF(M15<>"",(H15-I15)/M15,"") -> 0.049 | K15: =(F15*(273.15+D15)/273.15)/(M15*N15) -> 7.6694399 | L15: MU1 | M15: =VLOOKUP(L15,allgemein!$B$3:$C$13,2,FALSE) -> 1 | N15: 40 | O15: "
B16: " | C16: " | D16: 23.9 | E16: 0 | F16: 282 | H16: 1.889 | I16: 1.826 | J16: =IF(M16<>"",(H16-I16)/M16,"") -> 0.063 | K16: =(F16*(273.15+D16)/273.15)/(M16*N16) -> 7.6668589 | L16: MU1 | M16: =VLOOKUP(L16,allgemein!$B$3:$C$13,2,FALSE) -> 1 | N16: 40 | P16: geöffnet/ wieder verschraubt
B17: " | C17: " | D17: 22.3 | E17: 0.1 | F17: 282 | H17: 1.918 | I17: 1.859 | J17: =IF(M17<>"",(H17-I17)/M17,"") -> 0.059 | K17: =(F17*(273.15+D17)/273.15)/(M17*N17) -> 7.6255629 | L17: MU1 | M17: =VLOOKUP(L17,allgemein!$B$3:$C$13,2,FALSE) -> 1 | N17: 40 | P17: altes Testsys. 38.9A= 40A
B18: " | C18: 496138 | D18: 26 | E18: 0 | F18: 282 | H18: 1.827 | I18: 1.807 | J18: =IF(M18<>"",(H18-I18)/M18,"") -> 0.02 | K18: =(F18*(273.15+D18)/273.15)/(M18*N18) -> 7.7210599 | L18: MU1 | M18: =VLOOKUP(L18,allgemein!$B$3:$C$13,2,FALSE) -> 1 | N18: 40 | P18: Mem. gewechselt
B19: 19B-0010Z | C19: 496139 | D19: 24.1 | E19: 0 | F19: 282 | H19: 1.891 | I19: 1.827 | J19: =IF(M19<>"",(H19-I19)/M19,"") -> 0.064 | K19: =(F19*(273.15+D19)/273.15)/(M19*N19) -> 7.6720209 | L19: MU1 | M19: =VLOOKUP(L19,allgemein!$B$3:$C$13,2,FALSE) -> 1 | N19: 40 | O19: "
B20: " | C20: " | D20: 23.8 | E20: 0 | F20: 282 | H20: 1.897 | I20: 1.849 | J20: =IF(M20<>"",(H20-I20)/M20,"") -> 0.048 | K20: =(F20*(273.15+D20)/273.15)/(M20*N20) -> 7.6642779 | L20: MU1 | M20: =VLOOKUP(L20,allgemein!$B$3:$C$13,2,FALSE) -> 1 | N20: 40 | P20: geöffnet/ wieder verschraubt
B21: " | C21: " | D21: 22.5 | E21: 0 | F21: 282 | H21: 1.89 | I21: 1.862 | J21: =IF(M21<>"",(H21-I21)/M21,"") -> 0.028 | K21: =(F21*(273.15+D21)/273.15)/(M21*N21) -> 7.6307249 | L21: MU1 | M21: =VLOOKUP(L21,allgemein!$B$3:$C$13,2,FALSE) -> 1 | N21: 40 | P21: altes Testsys. 39.4A= 40A
B22: 19B-0011Z | C22: " | D22: 24.1 | E22: 0 | F22: 282 | H22: 1.888 | I22: 1.823 | J22: =IF(M22<>"",(H22-I22)/M22,"") -> 0.065 | K22: =(F22*(273.15+D22)/273.15)/(M22*N22) -> 7.6720209 | L22: MU1 | M22: =VLOOKUP(L22,allgemein!$B$3:$C$13,2,FALSE) -> 1 | N22: 40 | O22: "
B23: " | C23: " | D23: 23.7 | E23: 0 | F23: 282 | H23: 1.902 | I23: 1.856 | J23: =IF(M23<>"",(H23-I23)/M23,"") -> 0.046 | K23: =(F23*(273.15+D23)/273.15)/(M23*N23) -> 7.6616969 | L23: MU1 | M23: =VLOOKUP(L23,allgemein!$B$3:$C$13,2,FALSE) -> 1 | N23: 40 | P23: geöffnet/ wieder verschraubt
B24: 19B-0012Z | C24: " | D24: 24.1 | E24: 0 | F24: 281 | H24: 1.88 | I24: 1.82 | J24: =IF(M24<>"",(H24-I24)/M24,"") -> 0.06 | K24: =(F24*(273.15+D24)/273.15)/(M24*N24) -> 7.6448151 | L24: MU1 | M24: =VLOOKUP(L24,allgemein!$B$3:$C$13,2,FALSE) -> 1 | N24: 40 | O24: "
B25: " | C25: " | D25: 23.9 | E25: 0 | F25: 282 | H25: 1.885 | I25: 1.854 | J25: =IF(M25<>"",(H25-I25)/M25,"") -> 0.031 | K25: =(F25*(273.15+D25)/273.15)/(M25*N25) -> 7.6668589 | L25: MU1 | M25: =VLOOKUP(L25,allgemein!$B$3:$C$13,2,FALSE) -> 1 | N25: 40 | P25: geöffnet/ wieder verschraubt
B26: 19B-0013Z | C26: 496134 | D26: 22.3 | E26: 0.1 | F26: 173 | H26: 1.876 | I26: 1.861 | J26: =IF(M26<>"",(H26-I26)/M26,"") -> 0.015 | K26: =(F26*(273.15+D26)/273.15)/(M26*N26) -> 7.4849497 | L26: MI_V3 | M26: =VLOOKUP(L26,[1]allgemein!$B$3:$C$13,2,FALSE) -> 1 | N26: 25 | O26: FA496362 | P26: altes TS auf 24.2A= 25A
B27: 19B-0014Z | C27: " | D27: 22.3 | E27: 0.1 | F27: 173 | H27: 1.876 | I27: 1.861 | J27: =IF(M27<>"",(H27-I27)/M27,"") -> 0.015 | K27: =(F27*(273.15+D27)/273.15)/(M27*N27) -> 7.4849497 | L27: MI_V3 | M27: =VLOOKUP(L27,[1]allgemein!$B$3:$C$13,2,FALSE) -> 1 | N27: 25 | O27: " | P27: "
B28: 19B-0015Z | C28: " | D28: 22.3 | E28: 0.1 | F28: 173 | H28: 1.874 | I28: 1.858 | J28: =IF(M28<>"",(H28-I28)/M28,"") -> 0.016 | K28: =(F28*(273.15+D28)/273.15)/(M28*N28) -> 7.4849497 | L28: MI_V3 | M28: =VLOOKUP(L28,[1]allgemein!$B$3:$C$13,2,FALSE) -> 1 | N28: 25 | O28: " | P28: "
B29: 19B-0016Z | C29: 496136 | D29: 22.3 | E29: 0.1 | F29: 173 | H29: 1.87 | I29: 1.851 | J29: =IF(M29<>"",(H29-I29)/M29,"") -> 0.019 | K29: =(F29*(273.15+D29)/273.15)/(M29*N29) -> 7.4849497 | L29: MI_V3 | M29: =VLOOKUP(L29,[1]allgemein!$B$3:$C$13,2,FALSE) -> 1 | N29: 25 | O29: " | P29: "
B30: " | C30: " | D30: 23.8 | E30: 0 | F30: 175 | H30: 1.835 | I30: 1.817 | J30: =IF(M30<>"",(H30-I30)/M30,"") -> 0.018 | K30: =(F30*(273.15+D30)/273.15)/(M30*N30) -> 7.6099213 | L30: MI_V3 | M30: =VLOOKUP(L30,[1]allgemein!$B$3:$C$13,2,FALSE) -> 1 | N30: 25 | O30: " | P30: neues Netzteil Vergleichsmessung
B31: 19B-0017Z | C31: " | D31: 22.3 | E31: 0.1 | F31: 173 | H31: 1.869 | I31: 1.855 | J31: =IF(M31<>"",(H31-I31)/M31,"") -> 0.014 | K31: =(F31*(273.15+D31)/273.15)/(M31*N31) -> 7.4849497 | L31: MI_V3 | M31: =VLOOKUP(L31,[1]allgemein!$B$3:$C$13,2,FALSE) -> 1 | N31: 25 | O31: " | P31: altes TS auf 24.2A= 25A
B32: " | C32: " | D32: 23.9 | E32: 0 | F32: 175 | H32: 1.837 | I32: 1.824 | J32: =IF(M32<>"",(H32-I32)/M32,"") -> 0.013 | K32: =(F32*(273.15+D32)/273.15)/(M32*N32) -> 7.612484 | L32: MI_V3 | M32: =VLOOKUP(L32,[1]allgemein!$B$3:$C$13,2,FALSE) -> 1 | N32: 25 | O32: " | P32: neues Netzteil Vergleichsmessung
B33: 19B-0018Z | C33: " | D33: 22.3 | E33: 0.2 | F33: 173 | H33: 1.878 | I33: 1.861 | J33: =IF(M33<>"",(H33-I33)/M33,"") -> 0.017 | K33: =(F33*(273.15+D33)/273.15)/(M33*N33) -> 7.4849497 | L33: MI_V3 | M33: =VLOOKUP(L33,[1]allgemein!$B$3:$C$13,2,FALSE) -> 1 | N33: 25 | O33: "
B34: 19B-0019Z | C34: " | D34: 22.3 | E34: 0.2 | F34: 173 | H34: 1.873 | I34: 1.858 | J34: =IF(M34<>"",(H34-I34)/M34,"") -> 0.015 | K34: =(F34*(273.15+D34)/273.15)/(M34*N34) -> 7.4849497 | L34: MI_V3 | M34: =VLOOKUP(L34,[1]allgemein!$B$3:$C$13,2,FALSE) -> 1 | N34: 25 | O34: "
B35: 19B-0020Z | C35: " | D35: 22.1 | E35: 0.2 | F35: 173 | H35: 1.87 | I35: 1.862 | J35: =IF(M35<>"",(H35-I35)/M35,"") -> 0.008 | K35: =(F35*(273.15+D35)/273.15)/(M35*N35) -> 7.4798828 | L35: MI_V3 | M35: =VLOOKUP(L35,[1]allgemein!$B$3:$C$13,2,FALSE) -> 1 | N35: 25 | O35: "
B36: 19B-0021Z | C36: 496138 | D36: 26 | E36: 0 | F36: 281 | H36: 1.825 | I36: 1.809 | J36: =IF(M36<>"",(H36-I36)/M36,"") -> 0.016 | K36: =(F36*(273.15+D36)/273.15)/(M36*N36) -> 7.6936802 | L36: MU1 | M36: 1 | N36: 40 | O36: FA502898
B37: 19B-0022Z | C37: " | D37: 25.9 | E37: 0 | F37: 282 | H37: 1.843 | I37: 1.815 | J37: =IF(M37<>"",(H37-I37)/M37,"") -> 0.028 | K37: =(F37*(273.15+D37)/273.15)/(M37*N37) -> 7.7184789 | L37: MU1 | M37: =VLOOKUP(L37,allgemein!$B$3:$C$13,2,FALSE) -> 1 | N37: 40 | O37: " | P37: Mem. Punktlöcher
B38: 19B-0023Z | C38: " | D38: 25.8 | E38: 0 | F38: 281 | H38: 1.846 | I38: 1.813 | J38: =IF(M38<>"",(H38-I38)/M38,"") -> 0.033 | K38: =(F38*(273.15+D38)/273.15)/(M38*N38) -> 7.6885365 | L38: MU1 | M38: =VLOOKUP(L38,allgemein!$B$3:$C$13,2,FALSE) -> 1 | N38: 40 | O38: " | P38: "
B39: 19B-0024Z | C39: " | D39: 25.8 | E39: 0.1 | F39: 281 | H39: 1.836 | I39: 1.819 | J39: =IF(M39<>"",(H39-I39)/M39,"") -> 0.017 | K39: =(F39*(273.15+D39)/273.15)/(M39*N39) -> 7.6885365 | L39: MU1 | M39: =VLOOKUP(L39,allgemein!$B$3:$C$13,2,FALSE) -> 1 | N39: 40 | O39: " | P39: "
B40: 19B-0025Z | C40: " | D40: 25.6 | E40: 0.1 | F40: 281 | H40: 1.811 | I40: 1.792 | J40: =IF(M40<>"",(H40-I40)/M40,"") -> 0.019 | K40: =(F40*(273.15+D40)/273.15)/(M40*N40) -> 7.6833928 | L40: MU1 | M40: =VLOOKUP(L40,allgemein!$B$3:$C$13,2,FALSE) -> 1 | N40: 40 | O40: " | P40: "
B41: 19B-0026Z | C41: " | D41: 25.5 | E41: 0 | F41: 282 | H41: 1.807 | I41: 1.791 | J41: =IF(M41<>"",(H41-I41)/M41,"") -> 0.016 | K41: =(F41*(273.15+D41)/273.15)/(M41*N41) -> 7.7081549 | L41: MU1 | M41: =VLOOKUP(L41,allgemein!$B$3:$C$13,2,FALSE) -> 1 | N41: 40 | O41: " | P41: "
B42: 19B-0027Z | C42: " | D42: 23 | E42: 0 | F42: 281 | H42: 1.845 | I42: 1.82 | J42: =IF(M42<>"",(H42-I42)/M42,"") -> 0.025 | K42: =(F42*(273.15+D42)/273.15)/(M42*N42) -> 7.6165248 | L42: MU1 | M42: =VLOOKUP(L42,allgemein!$B$3:$C$13,2,FALSE) -> 1 | N42: 40 | O42: " | P42: "
...

Sheet Mar
B3: Cell # | C3: Membran Batch FA | D3: Temp Gas / [°C] | E3: Temp Kat T1-T2 / [°C] | F3: Gasfluss / [sccm / min] | G3: Membrane V @ 13 bar/[V] | H3: Cell V @ 13 bar/[V] | I3: Cell V @ 0 bar [V] | J3: Voltage Diff. / [V] | K3: H2 Prod / [nmL/A] | L3: Typ | M3: Anzahl Layer | N3: Strom / [A] | O3: FA # | P3: Bemerkungen | Q3: Bemerkungen | S3: Visum | T3: Jahr: | U3: 2019
B4: 19C-0001Z | C4: 496140 | D4: 25.4 | E4: 0 | F4: 282 | H4: 1.84 | I4: 1.82 | J4: =IF(M4<>"",(H4-I4)/M4,"") -> 0.02 | K4: =(F8*(273.15+D8)/273.15)/(M4*N4) -> 7.6756773 | L4: MU1 | M4: =VLOOKUP(L4,[1]allgemein!$B$3:$C$13,2,FALSE) -> 1 | N4: 40 | O4: FA506467
B5: 19C-0002Z | C5: " | D5: 25.4 | E5: 0 | F5: 282 | H5: 1.837 | I5: 1.818 | J5: =IF(M5<>"",(H5-I5)/M5,"") -> 0.019 | K5: =(F5*(273.15+D5)/273.15)/(M5*N5) -> 7.7055739 | L5: MU1 | M5: =VLOOKUP(L5,[1]allgemein!$B$3:$C$13,2,FALSE) -> 1 | N5: 40 | O5: "
B6: 19C-0003Z | C6: " | D6: 25.3 | E6: 0 | F6: 282 | H6: 1.832 | I6: 1.814 | J6: =IF(M6<>"",(H6-I6)/M6,"") -> 0.018 | K6: =(F6*(273.15+D6)/273.15)/(M6*N6) -> 7.7029929 | L6: MU1 | M6: =VLOOKUP(L6,[1]allgemein!$B$3:$C$13,2,FALSE) -> 1 | N6: 40 | O6: "
B7: 19C-0004Z | C7: " | D7: 25.3 | E7: 0 | F7: 282 | H7: 1.84 | I7: 1.816 | J7: =IF(M7<>"",(H7-I7)/M7,"") -> 0.024 | K7: =(F7*(273.15+D7)/273.15)/(M7*N7) -> 7.7029929 | L7: MU1 | M7: =VLOOKUP(L7,[1]allgemein!$B$3:$C$13,2,FALSE) -> 1 | N7: 40 | O7: "
B8: 19C-0005Z | C8: " | D8: 25.3 | E8: 0 | F8: 281 | H8: 1.832 | I8: 1.815 | J8: =IF(M8<>"",(H8-I8)/M8,"") -> 0.017 | K8: =(F8*(273.15+D8)/273.15)/(M8*N8) -> 7.6756773 | L8: MU1 | M8: =VLOOKUP(L8,[1]allgemein!$B$3:$C$13,2,FALSE) -> 1 | N8: 40 | O8: "
B9: 19C-0006Z | C9: " | D9: 23.3 | E9: 0 | F9: 856 | G9: 1.826 | H9: 5.484 | I9: 5.425 | J9: =IF(M9<>"",(H9-I9)/M9,"") -> 0.019666667 | K9: =(F9*(273.15+D9)/273.15)/(M9*N9) -> 7.7418146 | L9: MU3 | M9: =VLOOKUP(L9,[1]allgemein!$B$3:$C$13,2,FALSE) -> 3 | N9: 40 | O9: FA498497
C10: " | G10: 1.833
C11: " | G11: 1.825
B12: 19C-0007Z | C12: " | D12: 22.9 | E12: 0.1 | F12: 856 | G12: 1.823 | H12: 5.463 | I12: 5.413 | J12: =IF(M12<>"",(H12-I12)/M12,"") -> 0.016666667 | K12: =(F12*(273.15+D12)/273.15)/(M12*N12) -> 7.7313686 | L12: MU3 | M12: =VLOOKUP(L12,[1]allgemein!$B$3:$C$13,2,FALSE) -> 3 | N12: 40 | O12: "
C13: " | G13: 1.823
C14: " | G14: 1.817
B15: 19C-0008Z-R | C15: 496337 | D15: 24.9 | E15: 0.3 | F15: 275 | H15: 1.918 | I15: 1.903 | J15: =IF(M15<>"",(H15-I15)/M15,"") -> 0.015 | K15: =(F15*(273.15+D15)/273.15)/(M15*N15) -> 7.5017161 | L15: SP-H2 | M15: =VLOOKUP(L15,[1]allgemein!$B$3:$C$13,2,FALSE) -> 1 | N15: 40 | O15: FA509063 | P15: vormals: 0236-1867-2517
B16: 19C-0009Z-R | C16: " | D16: 25.1 | E16: 0.2 | F16: 275 | H16: 1.91 | I16: 1.895 | J16: =IF(M16<>"",(H16-I16)/M16,"") -> 0.015 | K16: =(F16*(273.15+D16)/273.15)/(M16*N16) -> 7.50675 | L16: SP-H2 | M16: =VLOOKUP(L16,[1]allgemein!$B$3:$C$13,2,FALSE) -> 1 | N16: 40 | O16: " | P16: vormals: 0522-0071-4116
B17: 19C-0010Z-R | C17: " | D17: 24.9 | E17: 0.1 | F17: 275 | H17: 1.917 | I17: 1.901 | J17: =IF(M17<>"",(H17-I17)/M17,"") -> 0.016 | K17: =(F17*(273.15+D17)/273.15)/(M17*N17) -> 7.5017161 | L17: SP-H2 | M17: =VLOOKUP(L17,[1]allgemein!$B$3:$C$13,2,FALSE) -> 1 | N17: 40 | O17: FA509064 | P17: vormals: 0522-0168-5117
B18: 19C-0011Z-R | C18: " | D18: 24.9 | E18: 0 | F18: 274 | H18: 1.901 | I18: 1.886 | J18: =IF(M18<>"",(H18-I18)/M18,"") -> 0.015 | K18: =(F18*(273.15+D18)/273.15)/(M18*N18) -> 7.4744371 | L18: SP-H2 | M18: =VLOOKUP(L18,[1]allgemein!$B$3:$C$13,2,FALSE) -> 1 | N18: 40 | O18: FA505694 | P18: vormals: 0522-0043-1616
B19: 19C-0012Z-R | C19: 496140 | D19: 25.1 | E19: 0.3 | F19: 281 | H19: 1.884 | I19: 1.869 | J19: =IF(M19<>"",(H19-I19)/M19,"") -> 0.015 | K19: =(F19*(273.15+D19)/273.15)/(M19*N19) -> 7.6705336 | L19: MA_V1 | M19: =VLOOKUP(L19,[1]allgemein!$B$3:$C$13,2,FALSE) -> 1 | N19: 40 | O19: FA505067
B20: 19C-0013Z-R | C20: " | D20: 25.1 | E20: 0.3 | F20: 281 | H20: 1.884 | I20: 1.87 | J20: =IF(M20<>"",(H20-I20)/M20,"") -> 0.014 | K20: =(F20*(273.15+D20)/273.15)/(M20*N20) -> 7.6705336 | L20: MA_V1 | M20: =VLOOKUP(L20,[1]allgemein!$B$3:$C$13,2,FALSE) -> 1 | N20: 40 | O20: ??? | P20: Mat. mit Stefan ausbuchen
B21: 19C-0014Z-R | C21: 496140 | D21: 25.1 | E21: 0.2 | F21: 281 | H21: 1.883 | I21: 1.869 | J21: =IF(M21<>"",(H21-I21)/M21,"") -> 0.014 | K21: =(F21*(273.15+D21)/273.15)/(M21*N21) -> 7.6705336 | L21: MA_V1 | M21: =VLOOKUP(L21,[1]allgemein!$B$3:$C$13,2,FALSE) -> 1 | N21: 40 | O21: FA499792
B22: 19C-0015Z-R | C22: " | D22: 25 | E22: 0.3 | F22: 281 | H22: 1.891 | I22: 1.875 | J22: =IF(M22<>"",(H22-I22)/M22,"") -> 0.016 | K22: =(F22*(273.15+D22)/273.15)/(M22*N22) -> 7.6679617 | L22: MA_V1 | M22: =VLOOKUP(L22,[1]allgemein!$B$3:$C$13,2,FALSE) -> 1 | N22: 40 | O22: "
B23: 19C-0016Z-R | C23: " | D23: 25 | E23: 0.3 | F23: 281 | H23: 1.884 | I23: 1.867 | J23: =IF(M23<>"",(H23-I23)/M23,"") -> 0.017 | K23: =(F23*(273.15+D23)/273.15)/(M23*N23) -> 7.6679617 | L23: MA_V1 | M23: =VLOOKUP(L23,[1]allgemein!$B$3:$C$13,2,FALSE) -> 1 | N23: 40 | O23: "
B24: 19C-0017Z-R | C24: " | D24: 24.9 | E24: 0.3 | F24: 280 | H24: 1.886 | I24: 1.871 | J24: =IF(M24<>"",(H24-I24)/M24,"") -> 0.015 | K24: =(F24*(273.15+D24)/273.15)/(M24*N24) -> 7.6381109 | L24: MA_V1 | M24: =VLOOKUP(L24,[1]allgemein!$B$3:$C$13,2,FALSE) -> 1 | N24: 40 | O24: "
B25: 19C-0018Z | C25: 496135 | D25: 24.5 | E25: 0.1 | F25: 173 | H25: 1.861 | I25: 1.844 | J25: =IF(M25<>"",(H25-I25)/M25,"") -> 0.017 | K25: =(F25*(273.15+D25)/273.15)/(M25*N25) -> 7.5406846 | L25: MI_V3 | M25: =VLOOKUP(L25,[1]allgemein!$B$3:$C$13,2,FALSE) -> 1 | N25: 25 | O25: FA506469
B26: 19C-0019Z | C26: " | D26: 24.5 | E26: 0.1 | F26: 173 | H26: 1.857 | I26: 1.842 | J26: =IF(M26<>"",(H26-I26)/M26,"") -> 0.015 | K26: =(F26*(273.15+D26)/273.15)/(M26*N26) -> 7.5406846 | L26: MI_V3 | M26: =VLOOKUP(L26,[1]allgemein!$B$3:$C$13,2,FALSE) -> 1 | N26: 25 | O26: "
B27: 19C-0020Z | C27: " | D27: 24.4 | E27: 0.1 | F27: 173 | H27: 1.849 | I27: 1.831 | J27: =IF(M27<>"",(H27-I27)/M27,"") -> 0.018 | K27: =(F27*(273.15+D27)/273.15)/(M27*N27) -> 7.5381512 | L27: MI_V3 | M27: =VLOOKUP(L27,[1]allgemein!$B$3:$C$13,2,FALSE) -> 1 | N27: 25 | O27: "
B28: 19C-0021Z | C28: " | D28: 24.3 | E28: 0.1 | F28: 173 | H28: 1.84 | I28: 1.823 | J28: =IF(M28<>"",(H28-I28)/M28,"") -> 0.017 | K28: =(F28*(273.15+D28)/273.15)/(M28*N28) -> 7.5356178 | L28: MI_V3 | M28: =VLOOKUP(L28,[1]allgemein!$B$3:$C$13,2,FALSE) -> 1 | N28: 25 | O28: "
B29: 19C-0022Z | C29: " | D29: 24.2 | E29: 0 | F29: 173 | H29: 1.849 | I29: 1.832 | J29: =IF(M29<>"",(H29-I29)/M29,"") -> 0.017 | K29: =(F29*(273.15+D29)/273.15)/(M29*N29) -> 7.5330844 | L29: MI_V3 | M29: =VLOOKUP(L29,[1]allgemein!$B$3:$C$13,2,FALSE) -> 1 | N29: 25 | O29: "
B30: 19C-0023Z | C30: " | D30: 23.8 | E30: 0 | F30: 173 | H30: 1.836 | I30: 1.822 | J30: =IF(M30<>"",(H30-I30)/M30,"") -> 0.014 | K30: =(F30*(273.15+D30)/273.15)/(M30*N30) -> 7.5229508 | L30: MI_V3 | M30: =VLOOKUP(L30,[1]allgemein!$B$3:$C$13,2,FALSE) -> 1 | N30: 25 | O30: "
B31: 19C-0024Z | C31: " | D31: 24.8 | E31: 0.2 | F31: 173 | H31: 1.852 | I31: 1.837 | J31: =IF(M31<>"",(H31-I31)/M31,"") -> 0.015 | K31: =(F31*(273.15+D31)/273.15)/(M31*N31) -> 7.5482848 | L31: MI_V3 | M31: =VLOOKUP(L31,[1]allgemein!$B$3:$C$13,2,FALSE) -> 1 | N31: 25 | O31: "
B32: 19C-0025Z | C32: " | D32: 24.8 | E32: 0.2 | F32: 173 | H32: 1.849 | I32: 1.833 | J32: =IF(M32<>"",(H32-I32)/M32,"") -> 0.016 | K32: =(F32*(273.15+D32)/273.15)/(M32*N32) -> 7.5482848 | L32: MI_V3 | M32: =VLOOKUP(L32,[1]allgemein!$B$3:$C$13,2,FALSE) -> 1 | N32: 25 | O32: "
B33: 19C-0026Z | C33: " | D33: 24.7 | E33: 0.2 | F33: 173 | H33: 1.858 | I33: 1.842 | J33: =IF(M33<>"",(H33-I33)/M33,"") -> 0.016 | K33: =(F33*(273.15+D33)/273.15)/(M33*N33) -> 7.5457514 | L33: MI_V3 | M33: =VLOOKUP(L33,[1]allgemein!$B$3:$C$13,2,FALSE) -> 1 | N33: 25 | O33: "
B34: 19C-0027Z | C34: " | D34: 24.6 | E34: 0.2 | F34: 173 | H34: 1.854 | I34: 1.837 | J34: =IF(M34<>"",(H34-I34)/M34,"") -> 0.017 | K34: =(F34*(273.15+D34)/273.15)/(M34*N34) -> 7.543218 | L34: MI_V3 | M34: =VLOOKUP(L34,[1]allgemein!$B$3:$C$13,2,FALSE) -> 1 | N34: 25 | O34: "
B35: 19C-0028Z | C35: " | D35: 24.6 | E35: 0.1 | F35: 173 | H35: 1.865 | I35: 1.847 | J35: =IF(M35<>"",(H35-I35)/M35,"") -> 0.018 | K35: =(F35*(273.15+D35)/273.15)/(M35*N35) -> 7.543218 | L35: MI_V3 | M35: =VLOOKUP(L35,[1]allgemein!$B$3:$C$13,2,FALSE) -> 1 | N35: 25 | O35: "
B36: 19C-0029Z | C36: " | D36: 24.5 | E36: 0.1 | F36: 173 | H36: 1.856 | I36: 1.84 | J36: =IF(M36<>"",(H36-I36)/M36,"") -> 0.016 | K36: =(F36*(273.15+D36)/273.15)/(M36*N36) -> 7.5406846 | L36: MI_V3 | M36: =VLOOKUP(L36,[1]allgemein!$B$3:$C$13,2,FALSE) -> 1 | N36: 25 | O36: "
B37: 19C-0030Z | C37: " | D37: 24.3 | E37: 0 | F37: 173 | H37: 1.843 | I37: 1.827 | J37: =IF(M37<>"",(H37-I37)/M37,"") -> 0.016 | K37: =(F37*(273.15+D37)/273.15)/(M37*N37) -> 7.5356178 | L37: MI_V3 | M37: =VLOOKUP(L37,[1]allgemein!$B$3:$C$13,2,FALSE) -> 1 | N37: 25 | O37: "
... B44: 19C-0037Z | C44: " | D44: 24.3 | E44: 0 | F44: 173 | H44: 1.842 | I44: 1.825 | J44: =IF(M44<>"",(H44-I44)/M44,"") -> 0.017 | K44: =(F44*(273.15+D44)/273.15)/(M44*N44) -> 7.5356178 | L44: MI_V3 | M44: =VLOOKUP(L44,[1]allgemein!$B$3:$C$13,2,FALSE) -> 1 | N44: 25 | O44: FA505877
B45: 19C-0038Z | C45: 499724 | D45: 25.8 | E45: 0 | F45: 173 | H45: 1.842 | I45: 1.829 | J45: =IF(M45<>"",(H45-I45)/M45,"") -> 0.013 | K45: =(F45*(273.15+D45)/273.15)/(M45*N45) -> 7.5736189 | L45: MI_V3 | M45: =VLOOKUP(L45,[1]allgemein!$B$3:$C$13,2,FALSE) -> 1 | N45: 25 | O45: " | P45: O-Ring 7.1x1.6
B46: 19C-0039Z | C46: " | D46: 25.7 | E46: 0 | F46: 173 | H46: 1.833 | I46: 1.819 | J46: =IF(M46<>"",(H46-I46)/M46,"") -> 0.014 | K46: =(F46*(273.15+D46)/273.15)/(M46*N46) -> 7.5710855 | L46: MI_V3 | M46: =VLOOKUP(L46,[1]allgemein!$B$3:$C$13,2,FALSE) -> 1 | N46: 25 | O46: "
B47: 19C-0040Z | C47: " | D47: 25.6 | E47: 0 | F47: 173 | H47: 1.837 | I47: 1.823 | J47: =IF(M47<>"",(H47-I47)/M47,"") -> 0.014 | K47: =(F47*(273.15+D47)/273.15)/(M47*N47) -> 7.5685521 | L47: MI_V3 | M47: =VLOOKUP(L47,[1]allgemein!$B$3:$C$13,2,FALSE) -> 1 | N47: 25 | O47: "
B48: 19C-0041Z | C48: " | D48: 25.6 | E48: 0 | F48: 173 | H48: 1.832 | I48: 1.819 | J48: =IF(M48<>"",(H48-I48)/M48,"") -> 0.013 | K48: =(F48*(273.15+D48)/273.15)/(M48*N48) -> 7.5685521 | L48: MI_V3 | M48: =VLOOKUP(L48,[1]allgemein!$B$3:$C$13,2,FALSE) -> 1 | N48: 25 | O48: "
...

Sheet Apr
B3: Cell # | C3: Membran Batch FA | D3: Temp Gas / [°C] | E3: Temp Kat T1-T2 / [°C] | F3: Gasfluss / [sccm / min] | G3: Membrane V @ 13 bar/[V] | H3: Cell V @ 13 bar/[V] | I3: Cell V @ 0 bar [V] | J3: Voltage Diff. / [V] | K3: H2 Prod / [nmL/A] | L3: Typ | M3: Anzahl Layer | N3: Strom / [A] | O3: FA # | P3: Bemerkungen | Q3: Bemerkungen | S3: Visum | T3: Jahr: | U3: 2019
B4: 19D-0001Z | C4: 499724 | D4: 25.7 | E4: 0.1 | F4: 173 | H4: 1.859 | I4: 1.84 | J4: =IF(M4<>"",(H4-I4)/M4,"") -> 0.019 | K4: =(F4*(273.15+D4)/273.15)/(M4*N4) -> 7.5710855 | L4: MI_V3 | M4: =VLOOKUP(L4,[1]allgemein!$B$3:$C$13,2,FALSE) -> 1 | N4: 25 | O4: FA500555
B5: 19D-0002Z | C5: " | D5: 25.8 | E5: 0.2 | F5: 173 | H5: 1.85 | I5: 1.834 | J5: =IF(M5<>"",(H5-I5)/M5,"") -> 0.016 | K5: =(F5*(273.15+D5)/273.15)/(M5*N5) -> 7.5736189 | L5: MI_V3 | M5: =VLOOKUP(L5,[1]allgemein!$B$3:$C$13,2,FALSE) -> 1 | N5: 25 | O5: "
B6: 19D-0003Z | C6: " | D6: 25.8 | E6: 0.1 | F6: 173 | H6: 1.86 | I6: 1.845 | J6: =IF(M6<>"",(H6-I6)/M6,"") -> 0.015 | K6: =(F6*(273.15+D6)/273.15)/(M6*N6) -> 7.5736189 | L6: MI_V3 | M6: =VLOOKUP(L6,[1]allgemein!$B$3:$C$13,2,FALSE) -> 1 | N6: 25 | O6: "
B7: 19D-0004Z | C7: " | D7: 25.8 | E7: 0.2 | F7: 173 | H7: 1.85 | I7: 1.835 | J7: =IF(M7<>"",(H7-I7)/M7,"") -> 0.015 | K7: =(F7*(273.15+D7)/273.15)/(M7*N7) -> 7.5736189 | L7: MI_V3 | M7: =VLOOKUP(L7,[1]allgemein!$B$3:$C$13,2,FALSE) -> 1 | N7: 25 | O7: "
B8: 19D-0005Z | C8: " | D8: 25.8 | E8: 0.2 | F8: 173 | H8: 1.855 | I8: 1.838 | J8: =IF(M8<>"",(H8-I8)/M8,"") -> 0.017 | K8: =(F8*(273.15+D8)/273.15)/(M8*N8) -> 7.5736189 | L8: MI_V3 | M8: =VLOOKUP(L8,[1]allgemein!$B$3:$C$13,2,FALSE) -> 1 | N8: 25 | O8: "
B9: 19D-0006Z | C9: " | D9: 25.8 | E9: 0.2 | F9: 173 | H9: 1.856 | I9: 1.843 | J9: =IF(M9<>"",(H9-I9)/M9,"") -> 0.013 | K9: =(F9*(273.15+D9)/273.15)/(M9*N9) -> 7.5736189 | L9: MI_V3 | M9: =VLOOKUP(L9,[1]allgemein!$B$3:$C$13,2,FALSE) -> 1 | N9: 25 | O9: "
B10: 19D-0007Z | C10: " | D10: 25.8 | E10: 0.2 | F10: 173 | H10: 1.866 | I10: 1.849 | J10: =IF(M10<>"",(H10-I10)/M10,"") -> 0.017 | K10: =(F10*(273.15+D10)/273.15)/(M10*N10) -> 7.5736189 | L10: MI_V3 | M10: =VLOOKUP(L10,[1]allgemein!$B$3:$C$13,2,FALSE) -> 1 | N10: 25 | O10: "
B11: 19D-0008Z | C11: " | D11: 25.9 | E11: 0.3 | F11: 173 | H11: 1.86 | I11: 1.842 | J11: =IF(M11<>"",(H11-I11)/M11,"") -> 0.018 | K11: =(F11*(273.15+D11)/273.15)/(M11*N11) -> 7.5761523 | L11: MI_V3 | M11: =VLOOKUP(L11,[1]allgemein!$B$3:$C$13,2,FALSE) -> 1 | N11: 25 | O11: "
B12: 19D-0009Z | C12: " | D12: 25.9 | E12: 0.2 | F12: 173 | H12: 1.865 | I12: 1.846 | J12: =IF(M12<>"",(H12-I12)/M12,"") -> 0.019 | K12: =(F12*(273.15+D12)/273.15)/(M12*N12) -> 7.5761523 | L12: MI_V3 | M12: =VLOOKUP(L12,[1]allgemein!$B$3:$C$13,2,FALSE) -> 1 | N12: 25 | O12: "
B13: 19D-0010Z | C13: 499725 | D13: 25.8 | E13: 0.2 | F13: 173 | H13: 1.86 | I13: 1.848 | J13: =IF(M13<>"",(H13-I13)/M13,"") -> 0.012 | K13: =(F13*(273.15+D13)/273.15)/(M13*N13) -> 7.5736189 | L13: MI_V3 | M13: =VLOOKUP(L13,[1]allgemein!$B$3:$C$13,2,FALSE) -> 1 | N13: 25 | O13: FA512225
B14: 19D-0011Z | C14: " | D14: 25.1 | E14: 0 | F14: 173 | H14: 1.85 | I14: 1.836 | J14: =IF(M14<>"",(H14-I14)/M14,"") -> 0.014 | K14: =(F14*(273.15+D14)/273.15)/(M14*N14) -> 7.555885 | L14: MI_V3 | M14: =VLOOKUP(L14,[1]allgemein!$B$3:$C$13,2,FALSE) -> 1 | N14: 25 | O14: "
B15: 19D-0012Z | C15: " | D15: 25.1 | E15: 0 | F15: 173 | H15: 1.848 | I15: 1.833 | J15: =IF(M15<>"",(H15-I15)/M15,"") -> 0.015 | K15: =(F15*(273.15+D15)/273.15)/(M15*N15) -> 7.555885 | L15: MI_V3 | M15: =VLOOKUP(L15,[1]allgemein!$B$3:$C$13,2,FALSE) -> 1 | N15: 25 | O15: "
B16: 19D-0013Z | C16: " | D16: 25.1 | E16: 0 | F16: 173 | H16: 1.841 | I16: 1.827 | J16: =IF(M16<>"",(H16-I16)/M16,"") -> 0.014 | K16: =(F16*(273.15+D16)/273.15)/(M16*N16) -> 7.555885 | L16: MI_V3 | M16: =VLOOKUP(L16,[1]allgemein!$B$3:$C$13,2,FALSE) -> 1 | N16: 25 | O16: "
B17: 19D-0014Z | C17: " | D17: 25.2 | E17: 0 | F17: 173 | H17: 1.841 | I17: 1.828 | J17: =IF(M17<>"",(H17-I17)/M17,"") -> 0.013 | K17: =(F17*(273.15+D17)/273.15)/(M17*N17) -> 7.5584185 | L17: MI_V3 | M17: =VLOOKUP(L17,[1]allgemein!$B$3:$C$13,2,FALSE) -> 1 | N17: 25 | O17: "
B18: 19D-0015Z | C18: " | D18: 25.5 | E18: 0 | F18: 173 | H18: 1.835 | I18: 1.819 | J18: =IF(M18<>"",(H18-I18)/M18,"") -> 0.016 | K18: =(F18*(273.15+D18)/273.15)/(M18*N18) -> 7.5660187 | L18: MI_V3 | M18: =VLOOKUP(L18,[1]allgemein!$B$3:$C$13,2,FALSE) -> 1 | N18: 25 | O18: "
B19: 19D-0016Z | C19: " | D19: 25.5 | E19: 0 | F19: 173 | H19: 1.829 | I19: 1.815 | J19: =IF(M19<>"",(H19-I19)/M19,"") -> 0.014 | K19: =(F19*(273.15+D19)/273.15)/(M19*N19) -> 7.5660187 | L19: MI_V3 | M19: =VLOOKUP(L19,[1]allgemein!$B$3:$C$13,2,FALSE) -> 1 | N19: 25 | O19: "
B20: 19D-0017Z | C20: " | D20: 25.5 | E20: 0 | F20: 173 | H20: 1.827 | I20: 1.812 | J20: =IF(M20<>"",(H20-I20)/M20,"") -> 0.015 | K20: =(F20*(273.15+D20)/273.15)/(M20*N20) -> 7.5660187 | L20: MI_V3 | M20: =VLOOKUP(L20,[1]allgemein!$B$3:$C$13,2,FALSE) -> 1 | N20: 25 | O20: "
B21: 19D-0018Z | C21: " | D21: 25.5 | E21: 0 | F21: 173 | H21: 1.836 | I21: 1.823 | J21: =IF(M21<>"",(H21-I21)/M21,"") -> 0.013 | K21: =(F21*(273.15+D21)/273.15)/(M21*N21) -> 7.5660187 | L21: MI_V3 | M21: =VLOOKUP(L21,[1]allgemein!$B$3:$C$13,2,FALSE) -> 1 | N21: 25 | O21: "
B22: 19D-0019Z | C22: " | D22: 25.4 | E22: 0 | F22: 173 | H22: 1.815 | I22: 1.802 | J22: =IF(M22<>"",(H22-I22)/M22,"") -> 0.013 | K22: =(F22*(273.15+D22)/273.15)/(M22*N22) -> 7.5634853 | L22: MI_V3 | M22: =VLOOKUP(L22,[1]allgemein!$B$3:$C$13,2,FALSE) -> 1 | N22: 25 | O22: "
B23: 19D-0020Z | C23: " | D23: 25.3 | E23: 0.1 | F23: 173 | H23: 1.865 | I23: 1.852 | J23: =IF(M23<>"",(H23-I23)/M23,"") -> 0.013 | K23: =(F23*(273.15+D23)/273.15)/(M23*N23) -> 7.5609519 | L23: MI_V3 | M23: =VLOOKUP(L23,[1]allgemein!$B$3:$C$13,2,FALSE) -> 1 | N23: 25 | O23: "
B24: 19D-0021Z | C24: " | D24: 25.3 | E24: 0.1 | F24: 173 | H24: 1.851 | I24: 1.837 | J24: =IF(M24<>"",(H24-I24)/M24,"") -> 0.014 | K24: =(F24*(273.15+D24)/273.15)/(M24*N24) -> 7.5609519 | L24: MI_V3 | M24: =VLOOKUP(L24,[1]allgemein!$B$3:$C$13,2,FALSE) -> 1 | N24: 25 | O24: "
B25: 19D-0022Z | C25: " | D25: 25.3 | E25: 0 | F25: 173 | H25: 1.855 | I25: 1.839 | J25: =IF(M25<>"",(H25-I25)/M25,"") -> 0.016 | K25: =(F25*(273.15+D25)/273.15)/(M25*N25) -> 7.5609519 | L25: MI_V3 | M25: =VLOOKUP(L25,[1]allgemein!$B$3:$C$13,2,FALSE) -> 1 | N25: 25 | O25: "
... B30: 19D-0027Z | C30: " | D30: 25.2 | E30: 0 | F30: 173 | H30: 1.863 | I30: 1.85 | J30: =IF(M30<>"",(H30-I30)/M30,"") -> 0.013 | K30: =(F30*(273.15+D30)/273.15)/(M30*N30) -> 7.5584185 | L30: MI_V3 | M30: =VLOOKUP(L30,[1]allgemein!$B$3:$C$13,2,FALSE) -> 1 | N30: 25 | O30: "
B31: 19D-0028Z | C31: 499726 | D31: 25.3 | E31: 0.1 | F31: 859 | G31: 1.811 | H31: 5.439 | I31: 5.391 | J31: =IF(M31<>"",(H31-I31)/M31,"") -> 0.016 | K31: =(F31*(273.15+D31)/273.15)/(M31*N31) -> 7.8213604 | L31: MU3 | M31: =VLOOKUP(L31,[1]allgemein!$B$3:$C$13,2,FALSE) -> 3 | N31: 40 | O31: FA513218
C32: " | G32: 1.812 | J32: =IF(M32<>"",(H32-I32)/M32,"")
C33: " | G33: 1.816 | J33: =IF(M33<>"",(H33-I33)/M33,"")
B34: 19D-0029Z | C34: " | D34: 25.2 | E34: 0.3 | F34: 859 | G34: 1.815 | H34: 5.425 | I34: 5.378 | J34: =IF(M34<>"",(H34-I34)/M34,"") -> 0.015666667 | K34: =(F34*(273.15+D34)/273.15)/(M34*N34) -> 7.8187397 | L34: MU3 | M34: =VLOOKUP(L34,[1]allgemein!$B$3:$C$13,2,FALSE) -> 3 | N34: 40 | O34: "
C35: 496337 | G35: 1.802 | J35: =IF(M35<>"",(H35-I35)/M35,"")
C36: " | G36: 1.808 | J36: =IF(M36<>"",(H36-I36)/M36,"")
B37: 19D-0030Z | C37: " | D37: 25.1 | E37: 0.2 | F37: 858 | G37: 1.805 | H37: 5.413 | I37: 5.371 | J37: =IF(M37<>"",(H37-I37)/M37,"") -> 0.014 | K37: =(F37*(273.15+D37)/273.15)/(M37*N37) -> 7.80702 | L37: MU3 | M37: =VLOOKUP(L37,[1]allgemein!$B$3:$C$13,2,FALSE) -> 3 | N37: 40 | O37: "
C38: " | G38: 1.807 | J38: =IF(M38<>"",(H38-I38)/M38,"")
C39: " | G39: 1.801 | J39: =IF(M39<>"",(H39-I39)/M39,"")
B40: 19D-0031Z | C40: 499926 | D40: 25.5 | E40: 0.4 | F40: 281 | H40: 1.838 | I40: 1.8222 | J40: =IF(M40<>"",(H40-I40)/M40,"") -> 0.0158 | K40: =(F40*(273.15+D40)/273.15)/(M40*N40) -> 7.680821 | L40: MU1 | M40: =VLOOKUP(L40,[1]allgemein!$B$3:$C$13,2,FALSE) -> 1 | N40: 40 | O40: FA513217 | P40: Mem. mit def. Filterplatte
B41: 19D-0032Z | C41: " | D41: 25.6 | E41: 0.6 | F41: 281 | H41: 1.828 | I41: 1.81 | J41: =IF(M41<>"",(H41-I41)/M41,"") -> 0.018 | K41: =(F41*(273.15+D41)/273.15)/(M41*N41) -> 7.6833928 | L41: MU1 | M41: =VLOOKUP(L41,[1]allgemein!$B$3:$C$13,2,FALSE) -> 1 | N41: 40 | O41: " | P41: "
B42: 19D-0033Z | C42: " | D42: 25.5 | E42: 0.8 | F42: 281 | H42: 1.824 | I42: 1.807 | J42: =IF(M42<>"",(H42-I42)/M42,"") -> 0.017 | K42: =(F42*(273.15+D42)/273.15)/(M42*N42) -> 7.680821 | L42: MU1 | M42: =VLOOKUP(L42,[1]allgemein!$B$3:$C$13,2,FALSE) -> 1 | N42: 40 | O42: " | P42: "
B43: 19D-0034Z-R | C43: " | D43: 25.2 | E43: 0.2 | F43: 279 | H43: 1.881 | I43: 1.868 | J43: =IF(M43<>"",(H43-I43)/M43,"") -> 0.013 | K43: =(F43*(273.15+D43)/273.15)/(M43*N43) -> 7.6184926 | L43: MA_V1 | M43: =VLOOKUP(L43,[1]allgemein!$B$3:$C$13,2,FALSE) -> 1 | N43: 40 | O43: FA512218 | P43: "
B44: 19D-0035Z | C44: " | D44: 25.5 | E44: 0.4 | F44: 281 | H44: 1.853 | I44: 1.834 | J44: =IF(M44<>"",(H44-I44)/M44,"") -> 0.019 | K44: =(F44*(273.15+D44)/273.15)/(M44*N44) -> 7.680821 | L44: MU1 | M44: =VLOOKUP(L44,[1]allgemein!$B$3:$C$13,2,FALSE) -> 1 | N44: 40 | O44: FA513228 | P44: "
B45: 19D-0036Z | C45: " | D45: 25.3 | E45: 0.1 | F45: 281 | H45: 1.847 | I45: 1.825 | J45: =IF(M45<>"",(H45-I45)/M45,"") -> 0.022 | K45: =(F45*(273.15+D45)/273.15)/(M45*N45) -> 7.6756773 | L45: MU1 | M45: =VLOOKUP(L45,[1]allgemein!$B$3:$C$13,2,FALSE) -> 1 | N45: 40 | O45: " | P45: "
B46: 19D-0037Z | C46: " | D46: 25.2 | E46: 0.2 | F46: 282 | H46: 1.831 | I46: 1.814 | J46: =IF(M46<>"",(H46-I46)/M46,"") -> 0.017 | K46: =(F46*(273.15+D46)/273.15)/(M46*N46) -> 7.7004119 | L46: MU1 | M46: =VLOOKUP(L46,[1]allgemein!$B$3:$C$13,2,FALSE) -> 1 | N46: 40 | O46: " | P46: "
...

Sheet May
B1: Cell # | C1: Membran Batch FA | D1: Temp Gas / [°C] | E1: Temp Kat T1-T2 / [°C] | F1: Gasfluss / [sccm / min] | G1: Membrane V @ 13 bar/[V] | H1: Cell V @ 13 bar/[V] | I1: Cell V @ 0 bar [V] | J1: Voltage Diff. / [V] | K1: H2 Prod / [nmL/A] | L1: Typ | M1: Anz. Layer | N1: Strom / [A] | O1: FA # | Q1: Bemerkungen | R1: Bemerkungen | T1: Visum | U1: Jahr: | V1: 2019
B2: 19E-0001Z | C2: 499727 | D2: 25.9 | E2: 0.4 | F2: 569 | G2: 1.829 | H2: 3.667 | I2: 3.631 | J2: =IF(M2<>"",(H2-I2)/M2,"") -> 0.018 | K2: =(F2*(273.15+D2)/273.15)/(M2*N2) -> 7.7869051 | L2: MU2 | M2: =VLOOKUP(L2,[1]allgemein!$B$3:$C$13,2,FALSE) -> 2 | N2: 40 | O2: FA516491
C3: " | G3: 1.838
B4: 19E-0002Z | C4: " | D4: 25.8 | E4: 0.3 | F4: 569 | G4: 1.824 | H4: 3.654 | I4: 3.619 | J4: =IF(M4<>"",(H4-I4)/M4,"") -> 0.0175 | K4: =(F4*(273.15+D4)/273.15)/(M4*N4) -> 7.7843012 | L4: MU2 | M4: =VLOOKUP(L4,[1]allgemein!$B$3:$C$13,2,FALSE) -> 2 | N4: 40 | O4: "
C5: " | G5: 1.83
B6: 19E-0003Z | C6: " | D6: 25.6 | E6: 0.3 | F6: 569 | G6: 1.843 | H6: 3.684 | I6: 3.65 | J6: =IF(M6<>"",(H6-I6)/M6,"") -> 0.017 | K6: =(F6*(273.15+D6)/273.15)/(M6*N6) -> 7.7790934 | L6: MU2 | M6: =VLOOKUP(L6,[1]allgemein!$B$3:$C$13,2,FALSE) -> 2 | N6: 40 | O6: "
C7: " | G7: 1.841
B8: 19E-0004Z | C8: " | D8: 25.6 | E8: 0.2 | F8: 568 | G8: 1.835 | H8: 3.676 | I8: 3.64 | J8: =IF(M8<>"",(H8-I8)/M8,"") -> 0.018 | K8: =(F8*(273.15+D8)/273.15)/(M8*N8) -> 7.7654219 | L8: MU2 | M8: =VLOOKUP(L8,[1]allgemein!$B$3:$C$13,2,FALSE) -> 2 | N8: 40 | O8: "
C9: " | G9: 1.841
B10: 19E-0005Z | C10: " | D10: 26.3 | E10: 1.3 | F10: 860 | G10: 1.826 | H10: 5.465 | I10: 5.415 | J10: =IF(M10<>"",(H10-I10)/M10,"") -> 0.016666667 | K10: =(F10*(273.15+D10)/273.15)/(M10*N10) -> 7.8567027 | L10: MU3 | M10: =VLOOKUP(L10,[1]allgemein!$B$3:$C$13,2,FALSE) -> 3 | N10: 40 | O10: FA516492
C11: " | G11: 1.817
C12: " | G12: 1.822
B13: 19E-0006Z | C13: " | D13: 26.4 | E13: 0.5 | F13: 282 | H13: 1.825 | I13: 1.804 | J13: =IF(M13<>"",(H13-I13)/M13,"") -> 0.021 | K13: =(F13*(273.15+D13)/273.15)/(M13*N13) -> 7.7313839 | L13: MU1 | M13: =VLOOKUP(L13,[1]allgemein!$B$3:$C$13,2,FALSE) -> 1 | N13: 40 | O13: FA516490
B14: 19E-0007Z | C14: " | D14: 26.4 | E14: 0.5 | F14: 281 | H14: 1.827 | I14: 1.81 | J14: =IF(M14<>"",(H14-I14)/M14,"") -> 0.017 | K14: =(F14*(273.15+D14)/273.15)/(M14*N14) -> 7.7039676 | L14: MU1 | M14: =VLOOKUP(L14,[1]allgemein!$B$3:$C$13,2,FALSE) -> 1 | N14: 40 | O14: " | Q14: Mem. leicht transp. Stellen
B15: 19E-0008Z | C15: " | D15: 26.4 | E15: 0.6 | F15: 281 | H15: 1.825 | I15: 1.807 | J15: =IF(M15<>"",(H15-I15)/M15,"") -> 0.018 | K15: =(F15*(273.15+D15)/273.15)/(M15*N15) -> 7.7039676 | L15: MU1 | M15: =VLOOKUP(L15,[1]allgemein!$B$3:$C$13,2,FALSE) -> 1 | N15: 40 | O15: "
B16: 19E-0009Z | C16: " | D16: 26.3 | E16: 0.9 | F16: 281 | H16: 1.824 | I16: 1.806 | J16: =IF(M16<>"",(H16-I16)/M16,"") -> 0.018 | K16: =(F16*(273.15+D16)/273.15)/(M16*N16) -> 7.7013958 | L16: MU1 | M16: =VLOOKUP(L16,[1]allgemein!$B$3:$C$13,2,FALSE) -> 1 | N16: 40 | O16: "
B17: 19E-0010Z | C17: " | D17: 26.5 | E17: 3.3 | F17: 281 | H17: 1.833 | I17: 1.816 | J17: =IF(M17<>"",(H17-I17)/M17,"") -> 0.017 | K17: =(F17*(273.15+D17)/273.15)/(M17*N17) -> 7.7065394 | L17: MU1 | M17: =VLOOKUP(L17,[1]allgemein!$B$3:$C$13,2,FALSE) -> 1 | N17: 40 | O17: "
B18: 19E-0011Z | C18: 499727 | D18: 26.2 | E18: 0.5 | F18: 1148 | G18: 1.819 | H18: 7.252 | I18: 7.18 | J18: =IF(M18<>"",(H18-I18)/M18,"") -> 0.018 | K18: =(F18*(273.15+D18)/273.15)/(M18*N18) -> 7.8632116 | L18: MU4 | M18: =VLOOKUP(L18,[1]allgemein!$B$3:$C$13,2,FALSE) -> 4 | N18: 40 | O18: FA511099
C19: 499727 | G19: 1.808
C20: " | G20: 1.811
C21: " | G21: 1.814
B22: 19E-0012Z | C22: " | D22: 26.2 | E22: 0.7 | F22: 857 | G22: 1.801 | H22: 5.401 | I22: 5.364 | J22: =IF(M22<>"",(H22-I22)/M22,"") -> 0.012333333 | K22: =(F22*(273.15+D22)/273.15)/(M22*N22) -> 7.826681 | L22: MU3 | M22: =VLOOKUP(L22,[1]allgemein!$B$3:$C$13,2,FALSE) -> 3 | N22: 40 | O22: FA502986
C23: " | G23: 1.795
C24: " | G24: 1.805
B25: 19E-0013Z | C25: " | D25: 25.9 | E25: 0.4 | F25: 857 | G25: 1.806 | H25: 5.422 | I25: 5.379 | J25: =IF(M25<>"",(H25-I25)/M25,"") -> 0.014333333 | K25: =(F25*(273.15+D25)/273.15)/(M25*N25) -> 7.8188373 | L25: MU3 | M25: =VLOOKUP(L25,[1]allgemein!$B$3:$C$13,2,FALSE) -> 3 | N25: 40
C26: " | G26: 1.809
C27: " | G27: 1.807
B28: 19E-0014Z | C28: 500951 | D28: 25.6 | E28: 0.3 | F28: 857 | G28: 1.802 | H28: 5.407 | I28: 5.361 | J28: =IF(M28<>"",(H28-I28)/M28,"") -> 0.015333333 | K28: =(F28*(273.15+D28)/273.15)/(M28*N28) -> 7.8109937 | L28: MU3 | M28: =VLOOKUP(L28,[1]allgemein!$B$3:$C$13,2,FALSE) -> 3 | N28: 40
C29: " | G29: 1.804
C30: " | G30: 1.801
B31: 19E-0015Z | C31: " | D31: 25.4 | E31: 0.4 | F31: 857 | G31: 1.799 | H31: 5.397 | I31: 5.35 | J31: =IF(M31<>"",(H31-I31)/M31,"") -> 0.015666667 | K31: =(F31*(273.15+D31)/273.15)/(M31*N31) -> 7.8057645 | L31: MU3 | M31: =VLOOKUP(L31,[1]allgemein!$B$3:$C$13,2,FALSE) -> 3 | N31: 40
C32: " | G32: 1.798
C33: " | G33: 1.8
B34: 19E-0016Z | C34: " | D34: 25.3 | E34: 0.3 | F34: 857 | G34: 1.811 | H34: 5.411 | I34: 5.369 | J34: =IF(M34<>"",(H34-I34)/M34,"") -> 0.014 | K34: =(F34*(273.15+D34)/273.15)/(M34*N34) -> 7.80315 | L34: MU3 | M34: =VLOOKUP(L34,[1]allgemein!$B$3:$C$13,2,FALSE) -> 3 | N34: 40
C35: " | G35: 1.798
C36: " | G36: 1.802
B37: 19E-0017Z | C37: 499726 | D37: 25.3 | E37: 0.1 | F37: 281 | H37: 1.814 | I37: 1.795 | J37: =IF(M37<>"",(H37-I37)/M37,"") -> 0.019 | K37: =(F37*(273.15+D37)/273.15)/(M37*N37) -> 7.6756773 | L37: MU1 | M37: =VLOOKUP(L37,[1]allgemein!$B$3:$C$13,2,FALSE) -> 1 | N37: 40 | O37: FA517454
B38: 19E-0018Z | C38: 500951 | D38: 25.9 | E38: 0.3 | F38: 858 | G38: 1.808 | H38: 5.415 | I38: 5.367 | J38: =IF(M38<>"",(H38-I38)/M38,"") -> 0.016 | K38: =(F38*(273.15+D38)/273.15)/(M38*N38) -> 7.8279608 | L38: MU3 | M38: =VLOOKUP(L38,[1]allgemein!$B$3:$C$13,2,FALSE) -> 3 | N38: 40 | O38: FA505880
C39: " | G39: 1.801
C40: " | G40: 1.806 | Q40: Mem. kl. Kratzer
...

Sheet Jun
B1: Cell # | C1: Membran Batch FA | D1: Temp Gas / [°C] | E1: Temp Kat T1-T2 / [°C] | F1: Gasfluss / [sccm / min] | G1: Membrane V @ 13 bar/[V] | H1: Cell V @ 13 bar/[V] | I1: Cell V @ 0 bar [V] | J1: Voltage Diff. / [V] | K1: H2 Prod / [nmL/A] | L1: Typ | M1: Anz. Layer | N1: Strom / [A] | O1: FA # | Q1: Bemerkungen | R1: Bemerkungen | T1: Visum | U1: Jahr: | V1: 2019
B2: 19F-0001Z-R | C2: 503924 | D2: 26.8 | E2: 0.1 | F2: 173 | H2: 1.842 | I2: 1.829 | J2: =IF(M2<>"",(H2-I2)/M2,"") -> 0.013 | K2: =(F2*(273.15+D2)/273.15)/(M2*N2) -> 7.598953 | L2: MI_V3 | M2: =VLOOKUP(L2,[1]allgemein!$B$3:$C$13,2,FALSE) -> 1 | N2: 25 | O2: FA518657 | Q2: ersetzt: NV1407-2020
B3: 19F-0002Z-R | C3: " | D3: 26.7 | E3: 0.1 | F3: 173 | H3: 1.852 | I3: 1.84 | J3: =IF(M3<>"",(H3-I3)/M3,"") -> 0.012 | K3: =(F3*(273.15+D3)/273.15)/(M3*N3) -> 7.5964195 | L3: MI_V3 | M3: =VLOOKUP(L3,[1]allgemein!$B$3:$C$13,2,FALSE) -> 1 | N3: 25 | O3: FA518658 | Q3: ersetzt: 16J-0009Z-R
B4: 19F-0003Z | C4: " | D4: 25.8 | E4: 0 | F4: 173 | H4: 1.864 | I4: 1.85 | J4: =IF(M4<>"",(H4-I4)/M4,"") -> 0.014 | K4: =(F4*(273.15+D4)/273.15)/(M4*N4) -> 7.5736189 | L4: MI_V3 | M4: =VLOOKUP(L4,[1]allgemein!$B$3:$C$13,2,FALSE) -> 1 | N4: 25 | O4: FA496363
B5: 19F-0004Z | C5: " | D5: 25.7 | E5: 0 | F5: 173 | H5: 1.851 | I5: 1.836 | J5: =IF(M5<>"",(H5-I5)/M5,"") -> 0.015 | K5: =(F5*(273.15+D5)/273.15)/(M5*N5) -> 7.5710855 | L5: MI_V3 | M5: =VLOOKUP(L5,[1]allgemein!$B$3:$C$13,2,FALSE) -> 1 | N5: 25 | O5: "
B6: 19F-0005Z | C6: " | D6: 25.6 | E6: 0 | F6: 173 | H6: 1.867 | I6: 1.853 | J6: =IF(M6<>"",(H6-I6)/M6,"") -> 0.014 | K6: =(F6*(273.15+D6)/273.15)/(M6*N6) -> 7.5685521 | L6: MI_V3 | M6: =VLOOKUP(L6,[1]allgemein!$B$3:$C$13,2,FALSE) -> 1 | N6: 25 | O6: "
B7: 19F-0006Z | C7: " | D7: 25.5 | E7: 0 | F7: 173 | H7: 1.861 | I7: 1.849 | J7: =IF(M7<>"",(H7-I7)/M7,"") -> 0.012 | K7: =(F7*(273.15+D7)/273.15)/(M7*N7) -> 7.5660187 | L7: MI_V3 | M7: =VLOOKUP(L7,[1]allgemein!$B$3:$C$13,2,FALSE) -> 1 | N7: 25 | O7: "
B8: 19F-0007Z | C8: 503927 | D8: 26.7 | E8: 0 | F8: 569 | G8: 1.866 | H8: 3.729 | I8: 3.696 | J8: =IF(M8<>"",(H8-I8)/M8,"") -> 0.0165 | K8: =(F8*(273.15+D8)/273.15)/(M8*N8) -> 7.8077361 | L8: MU2 | M8: =VLOOKUP(L8,[1]allgemein!$B$3:$C$13,2,FALSE) -> 2 | N8: 40 | O8: FA514869
C9: " | G9: 1.863 | P9: *
B10: 19F-0008Z | C10: " | D10: 26.6 | E10: 0 | F10: 569 | G10: 1.867 | H10: 3.736 | I10: 3.705 | J10: =IF(M10<>"",(H10-I10)/M10,"") -> 0.0155 | K10: =(F10*(273.15+D10)/273.15)/(M10*N10) -> 7.8051323 | L10: MU2 | M10: =VLOOKUP(L10,[1]allgemein!$B$3:$C$13,2,FALSE) -> 2 | N10: 40 | O10: "
C11: " | G11: 1.869 | P11: *
B12: 19F-0009Z | C12: 501546 | D12: 27.1 | E12: 0 | F12: 567 | G12: 1.825 | H12: 3.656 | I12: 3.628 | J12: =IF(M12<>"",(H12-I12)/M12,"") -> 0.014 | K12: =(F12*(273.15+D12)/273.15)/(M12*N12) -> 7.7906713 | L12: MU2 | M12: =VLOOKUP(L12,[1]allgemein!$B$3:$C$13,2,FALSE) -> 2 | N12: 40 | O12: "
C13: " | G13: 1.831 | P13: *
B14: 19F-0010Z | C14: " | D14: 26.7 | E14: 0 | F14: 568 | G14: 1.861 | H14: 3.702 | I14: 3.67 | J14: =IF(M14<>"",(H14-I14)/M14,"") -> 0.016 | K14: =(F14*(273.15+D14)/273.15)/(M14*N14) -> 7.7940143 | L14: MU2 | M14: =VLOOKUP(L14,[1]allgemein!$B$3:$C$13,2,FALSE) -> 2 | N14: 40 | O14: "
C15: " | G15: 1.841 | P15: *
B16: 19F-0011Z-R | C16: 503927 | D16: 26.8 | E16: 0 | F16: 281 | H16: 1.868 | I16: 1.842 | J16: =IF(M16<>"",(H16-I16)/M16,"") -> 0.026 | K16: =(F16*(273.15+D16)/273.15)/(M16*N16) -> 7.714255 | L16: MU1 | M16: =VLOOKUP(L16,[1]allgemein!$B$3:$C$13,2,FALSE) -> 1 | N16: 40 | O16: FA519559 | Q16: Revision: M1-1603-053
B17: 19F-0012Z-R | C17: 512136 | D17: 26.5 | E17: 0 | F17: 279 | H17: 1.901 | I17: 1.887 | J17: =IF(M17<>"",(H17-I17)/M17,"") -> 0.014 | K17: =(F17*(273.15+D17)/273.15)/(M17*N17) -> 7.6516886 | L17: MA_V1 | M17: =VLOOKUP(L17,[1]allgemein!$B$3:$C$13,2,FALSE) -> 1 | N17: 40 | O17: FA519560 | Q17: nur O-seitig TeflonDichtung (Anord. C.S.)/ Vlies DB-10436;Stützring ø92.4
B18: 19F-0013Z-R | C18: " | D18: 26.4 | E18: 0 | F18: 279 | H18: 1.895 | I18: 1.881 | J18: =IF(M18<>"",(H18-I18)/M18,"") -> 0.014 | K18: =(F18*(273.15+D18)/273.15)/(M18*N18) -> 7.6491351 | L18: MA_V1 | M18: =VLOOKUP(L18,[1]allgemein!$B$3:$C$13,2,FALSE) -> 1 | N18: 40 | O18: " | Q18: "
B19: 19F-0014Z-R | C19: " | D19: 26.2 | E19: 0.2 | F19: 274 | H19: 1.921 | I19: 1.908 | J19: =IF(M19<>"",(H19-I19)/M19,"") -> 0.013 | K19: =(F19*(273.15+D19)/273.15)/(M19*N19) -> 7.5070383 | L19: MA_V1 | M19: =VLOOKUP(L19,[1]allgemein!$B$3:$C$13,2,FALSE) -> 1 | N19: 40 | O19: FA510926 | Q19: " | R19: LeckTest i. O./ Abspr. S.B.,C.S. i.O.
B20: 19F-0015Z-R | C20: " | D20: 26.1 | E20: 0 | F20: 280 | H20: 1.912 | I20: 1.897 | J20: =IF(M20<>"",(H20-I20)/M20,"") -> 0.015 | K20: =(F20*(273.15+D20)/273.15)/(M20*N20) -> 7.6688633 | L20: MA_V1 | M20: =VLOOKUP(L20,[1]allgemein!$B$3:$C$13,2,FALSE) -> 1 | N20: 40 | O20: " | Q20: "
B21: 19F-0016Z-R | C21: " | D21: 25.9 | E21: 0 | F21: 280 | H21: 1.904 | I21: 1.89 | J21: =IF(M21<>"",(H21-I21)/M21,"") -> 0.014 | K21: =(F21*(273.15+D21)/273.15)/(M21*N21) -> 7.6637379 | L21: MA_V1 | M21: =VLOOKUP(L21,[1]allgemein!$B$3:$C$13,2,FALSE) -> 1 | N21: 40 | O21: " | Q21: "
B22: 19F-0017Z-R | C22: " | D22: 26.1 | E22: 0 | F22: 280 | H22: 1.898 | I22: 1.883 | J22: =IF(M22<>"",(H22-I22)/M22,"") -> 0.015 | K22: =(F22*(273.15+D22)/273.15)/(M22*N22) -> 7.6688633 | L22: MA_V1 | M22: =VLOOKUP(L22,[1]allgemein!$B$3:$C$13,2,FALSE) -> 1 | N22: 40 | O22: FA516561 | Q22: "
B23: 19F-0018Z-R | C23: " | D23: 27.7 | E23: 0 | F23: 279 | H23: 1.885 | I23: 1.868 | J23: =IF(M23<>"",(H23-I23)/M23,"") -> 0.017 | K23: =(F23*(273.15+D23)/273.15)/(M23*N23) -> 7.6823311 | L23: MA_V1 | M23: =VLOOKUP(L23,[1]allgemein!$B$3:$C$13,2,FALSE) -> 1 | N23: 40 | O23: FA514864 | Q23: "
B24: 19F-0019Z-R | C24: " | D24: 27.6 | E24: 0 | F24: 279 | H24: 1.89 | I24: 1.879 | J24: =IF(M24<>"",(H24-I24)/M24,"") -> 0.011 | K24: =(F24*(273.15+D24)/273.15)/(M24*N24) -> 7.6797776 | L24: MA_V1 | M24: =VLOOKUP(L24,[1]allgemein!$B$3:$C$13,2,FALSE) -> 1 | N24: 40 | O24: " | Q24: "
B25: 19F-0020Z-R | C25: " | D25: 27.5 | E25: 0 | F25: 278 | H25: 1.898 | I25: 1.886 | J25: =IF(M25<>"",(H25-I25)/M25,"") -> 0.012 | K25: =(F25*(273.15+D25)/273.15)/(M25*N25) -> 7.6497071 | L25: MA_V1 | M25: =VLOOKUP(L25,[1]allgemein!$B$3:$C$13,2,FALSE) -> 1 | N25: 40 | O25: FA518660 | Q25: " | R25: Mem. leicht transp. Stellen
B26: 19F-0021Z-R | C26: " | D26: 27.4 | E26: 0 | F26: 279 | H26: 1.895 | I26: 1.883 | J26: =IF(M26<>"",(H26-I26)/M26,"") -> 0.012 | K26: =(F26*(273.15+D26)/273.15)/(M26*N26) -> 7.6746705 | L26: MA_V1 | M26: =VLOOKUP(L26,[1]allgemein!$B$3:$C$13,2,FALSE) -> 1 | N26: 40 | O26: FA519558 | Q26: "
B27: 19F-0022Z-R | C27: " | D27: 27.3 | E27: 0 | F27: 279 | H27: 1.9 | I27: 1.889 | J27: =IF(M27<>"",(H27-I27)/M27,"") -> 0.011 | K27: =(F27*(273.15+D27)/273.15)/(M27*N27) -> 7.672117 | L27: MA_V1 | M27: =VLOOKUP(L27,[1]allgemein!$B$3:$C$13,2,FALSE) -> 1 | N27: 40 | O27: " | Q27: "
B28: 19F-0023Z | C28: " | D28: 25.6 | E28: 0 | F28: 566 | G28: 1.864 | H28: 3.73 | I28: 3.7 | J28: =IF(M28<>"",(H28-I28)/M28,"") -> 0.015 | K28: =(F28*(273.15+D28)/273.15)/(M28*N28) -> 7.7380789 | L28: MU2 | M28: =VLOOKUP(L28,[1]allgemein!$B$3:$C$13,2,FALSE) -> 2 | N28: 40 | O28: FA521383 | Q28: Mem. kleine Kratzer
C29: " | G29: 1.866 | P29: * | Q29: "
B30: 19F-0024Z | C30: " | D30: 25.4 | E30: 0 | F30: 566 | G30: 1.869 | H30: 3.741 | I30: 3.713 | J30: =IF(M30<>"",(H30-I30)/M30,"") -> 0.014 | K30: =(F30*(273.15+D30)/273.15)/(M30*N30) -> 7.7328986 | L30: MU2 | M30: =VLOOKUP(L30,[1]allgemein!$B$3:$C$13,2,FALSE) -> 2 | N30: 40 | O30: " | Q30: Mem. kleine Kratzer, kleine Pt Löcher
C31: " | G31: 1.872 | P31: * | Q31: "
B32: 19F-0025Z | C32: " | D32: 25 | E32: 0 | F32: 854 | G32: 1.818 | H32: 5.502 | I32: 5.458 | J32: =IF(M32<>"",(H32-I32)/M32,"") -> 0.014666667 | K32: =(F32*(273.15+D32)/273.15)/(M32*N32) -> 7.7680182 | L32: MU3 | M32: =VLOOKUP(L32,[1]allgemein!$B$3:$C$13,2,FALSE) -> 3 | N32: 40 | O32: FA521384
C33: " | G33: 1.813
C34: 503927 | G34: 1.871 | P34: *
B35: 19F-0026Z | C35: " | D35: 24.6 | E35: 0 | F35: 854 | G35: 1.881 | H35: 5.633 | I35: 5.594 | J35: =IF(M35<>"",(H35-I35)/M35,"") -> 0.013 | K35: =(F35*(273.15+D35)/273.15)/(M35*N35) -> 7.7575966 | L35: MU3 | M35: =VLOOKUP(L35,[1]allgemein!$B$3:$C$13,2,FALSE) -> 3 | N35: 40 | O35: "
C36: " | G36: 1.875
C37: " | G37: 1.877 | P37: *
B38: 19F-0027Z | C38: " | D38: 25.7 | E38: 0 | F38: 1142 | G38: 1.865 | H38: 7.461 | I38: 7.41 | J38: =IF(M38<>"",(H38-I38)/M38,"") -> 0.01275 | K38: =(F38*(273.15+D38)/273.15)/(M38*N38) -> 7.8090495 | L38: MU4 | M38: =VLOOKUP(L38,[1]allgemein!$B$3:$C$13,2,FALSE) -> 4 | N38: 40 | O38: FA518472 | P38: b
C39: " | G39: 1.866
C40: " | G40: 1.863
...

Sheet Jul
B1: Cell # | C1: Membran Batch FA | D1: Temp Gas / [°C] | E1: Temp Kat T1-T2 / [°C] | F1: Gasfluss / [mln / min] | G1: Membrane V @ 13 bar/[V] | H1: Cell V @ 13 bar/[V] | I1: Cell V @ 0 bar [V] | J1: Voltage Diff. / [V] | K1: H2 Prod / [nmL/A] | L1: Typ | M1: Anz. Layer | N1: Strom / [A] | O1: FA # | Q1: Bemerkungen | R1: Bemerkungen | T1: Visum | U1: Jahr: | V1: 2019
B2: 19G-0001Z | C2: 503925 | D2: 25.3 | E2: 0 | F2: 172 | H2: 1.846 | I2: 1.831 | J2: =IF(M2<>"",(H2-I2)/M2,"") -> 0.015 | K2: =(F2*(273.15+D2)/273.15)/(M2*N2) -> 7.5172469 | L2: MI_V3 | M2: =VLOOKUP(L2,[1]allgemein!$B$3:$C$13,2,FALSE) -> 1 | N2: 25 | O2: FA521319 | Q2: ok laut CS | T2: TH
B3: 19G-0002Z | C3: 503925 | D3: 25 | E3: 0.6 | F3: 172 | H3: 1.863 | I3: 1.84 | J3: =IF(M3<>"",(H3-I3)/M3,"") -> 0.023 | K3: =(F3*(273.15+D3)/273.15)/(M3*N3) -> 7.5096906 | L3: MI_V3 | M3: =VLOOKUP(L3,[1]allgemein!$B$3:$C$13,2,FALSE) -> 1 | N3: 25 | O3: " | Q3: ok laut CS | T3: TH
B4: 19G-0003Z | C4: 503925 | D4: 24.9 | E4: 0.6 | F4: 172 | H4: 1.852 | I4: 1.839 | J4: =IF(M4<>"",(H4-I4)/M4,"") -> 0.013 | K4: =(F4*(273.15+D4)/273.15)/(M4*N4) -> 7.5071719 | L4: MI_V3 | M4: =VLOOKUP(L4,[1]allgemein!$B$3:$C$13,2,FALSE) -> 1 | N4: 25 | O4: " | Q4: ok laut CS | T4: TH
B5: 19G-0004Z | C5: 503925 | D5: 24.9 | E5: 0 | F5: 172 | H5: 1.846 | I5: 1.836 | J5: =IF(M5<>"",(H5-I5)/M5,"") -> 0.01 | K5: =(F5*(273.15+D5)/273.15)/(M5*N5) -> 7.5071719 | L5: MI_V3 | M5: =VLOOKUP(L5,[1]allgemein!$B$3:$C$13,2,FALSE) -> 1 | N5: 25 | O5: " | Q5: ok laut CS | T5: TH
B6: 19G-0005Z | C6: 503925 | D6: 24.8 | E6: 0 | F6: 173 | H6: 1.849 | I6: 1.837 | J6: =IF(M6<>"",(H6-I6)/M6,"") -> 0.012 | K6: =(F6*(273.15+D6)/273.15)/(M6*N6) -> 7.5482848 | L6: MI_V3 | M6: =VLOOKUP(L6,[1]allgemein!$B$3:$C$13,2,FALSE) -> 1 | N6: 25 | O6: " | Q6: ok laut CS | T6: TH
B7: 19G-0006Z | C7: 503925 | D7: 24.8 | E7: 0.1 | F7: 173 | H7: 1.87 | I7: 1.853 | J7: =IF(M7<>"",(H7-I7)/M7,"") -> 0.017 | K7: =(F7*(273.15+D7)/273.15)/(M7*N7) -> 7.5482848 | L7: MI_V3 | M7: =VLOOKUP(L7,[1]allgemein!$B$3:$C$13,2,FALSE) -> 1 | N7: 25 | O7: " | Q7: ok laut CS | T7: TH
B8: 19G-0007Z | C8: 503925 | D8: 24.8 | E8: 0 | F8: 172 | H8: 1.87 | I8: 1.861 | J8: =IF(M8<>"",(H8-I8)/M8,"") -> 0.009 | K8: =(F8*(273.15+D8)/273.15)/(M8*N8) -> 7.5046531 | L8: MI_V3 | M8: =VLOOKUP(L8,[1]allgemein!$B$3:$C$13,2,FALSE) -> 1 | N8: 25 | O8: " | Q8: ok laut CS | T8: TH
B9: 19G-0008Z | C9: 503925 | D9: 24.9 | E9: 0.3 | F9: 172 | H9: 1.874 | I9: 1.859 | J9: =IF(M9<>"",(H9-I9)/M9,"") -> 0.015 | K9: =(F9*(273.15+D9)/273.15)/(M9*N9) -> 7.5071719 | L9: MI_V3 | M9: =VLOOKUP(L9,[1]allgemein!$B$3:$C$13,2,FALSE) -> 1 | N9: 25 | O9: " | Q9: ok laut CS | T9: TH
B10: 19G-0009Z | C10: 503925 | D10: 25.1 | E10: 0 | F10: 172 | H10: 1.867 | I10: 1.853 | J10: =IF(M10<>"",(H10-I10)/M10,"") -> 0.014 | K10: =(F10*(273.15+D10)/273.15)/(M10*N10) -> 7.5122094 | L10: MI_V3 | M10: =VLOOKUP(L10,[1]allgemein!$B$3:$C$13,2,FALSE) -> 1 | N10: 25 | O10: " | Q10: ok laut CS | T10: TH
B11: 19G-0010Z | C11: 512136 | D11: 27.7 | E11: 6.9 | F11: 565 | G11: 1.87 | H11: 3.731 | I11: 3.701 | J11: =IF(M11<>"",(H11-I11)/M11,"") -> 0.015 | K11: =(F11*(273.15+D11)/273.15)/(M11*N11) -> 7.7787045 | L11: MU2 | M11: =VLOOKUP(L11,[1]allgemein!$B$3:$C$13,2,FALSE) -> 2 | N11: 40 | O11: FA521320 | R11: neue Spülanlage | T11: HBR
C12: " | G12: 1.861 | P12: * | T12: HBR
B13: 19G-0011Z | C13: " | D13: 27.7 | E13: 6.3 | F13: 565 | G13: 1.864 | H13: 3.717 | I13: 3.688 | J13: =IF(M13<>"",(H13-I13)/M13,"") -> 0.0145 | K13: =(F13*(273.15+D13)/273.15)/(M13*N13) -> 7.7787045 | L13: MU2 | M13: =VLOOKUP(L13,[1]allgemein!$B$3:$C$13,2,FALSE) -> 2 | N13: 40 | O13: " | T13: HBR
C14: " | G14: 1.853 | P14: * | T14: HBR
B15: 19G-0012Z | C15: 514283 | D15: 27.7 | E15: 6.1 | F15: 564 | G15: 1.865 | H15: 3.731 | I15: 3.706 | J15: =IF(M15<>"",(H15-I15)/M15,"") -> 0.0125 | K15: =(F15*(273.15+D15)/273.15)/(M15*N15) -> 7.7649368 | L15: MU2 | M15: =VLOOKUP(L15,[1]allgemein!$B$3:$C$13,2,FALSE) -> 2 | N15: 40 | O15: " | T15: HBR
C16: " | G16: 1.866 | P16: * | Q16: Mem. leicht transp. | T16: HBR
B17: 19G-0013Z | C17: " | D17: 27.4 | E17: 7.1 | F17: 564 | G17: 1.863 | H17: 3.723 | I17: 3.697 | J17: =IF(M17<>"",(H17-I17)/M17,"") -> 0.013 | K17: =(F17*(273.15+D17)/273.15)/(M17*N17) -> 7.7571938 | L17: MU2 | M17: =VLOOKUP(L17,[1]allgemein!$B$3:$C$13,2,FALSE) -> 2 | N17: 40 | O17: " | T17: HBR
C18: " | G18: 1.86 | P18: * | Q18: Mem. leicht transp. | T18: HBR
B19: 19G-0014Z | C19: " | D19: 27.3 | E19: 6.5 | F19: 565 | G19: 1.853 | H19: 3.717 | I19: 3.692 | J19: =IF(M19<>"",(H19-I19)/M19,"") -> 0.0125 | K19: =(F19*(273.15+D19)/273.15)/(M19*N19) -> 7.7683622 | L19: MU2 | M19: =VLOOKUP(L19,[1]allgemein!$B$3:$C$13,2,FALSE) -> 2 | N19: 40 | O19: " | T19: HBR
C20: " | G20: 1.864 | P20: * | Q20: Mem. leicht transp. | T20: HBR
B21: 19G-0015Z | C21: " | D21: 27.2 | E21: 4.7 | F21: 564 | G21: 1.876 | H21: 3.75 | I21: 3.714 | J21: =IF(M21<>"",(H21-I21)/M21,"") -> 0.018 | K21: =(F21*(273.15+D21)/273.15)/(M21*N21) -> 7.7520319 | L21: MU2 | M21: =VLOOKUP(L21,[1]allgemein!$B$3:$C$13,2,FALSE) -> 2 | N21: 40 | O21: " | T21: HBR
C22: " | G22: 1.874 | P22: * | T22: HBR
B23: 19G-0016Z | C23: " | D23: 27.9 | E23: 0.3 | F23: 853 | G23: 1.854 | H23: 5.554 | I23: 5.51 | J23: =IF(M23<>"",(H23-I23)/M23,"") -> 0.014666667 | K23: =(F23*(273.15+D23)/273.15)/(M23*N23) -> 7.8343904 | L23: MU3 | M23: =VLOOKUP(L23,[1]allgemein!$B$3:$C$13,2,FALSE) -> 3 | N23: 40 | O23: FA519066 | T23: HBR
C24: " | G24: 1.852 | Q24: Mem. kl Ptloch | T24: HBR
C25: " | G25: 1.848 | P25: * | Q25: Mem. leicht transp. | T25: HBR
B26: 19G-0017Z | C26: 514283 | D26: 27.7 | E26: 0.8 | F26: 853 | G26: 1.853 | H26: 5.569 | I26: 5.528 | J26: =IF(M26<>"",(H26-I26)/M26,"") -> 0.013666667 | K26: =(F26*(273.15+D26)/273.15)/(M26*N26) -> 7.8291857 | L26: MU3 | M26: =VLOOKUP(L26,[1]allgemein!$B$3:$C$13,2,FALSE) -> 3 | N26: 40 | O26: " | T26: HBR
C27: " | G27: 1.855 | T27: HBR
C28: " | G28: 1.861 | P28: * | Q28: Mem. kl Ptloch | T28: HBR
B29: 19G-0018Z | C29: " | D29: 28.7 | E29: 0 | F29: 854 | G29: 1.865 | H29: 5.588 | I29: 5.546 | J29: =IF(M29<>"",(H29-I29)/M29,"") -> 0.014 | K29: =(F29*(273.15+D29)/273.15)/(M29*N29) -> 7.8644182 | L29: MU3 | M29: =VLOOKUP(L29,[1]allgemein!$B$3:$C$13,2,FALSE) -> 3 | N29: 40 | O29: " | T29: HBR
C30: " | G30: 1.863 | T30: HBR
C31: " | G31: 1.86 | P31: * | Q31: Mem. leicht transp. | T31: HBR
B32: 19G-0019Z | C32: " | D32: 28.4 | E32: 0.1 | F32: 854 | G32: 1.861 | H32: 5.576 | I32: 5.533 | J32: =IF(M32<>"",(H32-I32)/M32,"") -> 0.014333333 | K32: =(F32*(273.15+D32)/273.15)/(M32*N32) -> 7.856602 | L32: MU3 | M32: =VLOOKUP(L32,[1]allgemein!$B$3:$C$13,2,FALSE) -> 3 | N32: 40 | O32: " | T32: HBR
C33: " | G33: 1.859 | Q33: Mem. leicht transp. | T33: HBR
C34: " | G34: 1.856 | P34: * | Q34: " | T34: HBR
B35: 19G-0020Z | C35: " | D35: 28.3 | E35: 0.2 | F35: 853 | G35: 1.869 | H35: 5.605 | I35: 5.561 | J35: =IF(M35<>"",(H35-I35)/M35,"") -> 0.014666667 | K35: =(F35*(273.15+D35)/273.15)/(M35*N35) -> 7.8447999 | L35: MU3 | M35: =VLOOKUP(L35,[1]allgemein!$B$3:$C$13,2,FALSE) -> 3 | N35: 40 | O35: " | Q35: " | T35: HBR
C36: " | G36: 1.868 | Q36: " | T36: HBR
C37: " | G37: 1.868 | P37: * | Q37: " | T37: HBR
B38: 19G-0021Z-R | C38: 514283 | D38: 28.2 | E38: 0.2 | F38: 279 | H38: 1.885 | I38: 1.8713 | J38: =IF(M38<>"",(H38-I38)/M38,"") -> 0.0137 | K38: =(F38*(273.15+D38)/273.15)/(M38*N38) -> 7.6950988 | L38: MA_V1 | M38: =VLOOKUP(L38,[1]allgemein!$B$3:$C$13,2,FALSE) -> 1 | N38: 40 | O38: FA523183 | Q38: " | T38: HBR
B39: 19G-0022Z-R | C39: " | D39: 28.1 | E39: 0.1 | F39: 278 | H39: 1.888 | I39: 1.872 | J39: =IF(M39<>"",(H39-I39)/M39,"") -> 0.016 | K39: =(F39*(273.15+D39)/273.15)/(M39*N39) -> 7.6649735 | L39: MA_V1 | M39: =VLOOKUP(L39,[1]allgemein!$B$3:$C$13,2,FALSE) -> 1 | N39: 40 | O39: " | Q39: Mem. kl Ptloch | T39: HBR
B40: 19G-0023Z-R | C40: " | D40: 28.1 | E40: 0.1 | F40: 278 | H40: 1.876 | I40: 1.862 | J40: =IF(M40<>"",(H40-I40)/M40,"") -> 0.014 | K40: =(F40*(273.15+D40)/273.15)/(M40*N40) -> 7.6649735 | L40: MA_V1 | M40: =VLOOKUP(L40,[1]allgemein!$B$3:$C$13,2,FALSE) -> 1 | N40: 40 | O40: FA516561 | Q40: " | T40: HBR
...

Sheet Aug
